[2025-06-16T13:38:04.813+0000] {task_context_logger.py:104} ERROR - Executor reports task instance <TaskInstance: etl_brazil_pipeline.run_dbt_models manual__2025-06-16T13:30:24.846541+00:00 [queued]> finished (failed) although the task says it's queued. (Info: None) Was the task killed externally?
