[2025-06-16T13:40:15.365+0000] {local_task_job_runner.py:120} INFO - ::group::Pre task execution logs
[2025-06-16T13:40:15.500+0000] {taskinstance.py:2076} INFO - Dependencies all met for dep_context=non-requeueable deps ti=<TaskInstance: etl_brazil_pipeline.run_dbt_models manual__2025-06-16T13:30:24.846541+00:00 [queued]>
[2025-06-16T13:40:15.540+0000] {taskinstance.py:2076} INFO - Dependencies all met for dep_context=requeueable deps ti=<TaskInstance: etl_brazil_pipeline.run_dbt_models manual__2025-06-16T13:30:24.846541+00:00 [queued]>
[2025-06-16T13:40:15.541+0000] {taskinstance.py:2306} INFO - Starting attempt 2 of 2
[2025-06-16T13:40:15.590+0000] {taskinstance.py:2330} INFO - Executing <Task(BashOperator): run_dbt_models> on 2025-06-16 13:30:24.846541+00:00
[2025-06-16T13:40:15.681+0000] {warnings.py:110} WARNING - /home/airflow/.local/lib/python3.12/site-packages/airflow/task/task_runner/standard_task_runner.py:61: DeprecationWarning: This process (pid=530) is multi-threaded, use of fork() may lead to deadlocks in the child.
  pid = os.fork()

[2025-06-16T13:40:15.686+0000] {standard_task_runner.py:90} INFO - Running: ['airflow', 'tasks', 'run', 'etl_brazil_pipeline', 'run_dbt_models', 'manual__2025-06-16T13:30:24.846541+00:00', '--job-id', '56', '--raw', '--subdir', 'DAGS_FOLDER/etl_brazil_pipeline.py', '--cfg-path', '/tmp/tmpct7dr6yz']
[2025-06-16T13:40:15.687+0000] {standard_task_runner.py:63} INFO - Started process 559 to run task
[2025-06-16T13:40:15.688+0000] {standard_task_runner.py:91} INFO - Job 56: Subtask run_dbt_models
[2025-06-16T13:40:15.748+0000] {warnings.py:110} WARNING - /home/airflow/.local/lib/python3.12/site-packages/airflow/settings.py:195: DeprecationWarning: The sql_alchemy_conn option in [core] has been moved to the sql_alchemy_conn option in [database] - the old setting has been used, but please update your config.
  SQL_ALCHEMY_CONN = conf.get("database", "SQL_ALCHEMY_CONN")

[2025-06-16T13:40:15.847+0000] {task_command.py:426} INFO - Running <TaskInstance: etl_brazil_pipeline.run_dbt_models manual__2025-06-16T13:30:24.846541+00:00 [running]> on host e74b257ce696
[2025-06-16T13:40:16.031+0000] {taskinstance.py:2648} INFO - Exporting env vars: AIRFLOW_CTX_DAG_OWNER='vaishnavi' AIRFLOW_CTX_DAG_ID='etl_brazil_pipeline' AIRFLOW_CTX_TASK_ID='run_dbt_models' AIRFLOW_CTX_EXECUTION_DATE='2025-06-16T13:30:24.846541+00:00' AIRFLOW_CTX_TRY_NUMBER='2' AIRFLOW_CTX_DAG_RUN_ID='manual__2025-06-16T13:30:24.846541+00:00'
[2025-06-16T13:40:16.034+0000] {taskinstance.py:430} INFO - ::endgroup::
[2025-06-16T13:40:16.083+0000] {subprocess.py:63} INFO - Tmp dir root location: /tmp
[2025-06-16T13:40:16.092+0000] {subprocess.py:75} INFO - Running command: ['/usr/bin/bash', '-c', 'cd /opt/airflow/dbt_project && /home/airflow/.local/bin/dbt run']
[2025-06-16T13:40:16.130+0000] {subprocess.py:86} INFO - Output:
[2025-06-16T13:40:24.620+0000] {subprocess.py:93} INFO - [0m13:40:24  Running with dbt=1.7.9
[2025-06-16T13:40:25.951+0000] {subprocess.py:93} INFO - [0m13:40:25  Registered adapter: ***=1.7.9
[2025-06-16T13:40:25.990+0000] {subprocess.py:93} INFO - [0m13:40:25  Unable to do partial parsing because saved manifest not found. Starting full parse.
[2025-06-16T13:40:29.810+0000] {subprocess.py:93} INFO - [0m13:40:29  Found 11 models, 19 tests, 0 sources, 0 exposures, 0 metrics, 401 macros, 0 groups, 0 semantic models
[2025-06-16T13:40:29.822+0000] {subprocess.py:93} INFO - [0m13:40:29
[2025-06-16T13:40:29.930+0000] {subprocess.py:93} INFO - [0m13:40:29
[2025-06-16T13:40:29.933+0000] {subprocess.py:93} INFO - [0m13:40:29  Finished running  in 0 hours 0 minutes and 0.10 seconds (0.10s).
[2025-06-16T13:40:29.938+0000] {subprocess.py:93} INFO - [0m13:40:29  Encountered an error:
[2025-06-16T13:40:29.939+0000] {subprocess.py:93} INFO - Database Error
[2025-06-16T13:40:29.940+0000] {subprocess.py:93} INFO -   connection to server at "***" (172.18.0.3), port 5432 failed: FATAL:  password authentication failed for user "${POSTGRES_USER}"
[2025-06-16T13:40:29.941+0000] {subprocess.py:93} INFO - 
[2025-06-16T13:40:31.323+0000] {subprocess.py:97} INFO - Command exited with return code 2
[2025-06-16T13:40:31.326+0000] {taskinstance.py:441} INFO - ::group::Post task execution logs
[2025-06-16T13:40:31.353+0000] {taskinstance.py:2905} ERROR - Task failed with exception
Traceback (most recent call last):
  File "/home/airflow/.local/lib/python3.12/site-packages/airflow/models/taskinstance.py", line 465, in _execute_task
    result = _execute_callable(context=context, **execute_callable_kwargs)
             ^^^^^^^^^^^^^^^^^^^^^^^^^^^^^^^^^^^^^^^^^^^^^^^^^^^^^^^^^^^^^
  File "/home/airflow/.local/lib/python3.12/site-packages/airflow/models/taskinstance.py", line 432, in _execute_callable
    return execute_callable(context=context, **execute_callable_kwargs)
           ^^^^^^^^^^^^^^^^^^^^^^^^^^^^^^^^^^^^^^^^^^^^^^^^^^^^^^^^^^^^
  File "/home/airflow/.local/lib/python3.12/site-packages/airflow/models/baseoperator.py", line 400, in wrapper
    return func(self, *args, **kwargs)
           ^^^^^^^^^^^^^^^^^^^^^^^^^^^
  File "/home/airflow/.local/lib/python3.12/site-packages/airflow/operators/bash.py", line 243, in execute
    raise AirflowException(
airflow.exceptions.AirflowException: Bash command failed. The command returned a non-zero exit code 2.
[2025-06-16T13:40:31.361+0000] {taskinstance.py:1206} INFO - Marking task as FAILED. dag_id=etl_brazil_pipeline, task_id=run_dbt_models, run_id=manual__2025-06-16T13:30:24.846541+00:00, execution_date=20250616T133024, start_date=20250616T134015, end_date=20250616T134031
[2025-06-16T13:40:31.386+0000] {standard_task_runner.py:110} ERROR - Failed to execute job 56 for task run_dbt_models (Bash command failed. The command returned a non-zero exit code 2.; 559)
[2025-06-16T13:40:31.409+0000] {local_task_job_runner.py:240} INFO - Task exited with return code 1
[2025-06-16T13:40:31.441+0000] {taskinstance.py:3498} INFO - 0 downstream tasks scheduled from follow-on schedule check
[2025-06-16T13:40:31.447+0000] {local_task_job_runner.py:222} INFO - ::endgroup::
