[2025-06-10T13:55:10.954+0000] {processor.py:161} INFO - Started process (PID=220) to work on /opt/airflow/dags/etl_pipeline_dag.py
[2025-06-10T13:55:10.979+0000] {processor.py:830} INFO - Processing file /opt/airflow/dags/etl_pipeline_dag.py for tasks to queue
[2025-06-10T13:55:11.039+0000] {logging_mixin.py:188} INFO - [2025-06-10T13:55:11.034+0000] {dagbag.py:545} INFO - Filling up the DagBag from /opt/airflow/dags/etl_pipeline_dag.py
[2025-06-10T13:55:11.158+0000] {logging_mixin.py:188} INFO - [2025-06-10T13:55:11.125+0000] {dagbag.py:355} ERROR - Failed to import: /opt/airflow/dags/etl_pipeline_dag.py
Traceback (most recent call last):
  File "/home/airflow/.local/lib/python3.12/site-packages/airflow/models/dagbag.py", line 351, in parse
    loader.exec_module(new_module)
  File "<frozen importlib._bootstrap_external>", line 995, in exec_module
  File "<frozen importlib._bootstrap>", line 488, in _call_with_frames_removed
  File "/opt/airflow/dags/etl_pipeline_dag.py", line 8, in <module>
    from main_etl import run_etl
ModuleNotFoundError: No module named 'main_etl'
[2025-06-10T13:55:11.165+0000] {processor.py:842} WARNING - No viable dags retrieved from /opt/airflow/dags/etl_pipeline_dag.py
[2025-06-10T13:55:11.478+0000] {processor.py:183} INFO - Processing /opt/airflow/dags/etl_pipeline_dag.py took 0.675 seconds
[2025-06-10T13:55:42.356+0000] {processor.py:161} INFO - Started process (PID=225) to work on /opt/airflow/dags/etl_pipeline_dag.py
[2025-06-10T13:55:42.367+0000] {processor.py:830} INFO - Processing file /opt/airflow/dags/etl_pipeline_dag.py for tasks to queue
[2025-06-10T13:55:42.453+0000] {logging_mixin.py:188} INFO - [2025-06-10T13:55:42.442+0000] {dagbag.py:545} INFO - Filling up the DagBag from /opt/airflow/dags/etl_pipeline_dag.py
[2025-06-10T13:55:42.684+0000] {logging_mixin.py:188} INFO - [2025-06-10T13:55:42.635+0000] {dagbag.py:355} ERROR - Failed to import: /opt/airflow/dags/etl_pipeline_dag.py
Traceback (most recent call last):
  File "/home/airflow/.local/lib/python3.12/site-packages/airflow/models/dagbag.py", line 351, in parse
    loader.exec_module(new_module)
  File "<frozen importlib._bootstrap_external>", line 995, in exec_module
  File "<frozen importlib._bootstrap>", line 488, in _call_with_frames_removed
  File "/opt/airflow/dags/etl_pipeline_dag.py", line 8, in <module>
    from main_etl import run_etl
ModuleNotFoundError: No module named 'main_etl'
[2025-06-10T13:55:42.693+0000] {processor.py:842} WARNING - No viable dags retrieved from /opt/airflow/dags/etl_pipeline_dag.py
[2025-06-10T13:55:43.118+0000] {processor.py:183} INFO - Processing /opt/airflow/dags/etl_pipeline_dag.py took 0.997 seconds
[2025-06-10T13:56:13.700+0000] {processor.py:161} INFO - Started process (PID=230) to work on /opt/airflow/dags/etl_pipeline_dag.py
[2025-06-10T13:56:13.712+0000] {processor.py:830} INFO - Processing file /opt/airflow/dags/etl_pipeline_dag.py for tasks to queue
[2025-06-10T13:56:13.740+0000] {logging_mixin.py:188} INFO - [2025-06-10T13:56:13.737+0000] {dagbag.py:545} INFO - Filling up the DagBag from /opt/airflow/dags/etl_pipeline_dag.py
[2025-06-10T13:56:13.959+0000] {logging_mixin.py:188} INFO - [2025-06-10T13:56:13.922+0000] {dagbag.py:355} ERROR - Failed to import: /opt/airflow/dags/etl_pipeline_dag.py
Traceback (most recent call last):
  File "/home/airflow/.local/lib/python3.12/site-packages/airflow/models/dagbag.py", line 351, in parse
    loader.exec_module(new_module)
  File "<frozen importlib._bootstrap_external>", line 995, in exec_module
  File "<frozen importlib._bootstrap>", line 488, in _call_with_frames_removed
  File "/opt/airflow/dags/etl_pipeline_dag.py", line 8, in <module>
    from main_etl import run_etl
ModuleNotFoundError: No module named 'main_etl'
[2025-06-10T13:56:13.968+0000] {processor.py:842} WARNING - No viable dags retrieved from /opt/airflow/dags/etl_pipeline_dag.py
[2025-06-10T13:56:14.275+0000] {processor.py:183} INFO - Processing /opt/airflow/dags/etl_pipeline_dag.py took 0.693 seconds
[2025-06-10T13:56:44.887+0000] {processor.py:161} INFO - Started process (PID=235) to work on /opt/airflow/dags/etl_pipeline_dag.py
[2025-06-10T13:56:44.893+0000] {processor.py:830} INFO - Processing file /opt/airflow/dags/etl_pipeline_dag.py for tasks to queue
[2025-06-10T13:56:44.908+0000] {logging_mixin.py:188} INFO - [2025-06-10T13:56:44.904+0000] {dagbag.py:545} INFO - Filling up the DagBag from /opt/airflow/dags/etl_pipeline_dag.py
[2025-06-10T13:56:44.961+0000] {logging_mixin.py:188} INFO - [2025-06-10T13:56:44.952+0000] {dagbag.py:355} ERROR - Failed to import: /opt/airflow/dags/etl_pipeline_dag.py
Traceback (most recent call last):
  File "/home/airflow/.local/lib/python3.12/site-packages/airflow/models/dagbag.py", line 351, in parse
    loader.exec_module(new_module)
  File "<frozen importlib._bootstrap_external>", line 995, in exec_module
  File "<frozen importlib._bootstrap>", line 488, in _call_with_frames_removed
  File "/opt/airflow/dags/etl_pipeline_dag.py", line 8, in <module>
    from main_etl import run_etl
ModuleNotFoundError: No module named 'main_etl'
[2025-06-10T13:56:44.969+0000] {processor.py:842} WARNING - No viable dags retrieved from /opt/airflow/dags/etl_pipeline_dag.py
[2025-06-10T13:56:45.158+0000] {processor.py:183} INFO - Processing /opt/airflow/dags/etl_pipeline_dag.py took 0.332 seconds
[2025-06-10T13:57:15.587+0000] {processor.py:161} INFO - Started process (PID=240) to work on /opt/airflow/dags/etl_pipeline_dag.py
[2025-06-10T13:57:15.589+0000] {processor.py:830} INFO - Processing file /opt/airflow/dags/etl_pipeline_dag.py for tasks to queue
[2025-06-10T13:57:15.593+0000] {logging_mixin.py:188} INFO - [2025-06-10T13:57:15.592+0000] {dagbag.py:545} INFO - Filling up the DagBag from /opt/airflow/dags/etl_pipeline_dag.py
[2025-06-10T13:57:15.684+0000] {logging_mixin.py:188} INFO - [2025-06-10T13:57:15.671+0000] {dagbag.py:355} ERROR - Failed to import: /opt/airflow/dags/etl_pipeline_dag.py
Traceback (most recent call last):
  File "/home/airflow/.local/lib/python3.12/site-packages/airflow/models/dagbag.py", line 351, in parse
    loader.exec_module(new_module)
  File "<frozen importlib._bootstrap_external>", line 995, in exec_module
  File "<frozen importlib._bootstrap>", line 488, in _call_with_frames_removed
  File "/opt/airflow/dags/etl_pipeline_dag.py", line 8, in <module>
    from main_etl import run_etl
ModuleNotFoundError: No module named 'main_etl'
[2025-06-10T13:57:15.693+0000] {processor.py:842} WARNING - No viable dags retrieved from /opt/airflow/dags/etl_pipeline_dag.py
[2025-06-10T13:57:15.798+0000] {processor.py:183} INFO - Processing /opt/airflow/dags/etl_pipeline_dag.py took 0.221 seconds
[2025-06-10T13:57:46.172+0000] {processor.py:161} INFO - Started process (PID=245) to work on /opt/airflow/dags/etl_pipeline_dag.py
[2025-06-10T13:57:46.176+0000] {processor.py:830} INFO - Processing file /opt/airflow/dags/etl_pipeline_dag.py for tasks to queue
[2025-06-10T13:57:46.184+0000] {logging_mixin.py:188} INFO - [2025-06-10T13:57:46.183+0000] {dagbag.py:545} INFO - Filling up the DagBag from /opt/airflow/dags/etl_pipeline_dag.py
[2025-06-10T13:57:46.281+0000] {logging_mixin.py:188} INFO - [2025-06-10T13:57:46.264+0000] {dagbag.py:355} ERROR - Failed to import: /opt/airflow/dags/etl_pipeline_dag.py
Traceback (most recent call last):
  File "/home/airflow/.local/lib/python3.12/site-packages/airflow/models/dagbag.py", line 351, in parse
    loader.exec_module(new_module)
  File "<frozen importlib._bootstrap_external>", line 995, in exec_module
  File "<frozen importlib._bootstrap>", line 488, in _call_with_frames_removed
  File "/opt/airflow/dags/etl_pipeline_dag.py", line 8, in <module>
    from main_etl import run_etl
ModuleNotFoundError: No module named 'main_etl'
[2025-06-10T13:57:46.286+0000] {processor.py:842} WARNING - No viable dags retrieved from /opt/airflow/dags/etl_pipeline_dag.py
[2025-06-10T13:57:46.343+0000] {processor.py:183} INFO - Processing /opt/airflow/dags/etl_pipeline_dag.py took 0.180 seconds
[2025-06-10T13:58:16.453+0000] {processor.py:161} INFO - Started process (PID=250) to work on /opt/airflow/dags/etl_pipeline_dag.py
[2025-06-10T13:58:16.455+0000] {processor.py:830} INFO - Processing file /opt/airflow/dags/etl_pipeline_dag.py for tasks to queue
[2025-06-10T13:58:16.458+0000] {logging_mixin.py:188} INFO - [2025-06-10T13:58:16.457+0000] {dagbag.py:545} INFO - Filling up the DagBag from /opt/airflow/dags/etl_pipeline_dag.py
[2025-06-10T13:58:16.523+0000] {logging_mixin.py:188} INFO - [2025-06-10T13:58:16.511+0000] {dagbag.py:355} ERROR - Failed to import: /opt/airflow/dags/etl_pipeline_dag.py
Traceback (most recent call last):
  File "/home/airflow/.local/lib/python3.12/site-packages/airflow/models/dagbag.py", line 351, in parse
    loader.exec_module(new_module)
  File "<frozen importlib._bootstrap_external>", line 995, in exec_module
  File "<frozen importlib._bootstrap>", line 488, in _call_with_frames_removed
  File "/opt/airflow/dags/etl_pipeline_dag.py", line 8, in <module>
    from main_etl import run_etl
ModuleNotFoundError: No module named 'main_etl'
[2025-06-10T13:58:16.529+0000] {processor.py:842} WARNING - No viable dags retrieved from /opt/airflow/dags/etl_pipeline_dag.py
[2025-06-10T13:58:16.576+0000] {processor.py:183} INFO - Processing /opt/airflow/dags/etl_pipeline_dag.py took 0.130 seconds
[2025-06-10T13:58:47.034+0000] {processor.py:161} INFO - Started process (PID=255) to work on /opt/airflow/dags/etl_pipeline_dag.py
[2025-06-10T13:58:47.038+0000] {processor.py:830} INFO - Processing file /opt/airflow/dags/etl_pipeline_dag.py for tasks to queue
[2025-06-10T13:58:47.048+0000] {logging_mixin.py:188} INFO - [2025-06-10T13:58:47.047+0000] {dagbag.py:545} INFO - Filling up the DagBag from /opt/airflow/dags/etl_pipeline_dag.py
[2025-06-10T13:58:47.123+0000] {logging_mixin.py:188} INFO - [2025-06-10T13:58:47.110+0000] {dagbag.py:355} ERROR - Failed to import: /opt/airflow/dags/etl_pipeline_dag.py
Traceback (most recent call last):
  File "/home/airflow/.local/lib/python3.12/site-packages/airflow/models/dagbag.py", line 351, in parse
    loader.exec_module(new_module)
  File "<frozen importlib._bootstrap_external>", line 995, in exec_module
  File "<frozen importlib._bootstrap>", line 488, in _call_with_frames_removed
  File "/opt/airflow/dags/etl_pipeline_dag.py", line 8, in <module>
    from main_etl import run_etl
ModuleNotFoundError: No module named 'main_etl'
[2025-06-10T13:58:47.129+0000] {processor.py:842} WARNING - No viable dags retrieved from /opt/airflow/dags/etl_pipeline_dag.py
[2025-06-10T13:58:47.238+0000] {processor.py:183} INFO - Processing /opt/airflow/dags/etl_pipeline_dag.py took 0.229 seconds
[2025-06-10T13:59:17.551+0000] {processor.py:161} INFO - Started process (PID=260) to work on /opt/airflow/dags/etl_pipeline_dag.py
[2025-06-10T13:59:17.553+0000] {processor.py:830} INFO - Processing file /opt/airflow/dags/etl_pipeline_dag.py for tasks to queue
[2025-06-10T13:59:17.556+0000] {logging_mixin.py:188} INFO - [2025-06-10T13:59:17.556+0000] {dagbag.py:545} INFO - Filling up the DagBag from /opt/airflow/dags/etl_pipeline_dag.py
[2025-06-10T13:59:17.622+0000] {logging_mixin.py:188} INFO - [2025-06-10T13:59:17.610+0000] {dagbag.py:355} ERROR - Failed to import: /opt/airflow/dags/etl_pipeline_dag.py
Traceback (most recent call last):
  File "/home/airflow/.local/lib/python3.12/site-packages/airflow/models/dagbag.py", line 351, in parse
    loader.exec_module(new_module)
  File "<frozen importlib._bootstrap_external>", line 995, in exec_module
  File "<frozen importlib._bootstrap>", line 488, in _call_with_frames_removed
  File "/opt/airflow/dags/etl_pipeline_dag.py", line 8, in <module>
    from main_etl import run_etl
ModuleNotFoundError: No module named 'main_etl'
[2025-06-10T13:59:17.628+0000] {processor.py:842} WARNING - No viable dags retrieved from /opt/airflow/dags/etl_pipeline_dag.py
[2025-06-10T13:59:17.930+0000] {processor.py:183} INFO - Processing /opt/airflow/dags/etl_pipeline_dag.py took 0.388 seconds
[2025-06-10T14:03:00.368+0000] {processor.py:161} INFO - Started process (PID=220) to work on /opt/airflow/dags/etl_pipeline_dag.py
[2025-06-10T14:03:00.392+0000] {processor.py:830} INFO - Processing file /opt/airflow/dags/etl_pipeline_dag.py for tasks to queue
[2025-06-10T14:03:00.446+0000] {logging_mixin.py:188} INFO - [2025-06-10T14:03:00.430+0000] {dagbag.py:545} INFO - Filling up the DagBag from /opt/airflow/dags/etl_pipeline_dag.py
[2025-06-10T14:03:00.621+0000] {logging_mixin.py:188} INFO - [2025-06-10T14:03:00.580+0000] {dagbag.py:355} ERROR - Failed to import: /opt/airflow/dags/etl_pipeline_dag.py
Traceback (most recent call last):
  File "/home/airflow/.local/lib/python3.12/site-packages/airflow/models/dagbag.py", line 351, in parse
    loader.exec_module(new_module)
  File "<frozen importlib._bootstrap_external>", line 995, in exec_module
  File "<frozen importlib._bootstrap>", line 488, in _call_with_frames_removed
  File "/opt/airflow/dags/etl_pipeline_dag.py", line 8, in <module>
    from main_etl import run_etl
ModuleNotFoundError: No module named 'main_etl'
[2025-06-10T14:03:00.629+0000] {processor.py:842} WARNING - No viable dags retrieved from /opt/airflow/dags/etl_pipeline_dag.py
[2025-06-10T14:03:00.884+0000] {processor.py:183} INFO - Processing /opt/airflow/dags/etl_pipeline_dag.py took 0.687 seconds
[2025-06-10T14:03:31.536+0000] {processor.py:161} INFO - Started process (PID=225) to work on /opt/airflow/dags/etl_pipeline_dag.py
[2025-06-10T14:03:31.549+0000] {processor.py:830} INFO - Processing file /opt/airflow/dags/etl_pipeline_dag.py for tasks to queue
[2025-06-10T14:03:31.598+0000] {logging_mixin.py:188} INFO - [2025-06-10T14:03:31.592+0000] {dagbag.py:545} INFO - Filling up the DagBag from /opt/airflow/dags/etl_pipeline_dag.py
[2025-06-10T14:03:31.736+0000] {logging_mixin.py:188} INFO - [2025-06-10T14:03:31.714+0000] {dagbag.py:355} ERROR - Failed to import: /opt/airflow/dags/etl_pipeline_dag.py
Traceback (most recent call last):
  File "/home/airflow/.local/lib/python3.12/site-packages/airflow/models/dagbag.py", line 351, in parse
    loader.exec_module(new_module)
  File "<frozen importlib._bootstrap_external>", line 995, in exec_module
  File "<frozen importlib._bootstrap>", line 488, in _call_with_frames_removed
  File "/opt/airflow/dags/etl_pipeline_dag.py", line 8, in <module>
    from main_etl import run_etl
ModuleNotFoundError: No module named 'main_etl'
[2025-06-10T14:03:31.742+0000] {processor.py:842} WARNING - No viable dags retrieved from /opt/airflow/dags/etl_pipeline_dag.py
[2025-06-10T14:03:32.038+0000] {processor.py:183} INFO - Processing /opt/airflow/dags/etl_pipeline_dag.py took 0.613 seconds
[2025-06-10T14:04:02.615+0000] {processor.py:161} INFO - Started process (PID=230) to work on /opt/airflow/dags/etl_pipeline_dag.py
[2025-06-10T14:04:02.639+0000] {processor.py:830} INFO - Processing file /opt/airflow/dags/etl_pipeline_dag.py for tasks to queue
[2025-06-10T14:04:02.683+0000] {logging_mixin.py:188} INFO - [2025-06-10T14:04:02.680+0000] {dagbag.py:545} INFO - Filling up the DagBag from /opt/airflow/dags/etl_pipeline_dag.py
[2025-06-10T14:04:02.794+0000] {logging_mixin.py:188} INFO - [2025-06-10T14:04:02.776+0000] {dagbag.py:355} ERROR - Failed to import: /opt/airflow/dags/etl_pipeline_dag.py
Traceback (most recent call last):
  File "/home/airflow/.local/lib/python3.12/site-packages/airflow/models/dagbag.py", line 351, in parse
    loader.exec_module(new_module)
  File "<frozen importlib._bootstrap_external>", line 995, in exec_module
  File "<frozen importlib._bootstrap>", line 488, in _call_with_frames_removed
  File "/opt/airflow/dags/etl_pipeline_dag.py", line 8, in <module>
    from main_etl import run_etl
ModuleNotFoundError: No module named 'main_etl'
[2025-06-10T14:04:02.800+0000] {processor.py:842} WARNING - No viable dags retrieved from /opt/airflow/dags/etl_pipeline_dag.py
[2025-06-10T14:04:03.016+0000] {processor.py:183} INFO - Processing /opt/airflow/dags/etl_pipeline_dag.py took 0.484 seconds
[2025-06-10T14:04:33.445+0000] {processor.py:161} INFO - Started process (PID=235) to work on /opt/airflow/dags/etl_pipeline_dag.py
[2025-06-10T14:04:33.464+0000] {processor.py:830} INFO - Processing file /opt/airflow/dags/etl_pipeline_dag.py for tasks to queue
[2025-06-10T14:04:33.500+0000] {logging_mixin.py:188} INFO - [2025-06-10T14:04:33.495+0000] {dagbag.py:545} INFO - Filling up the DagBag from /opt/airflow/dags/etl_pipeline_dag.py
[2025-06-10T14:04:33.602+0000] {logging_mixin.py:188} INFO - [2025-06-10T14:04:33.581+0000] {dagbag.py:355} ERROR - Failed to import: /opt/airflow/dags/etl_pipeline_dag.py
Traceback (most recent call last):
  File "/home/airflow/.local/lib/python3.12/site-packages/airflow/models/dagbag.py", line 351, in parse
    loader.exec_module(new_module)
  File "<frozen importlib._bootstrap_external>", line 995, in exec_module
  File "<frozen importlib._bootstrap>", line 488, in _call_with_frames_removed
  File "/opt/airflow/dags/etl_pipeline_dag.py", line 8, in <module>
    from main_etl import run_etl
ModuleNotFoundError: No module named 'main_etl'
[2025-06-10T14:04:33.607+0000] {processor.py:842} WARNING - No viable dags retrieved from /opt/airflow/dags/etl_pipeline_dag.py
[2025-06-10T14:04:33.786+0000] {processor.py:183} INFO - Processing /opt/airflow/dags/etl_pipeline_dag.py took 0.425 seconds
[2025-06-10T14:05:04.093+0000] {processor.py:161} INFO - Started process (PID=240) to work on /opt/airflow/dags/etl_pipeline_dag.py
[2025-06-10T14:05:04.105+0000] {processor.py:830} INFO - Processing file /opt/airflow/dags/etl_pipeline_dag.py for tasks to queue
[2025-06-10T14:05:04.110+0000] {logging_mixin.py:188} INFO - [2025-06-10T14:05:04.109+0000] {dagbag.py:545} INFO - Filling up the DagBag from /opt/airflow/dags/etl_pipeline_dag.py
[2025-06-10T14:05:04.188+0000] {logging_mixin.py:188} INFO - [2025-06-10T14:05:04.173+0000] {dagbag.py:355} ERROR - Failed to import: /opt/airflow/dags/etl_pipeline_dag.py
Traceback (most recent call last):
  File "/home/airflow/.local/lib/python3.12/site-packages/airflow/models/dagbag.py", line 351, in parse
    loader.exec_module(new_module)
  File "<frozen importlib._bootstrap_external>", line 995, in exec_module
  File "<frozen importlib._bootstrap>", line 488, in _call_with_frames_removed
  File "/opt/airflow/dags/etl_pipeline_dag.py", line 8, in <module>
    from main_etl import run_etl
ModuleNotFoundError: No module named 'main_etl'
[2025-06-10T14:05:04.191+0000] {processor.py:842} WARNING - No viable dags retrieved from /opt/airflow/dags/etl_pipeline_dag.py
[2025-06-10T14:05:04.286+0000] {processor.py:183} INFO - Processing /opt/airflow/dags/etl_pipeline_dag.py took 0.205 seconds
[2025-06-10T14:05:34.560+0000] {processor.py:161} INFO - Started process (PID=245) to work on /opt/airflow/dags/etl_pipeline_dag.py
[2025-06-10T14:05:34.563+0000] {processor.py:830} INFO - Processing file /opt/airflow/dags/etl_pipeline_dag.py for tasks to queue
[2025-06-10T14:05:34.567+0000] {logging_mixin.py:188} INFO - [2025-06-10T14:05:34.566+0000] {dagbag.py:545} INFO - Filling up the DagBag from /opt/airflow/dags/etl_pipeline_dag.py
[2025-06-10T14:05:34.623+0000] {logging_mixin.py:188} INFO - [2025-06-10T14:05:34.614+0000] {dagbag.py:355} ERROR - Failed to import: /opt/airflow/dags/etl_pipeline_dag.py
Traceback (most recent call last):
  File "/home/airflow/.local/lib/python3.12/site-packages/airflow/models/dagbag.py", line 351, in parse
    loader.exec_module(new_module)
  File "<frozen importlib._bootstrap_external>", line 995, in exec_module
  File "<frozen importlib._bootstrap>", line 488, in _call_with_frames_removed
  File "/opt/airflow/dags/etl_pipeline_dag.py", line 8, in <module>
    from main_etl import run_etl
ModuleNotFoundError: No module named 'main_etl'
[2025-06-10T14:05:34.627+0000] {processor.py:842} WARNING - No viable dags retrieved from /opt/airflow/dags/etl_pipeline_dag.py
[2025-06-10T14:05:34.656+0000] {processor.py:183} INFO - Processing /opt/airflow/dags/etl_pipeline_dag.py took 0.107 seconds
[2025-06-10T14:06:04.838+0000] {processor.py:161} INFO - Started process (PID=250) to work on /opt/airflow/dags/etl_pipeline_dag.py
[2025-06-10T14:06:04.840+0000] {processor.py:830} INFO - Processing file /opt/airflow/dags/etl_pipeline_dag.py for tasks to queue
[2025-06-10T14:06:04.842+0000] {logging_mixin.py:188} INFO - [2025-06-10T14:06:04.842+0000] {dagbag.py:545} INFO - Filling up the DagBag from /opt/airflow/dags/etl_pipeline_dag.py
[2025-06-10T14:06:04.892+0000] {logging_mixin.py:188} INFO - [2025-06-10T14:06:04.884+0000] {dagbag.py:355} ERROR - Failed to import: /opt/airflow/dags/etl_pipeline_dag.py
Traceback (most recent call last):
  File "/home/airflow/.local/lib/python3.12/site-packages/airflow/models/dagbag.py", line 351, in parse
    loader.exec_module(new_module)
  File "<frozen importlib._bootstrap_external>", line 995, in exec_module
  File "<frozen importlib._bootstrap>", line 488, in _call_with_frames_removed
  File "/opt/airflow/dags/etl_pipeline_dag.py", line 8, in <module>
    from main_etl import run_etl
ModuleNotFoundError: No module named 'main_etl'
[2025-06-10T14:06:04.895+0000] {processor.py:842} WARNING - No viable dags retrieved from /opt/airflow/dags/etl_pipeline_dag.py
[2025-06-10T14:06:04.929+0000] {processor.py:183} INFO - Processing /opt/airflow/dags/etl_pipeline_dag.py took 0.097 seconds
[2025-06-10T14:06:35.310+0000] {processor.py:161} INFO - Started process (PID=255) to work on /opt/airflow/dags/etl_pipeline_dag.py
[2025-06-10T14:06:35.315+0000] {processor.py:830} INFO - Processing file /opt/airflow/dags/etl_pipeline_dag.py for tasks to queue
[2025-06-10T14:06:35.320+0000] {logging_mixin.py:188} INFO - [2025-06-10T14:06:35.319+0000] {dagbag.py:545} INFO - Filling up the DagBag from /opt/airflow/dags/etl_pipeline_dag.py
[2025-06-10T14:06:35.398+0000] {logging_mixin.py:188} INFO - [2025-06-10T14:06:35.386+0000] {dagbag.py:355} ERROR - Failed to import: /opt/airflow/dags/etl_pipeline_dag.py
Traceback (most recent call last):
  File "/home/airflow/.local/lib/python3.12/site-packages/airflow/models/dagbag.py", line 351, in parse
    loader.exec_module(new_module)
  File "<frozen importlib._bootstrap_external>", line 995, in exec_module
  File "<frozen importlib._bootstrap>", line 488, in _call_with_frames_removed
  File "/opt/airflow/dags/etl_pipeline_dag.py", line 8, in <module>
    from main_etl import run_etl
ModuleNotFoundError: No module named 'main_etl'
[2025-06-10T14:06:35.405+0000] {processor.py:842} WARNING - No viable dags retrieved from /opt/airflow/dags/etl_pipeline_dag.py
[2025-06-10T14:06:35.466+0000] {processor.py:183} INFO - Processing /opt/airflow/dags/etl_pipeline_dag.py took 0.249 seconds
[2025-06-10T14:07:05.595+0000] {processor.py:161} INFO - Started process (PID=260) to work on /opt/airflow/dags/etl_pipeline_dag.py
[2025-06-10T14:07:05.597+0000] {processor.py:830} INFO - Processing file /opt/airflow/dags/etl_pipeline_dag.py for tasks to queue
[2025-06-10T14:07:05.603+0000] {logging_mixin.py:188} INFO - [2025-06-10T14:07:05.602+0000] {dagbag.py:545} INFO - Filling up the DagBag from /opt/airflow/dags/etl_pipeline_dag.py
[2025-06-10T14:07:05.660+0000] {logging_mixin.py:188} INFO - [2025-06-10T14:07:05.650+0000] {dagbag.py:355} ERROR - Failed to import: /opt/airflow/dags/etl_pipeline_dag.py
Traceback (most recent call last):
  File "/home/airflow/.local/lib/python3.12/site-packages/airflow/models/dagbag.py", line 351, in parse
    loader.exec_module(new_module)
  File "<frozen importlib._bootstrap_external>", line 995, in exec_module
  File "<frozen importlib._bootstrap>", line 488, in _call_with_frames_removed
  File "/opt/airflow/dags/etl_pipeline_dag.py", line 8, in <module>
    from main_etl import run_etl
ModuleNotFoundError: No module named 'main_etl'
[2025-06-10T14:07:05.663+0000] {processor.py:842} WARNING - No viable dags retrieved from /opt/airflow/dags/etl_pipeline_dag.py
[2025-06-10T14:07:05.691+0000] {processor.py:183} INFO - Processing /opt/airflow/dags/etl_pipeline_dag.py took 0.103 seconds
[2025-06-10T14:07:35.949+0000] {processor.py:161} INFO - Started process (PID=265) to work on /opt/airflow/dags/etl_pipeline_dag.py
[2025-06-10T14:07:35.951+0000] {processor.py:830} INFO - Processing file /opt/airflow/dags/etl_pipeline_dag.py for tasks to queue
[2025-06-10T14:07:35.955+0000] {logging_mixin.py:188} INFO - [2025-06-10T14:07:35.955+0000] {dagbag.py:545} INFO - Filling up the DagBag from /opt/airflow/dags/etl_pipeline_dag.py
[2025-06-10T14:07:36.026+0000] {logging_mixin.py:188} INFO - [2025-06-10T14:07:36.015+0000] {dagbag.py:355} ERROR - Failed to import: /opt/airflow/dags/etl_pipeline_dag.py
Traceback (most recent call last):
  File "/home/airflow/.local/lib/python3.12/site-packages/airflow/models/dagbag.py", line 351, in parse
    loader.exec_module(new_module)
  File "<frozen importlib._bootstrap_external>", line 995, in exec_module
  File "<frozen importlib._bootstrap>", line 488, in _call_with_frames_removed
  File "/opt/airflow/dags/etl_pipeline_dag.py", line 8, in <module>
    from main_etl import run_etl
ModuleNotFoundError: No module named 'main_etl'
[2025-06-10T14:07:36.032+0000] {processor.py:842} WARNING - No viable dags retrieved from /opt/airflow/dags/etl_pipeline_dag.py
[2025-06-10T14:07:36.073+0000] {processor.py:183} INFO - Processing /opt/airflow/dags/etl_pipeline_dag.py took 0.137 seconds
[2025-06-10T14:08:06.472+0000] {processor.py:161} INFO - Started process (PID=270) to work on /opt/airflow/dags/etl_pipeline_dag.py
[2025-06-10T14:08:06.473+0000] {processor.py:830} INFO - Processing file /opt/airflow/dags/etl_pipeline_dag.py for tasks to queue
[2025-06-10T14:08:06.482+0000] {logging_mixin.py:188} INFO - [2025-06-10T14:08:06.481+0000] {dagbag.py:545} INFO - Filling up the DagBag from /opt/airflow/dags/etl_pipeline_dag.py
[2025-06-10T14:08:06.564+0000] {logging_mixin.py:188} INFO - [2025-06-10T14:08:06.553+0000] {dagbag.py:355} ERROR - Failed to import: /opt/airflow/dags/etl_pipeline_dag.py
Traceback (most recent call last):
  File "/home/airflow/.local/lib/python3.12/site-packages/airflow/models/dagbag.py", line 351, in parse
    loader.exec_module(new_module)
  File "<frozen importlib._bootstrap_external>", line 995, in exec_module
  File "<frozen importlib._bootstrap>", line 488, in _call_with_frames_removed
  File "/opt/airflow/dags/etl_pipeline_dag.py", line 8, in <module>
    from main_etl import run_etl
ModuleNotFoundError: No module named 'main_etl'
[2025-06-10T14:08:06.567+0000] {processor.py:842} WARNING - No viable dags retrieved from /opt/airflow/dags/etl_pipeline_dag.py
[2025-06-10T14:08:06.654+0000] {processor.py:183} INFO - Processing /opt/airflow/dags/etl_pipeline_dag.py took 0.216 seconds
[2025-06-10T14:08:37.132+0000] {processor.py:161} INFO - Started process (PID=275) to work on /opt/airflow/dags/etl_pipeline_dag.py
[2025-06-10T14:08:37.154+0000] {processor.py:830} INFO - Processing file /opt/airflow/dags/etl_pipeline_dag.py for tasks to queue
[2025-06-10T14:08:37.202+0000] {logging_mixin.py:188} INFO - [2025-06-10T14:08:37.196+0000] {dagbag.py:545} INFO - Filling up the DagBag from /opt/airflow/dags/etl_pipeline_dag.py
[2025-06-10T14:08:37.368+0000] {logging_mixin.py:188} INFO - [2025-06-10T14:08:37.346+0000] {dagbag.py:355} ERROR - Failed to import: /opt/airflow/dags/etl_pipeline_dag.py
Traceback (most recent call last):
  File "/home/airflow/.local/lib/python3.12/site-packages/airflow/models/dagbag.py", line 351, in parse
    loader.exec_module(new_module)
  File "<frozen importlib._bootstrap_external>", line 995, in exec_module
  File "<frozen importlib._bootstrap>", line 488, in _call_with_frames_removed
  File "/opt/airflow/dags/etl_pipeline_dag.py", line 8, in <module>
    from main_etl import run_etl
ModuleNotFoundError: No module named 'main_etl'
[2025-06-10T14:08:37.376+0000] {processor.py:842} WARNING - No viable dags retrieved from /opt/airflow/dags/etl_pipeline_dag.py
[2025-06-10T14:08:38.090+0000] {processor.py:183} INFO - Processing /opt/airflow/dags/etl_pipeline_dag.py took 1.103 seconds
[2025-06-10T14:09:08.213+0000] {processor.py:161} INFO - Started process (PID=280) to work on /opt/airflow/dags/etl_pipeline_dag.py
[2025-06-10T14:09:08.215+0000] {processor.py:830} INFO - Processing file /opt/airflow/dags/etl_pipeline_dag.py for tasks to queue
[2025-06-10T14:09:08.218+0000] {logging_mixin.py:188} INFO - [2025-06-10T14:09:08.218+0000] {dagbag.py:545} INFO - Filling up the DagBag from /opt/airflow/dags/etl_pipeline_dag.py
[2025-06-10T14:09:08.272+0000] {logging_mixin.py:188} INFO - [2025-06-10T14:09:08.262+0000] {dagbag.py:355} ERROR - Failed to import: /opt/airflow/dags/etl_pipeline_dag.py
Traceback (most recent call last):
  File "/home/airflow/.local/lib/python3.12/site-packages/airflow/models/dagbag.py", line 351, in parse
    loader.exec_module(new_module)
  File "<frozen importlib._bootstrap_external>", line 995, in exec_module
  File "<frozen importlib._bootstrap>", line 488, in _call_with_frames_removed
  File "/opt/airflow/dags/etl_pipeline_dag.py", line 8, in <module>
    from main_etl import run_etl
ModuleNotFoundError: No module named 'main_etl'
[2025-06-10T14:09:08.275+0000] {processor.py:842} WARNING - No viable dags retrieved from /opt/airflow/dags/etl_pipeline_dag.py
[2025-06-10T14:09:08.314+0000] {processor.py:183} INFO - Processing /opt/airflow/dags/etl_pipeline_dag.py took 0.106 seconds
[2025-06-10T14:09:38.505+0000] {processor.py:161} INFO - Started process (PID=285) to work on /opt/airflow/dags/etl_pipeline_dag.py
[2025-06-10T14:09:38.507+0000] {processor.py:830} INFO - Processing file /opt/airflow/dags/etl_pipeline_dag.py for tasks to queue
[2025-06-10T14:09:38.510+0000] {logging_mixin.py:188} INFO - [2025-06-10T14:09:38.510+0000] {dagbag.py:545} INFO - Filling up the DagBag from /opt/airflow/dags/etl_pipeline_dag.py
[2025-06-10T14:09:38.567+0000] {logging_mixin.py:188} INFO - [2025-06-10T14:09:38.556+0000] {dagbag.py:355} ERROR - Failed to import: /opt/airflow/dags/etl_pipeline_dag.py
Traceback (most recent call last):
  File "/home/airflow/.local/lib/python3.12/site-packages/airflow/models/dagbag.py", line 351, in parse
    loader.exec_module(new_module)
  File "<frozen importlib._bootstrap_external>", line 995, in exec_module
  File "<frozen importlib._bootstrap>", line 488, in _call_with_frames_removed
  File "/opt/airflow/dags/etl_pipeline_dag.py", line 8, in <module>
    from main_etl import run_etl
ModuleNotFoundError: No module named 'main_etl'
[2025-06-10T14:09:38.571+0000] {processor.py:842} WARNING - No viable dags retrieved from /opt/airflow/dags/etl_pipeline_dag.py
[2025-06-10T14:09:38.627+0000] {processor.py:183} INFO - Processing /opt/airflow/dags/etl_pipeline_dag.py took 0.132 seconds
[2025-06-10T14:10:08.878+0000] {processor.py:161} INFO - Started process (PID=290) to work on /opt/airflow/dags/etl_pipeline_dag.py
[2025-06-10T14:10:08.880+0000] {processor.py:830} INFO - Processing file /opt/airflow/dags/etl_pipeline_dag.py for tasks to queue
[2025-06-10T14:10:08.884+0000] {logging_mixin.py:188} INFO - [2025-06-10T14:10:08.883+0000] {dagbag.py:545} INFO - Filling up the DagBag from /opt/airflow/dags/etl_pipeline_dag.py
[2025-06-10T14:10:08.936+0000] {logging_mixin.py:188} INFO - [2025-06-10T14:10:08.928+0000] {dagbag.py:355} ERROR - Failed to import: /opt/airflow/dags/etl_pipeline_dag.py
Traceback (most recent call last):
  File "/home/airflow/.local/lib/python3.12/site-packages/airflow/models/dagbag.py", line 351, in parse
    loader.exec_module(new_module)
  File "<frozen importlib._bootstrap_external>", line 995, in exec_module
  File "<frozen importlib._bootstrap>", line 488, in _call_with_frames_removed
  File "/opt/airflow/dags/etl_pipeline_dag.py", line 8, in <module>
    from main_etl import run_etl
ModuleNotFoundError: No module named 'main_etl'
[2025-06-10T14:10:08.938+0000] {processor.py:842} WARNING - No viable dags retrieved from /opt/airflow/dags/etl_pipeline_dag.py
[2025-06-10T14:10:08.966+0000] {processor.py:183} INFO - Processing /opt/airflow/dags/etl_pipeline_dag.py took 0.094 seconds
[2025-06-10T14:10:39.146+0000] {processor.py:161} INFO - Started process (PID=295) to work on /opt/airflow/dags/etl_pipeline_dag.py
[2025-06-10T14:10:39.148+0000] {processor.py:830} INFO - Processing file /opt/airflow/dags/etl_pipeline_dag.py for tasks to queue
[2025-06-10T14:10:39.150+0000] {logging_mixin.py:188} INFO - [2025-06-10T14:10:39.150+0000] {dagbag.py:545} INFO - Filling up the DagBag from /opt/airflow/dags/etl_pipeline_dag.py
[2025-06-10T14:10:39.210+0000] {logging_mixin.py:188} INFO - [2025-06-10T14:10:39.200+0000] {dagbag.py:355} ERROR - Failed to import: /opt/airflow/dags/etl_pipeline_dag.py
Traceback (most recent call last):
  File "/home/airflow/.local/lib/python3.12/site-packages/airflow/models/dagbag.py", line 351, in parse
    loader.exec_module(new_module)
  File "<frozen importlib._bootstrap_external>", line 995, in exec_module
  File "<frozen importlib._bootstrap>", line 488, in _call_with_frames_removed
  File "/opt/airflow/dags/etl_pipeline_dag.py", line 8, in <module>
    from main_etl import run_etl
ModuleNotFoundError: No module named 'main_etl'
[2025-06-10T14:10:39.213+0000] {processor.py:842} WARNING - No viable dags retrieved from /opt/airflow/dags/etl_pipeline_dag.py
[2025-06-10T14:10:39.235+0000] {processor.py:183} INFO - Processing /opt/airflow/dags/etl_pipeline_dag.py took 0.094 seconds
[2025-06-10T14:11:09.543+0000] {processor.py:161} INFO - Started process (PID=300) to work on /opt/airflow/dags/etl_pipeline_dag.py
[2025-06-10T14:11:09.546+0000] {processor.py:830} INFO - Processing file /opt/airflow/dags/etl_pipeline_dag.py for tasks to queue
[2025-06-10T14:11:09.550+0000] {logging_mixin.py:188} INFO - [2025-06-10T14:11:09.550+0000] {dagbag.py:545} INFO - Filling up the DagBag from /opt/airflow/dags/etl_pipeline_dag.py
[2025-06-10T14:11:09.623+0000] {logging_mixin.py:188} INFO - [2025-06-10T14:11:09.610+0000] {dagbag.py:355} ERROR - Failed to import: /opt/airflow/dags/etl_pipeline_dag.py
Traceback (most recent call last):
  File "/home/airflow/.local/lib/python3.12/site-packages/airflow/models/dagbag.py", line 351, in parse
    loader.exec_module(new_module)
  File "<frozen importlib._bootstrap_external>", line 995, in exec_module
  File "<frozen importlib._bootstrap>", line 488, in _call_with_frames_removed
  File "/opt/airflow/dags/etl_pipeline_dag.py", line 8, in <module>
    from main_etl import run_etl
ModuleNotFoundError: No module named 'main_etl'
[2025-06-10T14:11:09.627+0000] {processor.py:842} WARNING - No viable dags retrieved from /opt/airflow/dags/etl_pipeline_dag.py
[2025-06-10T14:11:09.653+0000] {processor.py:183} INFO - Processing /opt/airflow/dags/etl_pipeline_dag.py took 0.119 seconds
[2025-06-10T14:11:39.851+0000] {processor.py:161} INFO - Started process (PID=305) to work on /opt/airflow/dags/etl_pipeline_dag.py
[2025-06-10T14:11:39.853+0000] {processor.py:830} INFO - Processing file /opt/airflow/dags/etl_pipeline_dag.py for tasks to queue
[2025-06-10T14:11:39.855+0000] {logging_mixin.py:188} INFO - [2025-06-10T14:11:39.855+0000] {dagbag.py:545} INFO - Filling up the DagBag from /opt/airflow/dags/etl_pipeline_dag.py
[2025-06-10T14:11:39.924+0000] {logging_mixin.py:188} INFO - [2025-06-10T14:11:39.913+0000] {dagbag.py:355} ERROR - Failed to import: /opt/airflow/dags/etl_pipeline_dag.py
Traceback (most recent call last):
  File "/home/airflow/.local/lib/python3.12/site-packages/airflow/models/dagbag.py", line 351, in parse
    loader.exec_module(new_module)
  File "<frozen importlib._bootstrap_external>", line 995, in exec_module
  File "<frozen importlib._bootstrap>", line 488, in _call_with_frames_removed
  File "/opt/airflow/dags/etl_pipeline_dag.py", line 8, in <module>
    from main_etl import run_etl
ModuleNotFoundError: No module named 'main_etl'
[2025-06-10T14:11:39.928+0000] {processor.py:842} WARNING - No viable dags retrieved from /opt/airflow/dags/etl_pipeline_dag.py
[2025-06-10T14:11:40.000+0000] {processor.py:183} INFO - Processing /opt/airflow/dags/etl_pipeline_dag.py took 0.162 seconds
[2025-06-10T14:12:10.231+0000] {processor.py:161} INFO - Started process (PID=310) to work on /opt/airflow/dags/etl_pipeline_dag.py
[2025-06-10T14:12:10.235+0000] {processor.py:830} INFO - Processing file /opt/airflow/dags/etl_pipeline_dag.py for tasks to queue
[2025-06-10T14:12:10.239+0000] {logging_mixin.py:188} INFO - [2025-06-10T14:12:10.239+0000] {dagbag.py:545} INFO - Filling up the DagBag from /opt/airflow/dags/etl_pipeline_dag.py
[2025-06-10T14:12:10.300+0000] {logging_mixin.py:188} INFO - [2025-06-10T14:12:10.291+0000] {dagbag.py:355} ERROR - Failed to import: /opt/airflow/dags/etl_pipeline_dag.py
Traceback (most recent call last):
  File "/home/airflow/.local/lib/python3.12/site-packages/airflow/models/dagbag.py", line 351, in parse
    loader.exec_module(new_module)
  File "<frozen importlib._bootstrap_external>", line 995, in exec_module
  File "<frozen importlib._bootstrap>", line 488, in _call_with_frames_removed
  File "/opt/airflow/dags/etl_pipeline_dag.py", line 8, in <module>
    from main_etl import run_etl
ModuleNotFoundError: No module named 'main_etl'
[2025-06-10T14:12:10.303+0000] {processor.py:842} WARNING - No viable dags retrieved from /opt/airflow/dags/etl_pipeline_dag.py
[2025-06-10T14:12:10.339+0000] {processor.py:183} INFO - Processing /opt/airflow/dags/etl_pipeline_dag.py took 0.115 seconds
[2025-06-10T14:12:40.662+0000] {processor.py:161} INFO - Started process (PID=315) to work on /opt/airflow/dags/etl_pipeline_dag.py
[2025-06-10T14:12:40.667+0000] {processor.py:830} INFO - Processing file /opt/airflow/dags/etl_pipeline_dag.py for tasks to queue
[2025-06-10T14:12:40.674+0000] {logging_mixin.py:188} INFO - [2025-06-10T14:12:40.673+0000] {dagbag.py:545} INFO - Filling up the DagBag from /opt/airflow/dags/etl_pipeline_dag.py
[2025-06-10T14:12:40.776+0000] {logging_mixin.py:188} INFO - [2025-06-10T14:12:40.760+0000] {dagbag.py:355} ERROR - Failed to import: /opt/airflow/dags/etl_pipeline_dag.py
Traceback (most recent call last):
  File "/home/airflow/.local/lib/python3.12/site-packages/airflow/models/dagbag.py", line 351, in parse
    loader.exec_module(new_module)
  File "<frozen importlib._bootstrap_external>", line 995, in exec_module
  File "<frozen importlib._bootstrap>", line 488, in _call_with_frames_removed
  File "/opt/airflow/dags/etl_pipeline_dag.py", line 8, in <module>
    from main_etl import run_etl
ModuleNotFoundError: No module named 'main_etl'
[2025-06-10T14:12:40.781+0000] {processor.py:842} WARNING - No viable dags retrieved from /opt/airflow/dags/etl_pipeline_dag.py
[2025-06-10T14:12:40.853+0000] {processor.py:183} INFO - Processing /opt/airflow/dags/etl_pipeline_dag.py took 0.204 seconds
