[2025-06-16T13:20:16.287+0000] {local_task_job_runner.py:120} INFO - ::group::Pre task execution logs
[2025-06-16T13:20:16.489+0000] {taskinstance.py:2076} INFO - Dependencies all met for dep_context=non-requeueable deps ti=<TaskInstance: etl_brazil_pipeline.run_dbt_models manual__2025-06-16T13:10:01.496652+00:00 [queued]>
[2025-06-16T13:20:16.515+0000] {taskinstance.py:2076} INFO - Dependencies all met for dep_context=requeueable deps ti=<TaskInstance: etl_brazil_pipeline.run_dbt_models manual__2025-06-16T13:10:01.496652+00:00 [queued]>
[2025-06-16T13:20:16.516+0000] {taskinstance.py:2306} INFO - Starting attempt 2 of 2
[2025-06-16T13:20:16.565+0000] {taskinstance.py:2330} INFO - Executing <Task(BashOperator): run_dbt_models> on 2025-06-16 13:10:01.496652+00:00
[2025-06-16T13:20:16.649+0000] {standard_task_runner.py:90} INFO - Running: ['airflow', 'tasks', 'run', 'etl_brazil_pipeline', 'run_dbt_models', 'manual__2025-06-16T13:10:01.496652+00:00', '--job-id', '52', '--raw', '--subdir', 'DAGS_FOLDER/etl_brazil_pipeline.py', '--cfg-path', '/tmp/tmpa_nuipy8']
[2025-06-16T13:20:16.649+0000] {warnings.py:110} WARNING - /home/airflow/.local/lib/python3.12/site-packages/airflow/task/task_runner/standard_task_runner.py:61: DeprecationWarning: This process (pid=604) is multi-threaded, use of fork() may lead to deadlocks in the child.
  pid = os.fork()

[2025-06-16T13:20:16.662+0000] {standard_task_runner.py:91} INFO - Job 52: Subtask run_dbt_models
[2025-06-16T13:20:16.664+0000] {standard_task_runner.py:63} INFO - Started process 618 to run task
[2025-06-16T13:20:16.867+0000] {warnings.py:110} WARNING - /home/airflow/.local/lib/python3.12/site-packages/airflow/settings.py:195: DeprecationWarning: The sql_alchemy_conn option in [core] has been moved to the sql_alchemy_conn option in [database] - the old setting has been used, but please update your config.
  SQL_ALCHEMY_CONN = conf.get("database", "SQL_ALCHEMY_CONN")

[2025-06-16T13:20:17.254+0000] {task_command.py:426} INFO - Running <TaskInstance: etl_brazil_pipeline.run_dbt_models manual__2025-06-16T13:10:01.496652+00:00 [running]> on host 5af264b1066b
[2025-06-16T13:20:17.775+0000] {taskinstance.py:2648} INFO - Exporting env vars: AIRFLOW_CTX_DAG_OWNER='vaishnavi' AIRFLOW_CTX_DAG_ID='etl_brazil_pipeline' AIRFLOW_CTX_TASK_ID='run_dbt_models' AIRFLOW_CTX_EXECUTION_DATE='2025-06-16T13:10:01.496652+00:00' AIRFLOW_CTX_TRY_NUMBER='2' AIRFLOW_CTX_DAG_RUN_ID='manual__2025-06-16T13:10:01.496652+00:00'
[2025-06-16T13:20:17.777+0000] {taskinstance.py:430} INFO - ::endgroup::
[2025-06-16T13:20:17.823+0000] {subprocess.py:63} INFO - Tmp dir root location: /tmp
[2025-06-16T13:20:17.838+0000] {subprocess.py:75} INFO - Running command: ['/usr/bin/bash', '-c', 'cd /opt/airflow/dbt_project && /home/airflow/.local/bin/dbt run']
[2025-06-16T13:20:17.891+0000] {subprocess.py:86} INFO - Output:
[2025-06-16T13:20:29.177+0000] {subprocess.py:93} INFO - [0m13:20:29  Running with dbt=1.7.9
[2025-06-16T13:20:29.218+0000] {subprocess.py:93} INFO - [0m13:20:29  Encountered an error:
[2025-06-16T13:20:29.221+0000] {subprocess.py:93} INFO - Runtime Error
[2025-06-16T13:20:29.224+0000] {subprocess.py:93} INFO -   Could not find profile named 'dbt_project'
[2025-06-16T13:20:30.701+0000] {subprocess.py:97} INFO - Command exited with return code 2
[2025-06-16T13:20:30.717+0000] {taskinstance.py:441} INFO - ::group::Post task execution logs
[2025-06-16T13:20:30.779+0000] {taskinstance.py:2905} ERROR - Task failed with exception
Traceback (most recent call last):
  File "/home/airflow/.local/lib/python3.12/site-packages/airflow/models/taskinstance.py", line 465, in _execute_task
    result = _execute_callable(context=context, **execute_callable_kwargs)
             ^^^^^^^^^^^^^^^^^^^^^^^^^^^^^^^^^^^^^^^^^^^^^^^^^^^^^^^^^^^^^
  File "/home/airflow/.local/lib/python3.12/site-packages/airflow/models/taskinstance.py", line 432, in _execute_callable
    return execute_callable(context=context, **execute_callable_kwargs)
           ^^^^^^^^^^^^^^^^^^^^^^^^^^^^^^^^^^^^^^^^^^^^^^^^^^^^^^^^^^^^
  File "/home/airflow/.local/lib/python3.12/site-packages/airflow/models/baseoperator.py", line 400, in wrapper
    return func(self, *args, **kwargs)
           ^^^^^^^^^^^^^^^^^^^^^^^^^^^
  File "/home/airflow/.local/lib/python3.12/site-packages/airflow/operators/bash.py", line 243, in execute
    raise AirflowException(
airflow.exceptions.AirflowException: Bash command failed. The command returned a non-zero exit code 2.
[2025-06-16T13:20:30.807+0000] {taskinstance.py:1206} INFO - Marking task as FAILED. dag_id=etl_brazil_pipeline, task_id=run_dbt_models, run_id=manual__2025-06-16T13:10:01.496652+00:00, execution_date=20250616T131001, start_date=20250616T132016, end_date=20250616T132030
[2025-06-16T13:20:30.900+0000] {standard_task_runner.py:110} ERROR - Failed to execute job 52 for task run_dbt_models (Bash command failed. The command returned a non-zero exit code 2.; 618)
[2025-06-16T13:20:30.963+0000] {local_task_job_runner.py:240} INFO - Task exited with return code 1
[2025-06-16T13:20:31.047+0000] {taskinstance.py:3498} INFO - 0 downstream tasks scheduled from follow-on schedule check
[2025-06-16T13:20:31.063+0000] {local_task_job_runner.py:222} INFO - ::endgroup::
