[2025-06-16T09:59:30.697+0000] {local_task_job_runner.py:120} INFO - ::group::Pre task execution logs
[2025-06-16T09:59:30.734+0000] {taskinstance.py:2076} INFO - Dependencies all met for dep_context=non-requeueable deps ti=<TaskInstance: etl_brazil_pipeline.run_ge_validation manual__2025-06-16T09:55:18.909208+00:00 [queued]>
[2025-06-16T09:59:30.743+0000] {taskinstance.py:2076} INFO - Dependencies all met for dep_context=requeueable deps ti=<TaskInstance: etl_brazil_pipeline.run_ge_validation manual__2025-06-16T09:55:18.909208+00:00 [queued]>
[2025-06-16T09:59:30.745+0000] {taskinstance.py:2306} INFO - Starting attempt 1 of 2
[2025-06-16T09:59:30.759+0000] {taskinstance.py:2330} INFO - Executing <Task(BashOperator): run_ge_validation> on 2025-06-16 09:55:18.909208+00:00
[2025-06-16T09:59:30.771+0000] {logging_mixin.py:188} WARNING - /home/airflow/.local/lib/python3.12/site-packages/airflow/task/task_runner/standard_task_runner.py:61 DeprecationWarning: This process (pid=593) is multi-threaded, use of fork() may lead to deadlocks in the child.
[2025-06-16T09:59:30.771+0000] {standard_task_runner.py:90} INFO - Running: ['airflow', 'tasks', 'run', 'etl_brazil_pipeline', 'run_ge_validation', 'manual__2025-06-16T09:55:18.909208+00:00', '--job-id', '10', '--raw', '--subdir', 'DAGS_FOLDER/etl_brazil_pipeline.py', '--cfg-path', '/tmp/tmpgg08f2t5']
[2025-06-16T09:59:30.772+0000] {standard_task_runner.py:63} INFO - Started process 594 to run task
[2025-06-16T09:59:30.773+0000] {standard_task_runner.py:91} INFO - Job 10: Subtask run_ge_validation
[2025-06-16T09:59:30.796+0000] {logging_mixin.py:188} WARNING - /home/airflow/.local/lib/python3.12/site-packages/airflow/settings.py:195 DeprecationWarning: The sql_alchemy_conn option in [core] has been moved to the sql_alchemy_conn option in [database] - the old setting has been used, but please update your config.
[2025-06-16T09:59:30.837+0000] {task_command.py:426} INFO - Running <TaskInstance: etl_brazil_pipeline.run_ge_validation manual__2025-06-16T09:55:18.909208+00:00 [running]> on host 4efd89753c65
[2025-06-16T09:59:30.949+0000] {taskinstance.py:2648} INFO - Exporting env vars: AIRFLOW_CTX_DAG_OWNER='vaishnavi' AIRFLOW_CTX_DAG_ID='etl_brazil_pipeline' AIRFLOW_CTX_TASK_ID='run_ge_validation' AIRFLOW_CTX_EXECUTION_DATE='2025-06-16T09:55:18.909208+00:00' AIRFLOW_CTX_TRY_NUMBER='1' AIRFLOW_CTX_DAG_RUN_ID='manual__2025-06-16T09:55:18.909208+00:00'
[2025-06-16T09:59:30.951+0000] {taskinstance.py:430} INFO - ::endgroup::
[2025-06-16T09:59:30.977+0000] {subprocess.py:63} INFO - Tmp dir root location: /tmp
[2025-06-16T09:59:30.982+0000] {subprocess.py:75} INFO - Running command: ['/usr/bin/bash', '-c', 'python3 /opt/airflow/src/etl/validate_data.py processed_sales.csv']
[2025-06-16T09:59:30.993+0000] {subprocess.py:86} INFO - Output:
[2025-06-16T09:59:46.588+0000] {subprocess.py:93} INFO - /home/airflow/.local/lib/python3.12/site-packages/sqlalchemy_redshift/commands.py:31: SyntaxWarning: invalid escape sequence '\-'
[2025-06-16T09:59:46.598+0000] {subprocess.py:93} INFO -   IAM_ROLE_NAME_RE = re.compile('[A-Za-z0-9+=,.@\-_]{1,64}')  # noqa
[2025-06-16T09:59:46.599+0000] {subprocess.py:93} INFO - /home/airflow/.local/lib/python3.12/site-packages/sqlalchemy_redshift/commands.py:33: SyntaxWarning: invalid escape sequence '\-'
[2025-06-16T09:59:46.601+0000] {subprocess.py:93} INFO -   '[0-9]{12}:role/[A-Za-z0-9+=,.@\-_]{1,64}')  # noqa
[2025-06-16T10:00:01.033+0000] {subprocess.py:93} INFO - Traceback (most recent call last):
[2025-06-16T10:00:01.046+0000] {subprocess.py:93} INFO -   File "/home/airflow/.local/lib/python3.12/site-packages/great_expectations/data_context/store/in_memory_store_backend.py", line 56, in _get
[2025-06-16T10:00:01.047+0000] {subprocess.py:93} INFO -     return self._store[key]
[2025-06-16T10:00:01.049+0000] {subprocess.py:93} INFO -            ~~~~~~~~~~~^^^^^
[2025-06-16T10:00:01.051+0000] {subprocess.py:93} INFO - KeyError: ('validation_checkpoint',)
[2025-06-16T10:00:01.053+0000] {subprocess.py:93} INFO - 
[2025-06-16T10:00:01.055+0000] {subprocess.py:93} INFO - During handling of the above exception, another exception occurred:
[2025-06-16T10:00:01.057+0000] {subprocess.py:93} INFO - 
[2025-06-16T10:00:01.059+0000] {subprocess.py:93} INFO - Traceback (most recent call last):
[2025-06-16T10:00:01.060+0000] {subprocess.py:93} INFO -   File "/home/airflow/.local/lib/python3.12/site-packages/great_expectations/data_context/store/checkpoint_store.py", line 154, in get_checkpoint
[2025-06-16T10:00:01.063+0000] {subprocess.py:93} INFO -     checkpoint_config: Optional[Any] = self.get(key=key)
[2025-06-16T10:00:01.064+0000] {subprocess.py:93} INFO -                                        ^^^^^^^^^^^^^^^^^
[2025-06-16T10:00:01.065+0000] {subprocess.py:93} INFO -   File "/home/airflow/.local/lib/python3.12/site-packages/great_expectations/data_context/store/store.py", line 212, in get
[2025-06-16T10:00:01.068+0000] {subprocess.py:93} INFO -     value = self._store_backend.get(self.key_to_tuple(key))
[2025-06-16T10:00:01.072+0000] {subprocess.py:93} INFO -             ^^^^^^^^^^^^^^^^^^^^^^^^^^^^^^^^^^^^^^^^^^^^^^^
[2025-06-16T10:00:01.075+0000] {subprocess.py:93} INFO -   File "/home/airflow/.local/lib/python3.12/site-packages/great_expectations/data_context/store/_store_backend.py", line 123, in get
[2025-06-16T10:00:01.076+0000] {subprocess.py:93} INFO -     value = self._get(key, **kwargs)
[2025-06-16T10:00:01.078+0000] {subprocess.py:93} INFO -             ^^^^^^^^^^^^^^^^^^^^^^^^
[2025-06-16T10:00:01.081+0000] {subprocess.py:93} INFO -   File "/home/airflow/.local/lib/python3.12/site-packages/great_expectations/data_context/store/in_memory_store_backend.py", line 58, in _get
[2025-06-16T10:00:01.085+0000] {subprocess.py:93} INFO -     raise InvalidKeyError(f"{e!s}")
[2025-06-16T10:00:01.088+0000] {subprocess.py:93} INFO - great_expectations.exceptions.exceptions.InvalidKeyError: ('validation_checkpoint',)
[2025-06-16T10:00:01.091+0000] {subprocess.py:93} INFO - 
[2025-06-16T10:00:01.092+0000] {subprocess.py:93} INFO - During handling of the above exception, another exception occurred:
[2025-06-16T10:00:01.094+0000] {subprocess.py:93} INFO - 
[2025-06-16T10:00:01.096+0000] {subprocess.py:93} INFO - Traceback (most recent call last):
[2025-06-16T10:00:01.097+0000] {subprocess.py:93} INFO -   File "/opt/airflow/src/etl/validate_data.py", line 38, in <module>
[2025-06-16T10:00:01.099+0000] {subprocess.py:93} INFO -     validate_data(data_file)
[2025-06-16T10:00:01.100+0000] {subprocess.py:93} INFO -   File "/opt/airflow/src/etl/validate_data.py", line 17, in validate_data
[2025-06-16T10:00:01.101+0000] {subprocess.py:93} INFO -     results = context.run_checkpoint(
[2025-06-16T10:00:01.102+0000] {subprocess.py:93} INFO -               ^^^^^^^^^^^^^^^^^^^^^^^
[2025-06-16T10:00:01.103+0000] {subprocess.py:93} INFO -   File "/home/airflow/.local/lib/python3.12/site-packages/great_expectations/core/usage_statistics/usage_statistics.py", line 260, in usage_statistics_wrapped_method
[2025-06-16T10:00:01.105+0000] {subprocess.py:93} INFO -     result = func(*args, **kwargs)
[2025-06-16T10:00:01.106+0000] {subprocess.py:93} INFO -              ^^^^^^^^^^^^^^^^^^^^^
[2025-06-16T10:00:01.107+0000] {subprocess.py:93} INFO -   File "/home/airflow/.local/lib/python3.12/site-packages/great_expectations/data_context/data_context/abstract_data_context.py", line 2215, in run_checkpoint
[2025-06-16T10:00:01.109+0000] {subprocess.py:93} INFO -     return self._run_checkpoint(
[2025-06-16T10:00:01.110+0000] {subprocess.py:93} INFO -            ^^^^^^^^^^^^^^^^^^^^^
[2025-06-16T10:00:01.111+0000] {subprocess.py:93} INFO -   File "/home/airflow/.local/lib/python3.12/site-packages/great_expectations/data_context/data_context/abstract_data_context.py", line 2255, in _run_checkpoint
[2025-06-16T10:00:01.114+0000] {subprocess.py:93} INFO -     checkpoint: Checkpoint = self.get_checkpoint(
[2025-06-16T10:00:01.116+0000] {subprocess.py:93} INFO -                              ^^^^^^^^^^^^^^^^^^^^
[2025-06-16T10:00:01.117+0000] {subprocess.py:93} INFO -   File "/home/airflow/.local/lib/python3.12/site-packages/great_expectations/data_context/data_context/abstract_data_context.py", line 2106, in get_checkpoint
[2025-06-16T10:00:01.119+0000] {subprocess.py:93} INFO -     checkpoint_config: CheckpointConfig = self.checkpoint_store.get_checkpoint(
[2025-06-16T10:00:01.120+0000] {subprocess.py:93} INFO -                                           ^^^^^^^^^^^^^^^^^^^^^^^^^^^^^^^^^^^^^
[2025-06-16T10:00:01.122+0000] {subprocess.py:93} INFO -   File "/home/airflow/.local/lib/python3.12/site-packages/great_expectations/data_context/store/checkpoint_store.py", line 159, in get_checkpoint
[2025-06-16T10:00:01.123+0000] {subprocess.py:93} INFO -     raise gx_exceptions.CheckpointNotFoundError(
[2025-06-16T10:00:01.125+0000] {subprocess.py:93} INFO - great_expectations.exceptions.exceptions.CheckpointNotFoundError: Non-existent Checkpoint configuration named "validation_checkpoint".
[2025-06-16T10:00:01.126+0000] {subprocess.py:93} INFO - 
[2025-06-16T10:00:01.128+0000] {subprocess.py:93} INFO - Details: ('validation_checkpoint',)
[2025-06-16T10:00:03.051+0000] {subprocess.py:97} INFO - Command exited with return code 1
[2025-06-16T10:00:03.063+0000] {taskinstance.py:441} INFO - ::group::Post task execution logs
[2025-06-16T10:00:03.189+0000] {taskinstance.py:2905} ERROR - Task failed with exception
Traceback (most recent call last):
  File "/home/airflow/.local/lib/python3.12/site-packages/airflow/models/taskinstance.py", line 465, in _execute_task
    result = _execute_callable(context=context, **execute_callable_kwargs)
             ^^^^^^^^^^^^^^^^^^^^^^^^^^^^^^^^^^^^^^^^^^^^^^^^^^^^^^^^^^^^^
  File "/home/airflow/.local/lib/python3.12/site-packages/airflow/models/taskinstance.py", line 432, in _execute_callable
    return execute_callable(context=context, **execute_callable_kwargs)
           ^^^^^^^^^^^^^^^^^^^^^^^^^^^^^^^^^^^^^^^^^^^^^^^^^^^^^^^^^^^^
  File "/home/airflow/.local/lib/python3.12/site-packages/airflow/models/baseoperator.py", line 400, in wrapper
    return func(self, *args, **kwargs)
           ^^^^^^^^^^^^^^^^^^^^^^^^^^^
  File "/home/airflow/.local/lib/python3.12/site-packages/airflow/operators/bash.py", line 243, in execute
    raise AirflowException(
airflow.exceptions.AirflowException: Bash command failed. The command returned a non-zero exit code 1.
[2025-06-16T10:00:03.227+0000] {taskinstance.py:1206} INFO - Marking task as UP_FOR_RETRY. dag_id=etl_brazil_pipeline, task_id=run_ge_validation, run_id=manual__2025-06-16T09:55:18.909208+00:00, execution_date=20250616T095518, start_date=20250616T095930, end_date=20250616T100003
[2025-06-16T10:00:03.329+0000] {standard_task_runner.py:110} ERROR - Failed to execute job 10 for task run_ge_validation (Bash command failed. The command returned a non-zero exit code 1.; 594)
[2025-06-16T10:00:03.455+0000] {local_task_job_runner.py:240} INFO - Task exited with return code 1
[2025-06-16T10:00:03.631+0000] {taskinstance.py:3498} INFO - 0 downstream tasks scheduled from follow-on schedule check
[2025-06-16T10:00:03.638+0000] {local_task_job_runner.py:222} INFO - ::endgroup::
