[2025-06-16T10:06:10.252+0000] {local_task_job_runner.py:120} INFO - ::group::Pre task execution logs
[2025-06-16T10:06:10.702+0000] {taskinstance.py:2076} INFO - Dependencies all met for dep_context=non-requeueable deps ti=<TaskInstance: etl_brazil_pipeline.run_ge_validation manual__2025-06-16T09:55:18.909208+00:00 [queued]>
[2025-06-16T10:06:10.787+0000] {taskinstance.py:2076} INFO - Dependencies all met for dep_context=requeueable deps ti=<TaskInstance: etl_brazil_pipeline.run_ge_validation manual__2025-06-16T09:55:18.909208+00:00 [queued]>
[2025-06-16T10:06:10.791+0000] {taskinstance.py:2306} INFO - Starting attempt 2 of 2
[2025-06-16T10:06:10.880+0000] {taskinstance.py:2330} INFO - Executing <Task(BashOperator): run_ge_validation> on 2025-06-16 09:55:18.909208+00:00
[2025-06-16T10:06:11.271+0000] {logging_mixin.py:188} WARNING - /home/airflow/.local/lib/python3.12/site-packages/airflow/task/task_runner/standard_task_runner.py:61 DeprecationWarning: This process (pid=225) is multi-threaded, use of fork() may lead to deadlocks in the child.
[2025-06-16T10:06:11.381+0000] {standard_task_runner.py:63} INFO - Started process 228 to run task
[2025-06-16T10:06:11.241+0000] {standard_task_runner.py:90} INFO - Running: ['airflow', 'tasks', 'run', 'etl_brazil_pipeline', 'run_ge_validation', 'manual__2025-06-16T09:55:18.909208+00:00', '--job-id', '12', '--raw', '--subdir', 'DAGS_FOLDER/etl_brazil_pipeline.py', '--cfg-path', '/tmp/tmph9pjz5xz']
[2025-06-16T10:06:11.432+0000] {standard_task_runner.py:91} INFO - Job 12: Subtask run_ge_validation
[2025-06-16T10:06:11.753+0000] {logging_mixin.py:188} WARNING - /home/airflow/.local/lib/python3.12/site-packages/airflow/settings.py:195 DeprecationWarning: The sql_alchemy_conn option in [core] has been moved to the sql_alchemy_conn option in [database] - the old setting has been used, but please update your config.
[2025-06-16T10:06:12.194+0000] {task_command.py:426} INFO - Running <TaskInstance: etl_brazil_pipeline.run_ge_validation manual__2025-06-16T09:55:18.909208+00:00 [running]> on host 155077edd2ca
[2025-06-16T10:06:13.362+0000] {taskinstance.py:2648} INFO - Exporting env vars: AIRFLOW_CTX_DAG_OWNER='vaishnavi' AIRFLOW_CTX_DAG_ID='etl_brazil_pipeline' AIRFLOW_CTX_TASK_ID='run_ge_validation' AIRFLOW_CTX_EXECUTION_DATE='2025-06-16T09:55:18.909208+00:00' AIRFLOW_CTX_TRY_NUMBER='2' AIRFLOW_CTX_DAG_RUN_ID='manual__2025-06-16T09:55:18.909208+00:00'
[2025-06-16T10:06:13.367+0000] {taskinstance.py:430} INFO - ::endgroup::
[2025-06-16T10:06:13.685+0000] {subprocess.py:63} INFO - Tmp dir root location: /tmp
[2025-06-16T10:06:13.689+0000] {subprocess.py:75} INFO - Running command: ['/usr/bin/bash', '-c', 'python3 /opt/airflow/src/etl/validate_data.py processed_sales.csv']
[2025-06-16T10:06:13.717+0000] {subprocess.py:86} INFO - Output:
[2025-06-16T10:06:29.660+0000] {subprocess.py:93} INFO - /home/airflow/.local/lib/python3.12/site-packages/sqlalchemy_redshift/commands.py:31: SyntaxWarning: invalid escape sequence '\-'
[2025-06-16T10:06:29.661+0000] {subprocess.py:93} INFO -   IAM_ROLE_NAME_RE = re.compile('[A-Za-z0-9+=,.@\-_]{1,64}')  # noqa
[2025-06-16T10:06:29.663+0000] {subprocess.py:93} INFO - /home/airflow/.local/lib/python3.12/site-packages/sqlalchemy_redshift/commands.py:33: SyntaxWarning: invalid escape sequence '\-'
[2025-06-16T10:06:29.664+0000] {subprocess.py:93} INFO -   '[0-9]{12}:role/[A-Za-z0-9+=,.@\-_]{1,64}')  # noqa
[2025-06-16T10:06:43.853+0000] {subprocess.py:93} INFO - Traceback (most recent call last):
[2025-06-16T10:06:43.860+0000] {subprocess.py:93} INFO -   File "/home/airflow/.local/lib/python3.12/site-packages/great_expectations/data_context/store/in_memory_store_backend.py", line 56, in _get
[2025-06-16T10:06:43.864+0000] {subprocess.py:93} INFO -     return self._store[key]
[2025-06-16T10:06:43.867+0000] {subprocess.py:93} INFO -            ~~~~~~~~~~~^^^^^
[2025-06-16T10:06:43.871+0000] {subprocess.py:93} INFO - KeyError: ('validation_checkpoint',)
[2025-06-16T10:06:43.873+0000] {subprocess.py:93} INFO - 
[2025-06-16T10:06:43.876+0000] {subprocess.py:93} INFO - During handling of the above exception, another exception occurred:
[2025-06-16T10:06:43.878+0000] {subprocess.py:93} INFO - 
[2025-06-16T10:06:43.881+0000] {subprocess.py:93} INFO - Traceback (most recent call last):
[2025-06-16T10:06:43.883+0000] {subprocess.py:93} INFO -   File "/home/airflow/.local/lib/python3.12/site-packages/great_expectations/data_context/store/checkpoint_store.py", line 154, in get_checkpoint
[2025-06-16T10:06:43.885+0000] {subprocess.py:93} INFO -     checkpoint_config: Optional[Any] = self.get(key=key)
[2025-06-16T10:06:43.887+0000] {subprocess.py:93} INFO -                                        ^^^^^^^^^^^^^^^^^
[2025-06-16T10:06:43.889+0000] {subprocess.py:93} INFO -   File "/home/airflow/.local/lib/python3.12/site-packages/great_expectations/data_context/store/store.py", line 212, in get
[2025-06-16T10:06:43.892+0000] {subprocess.py:93} INFO -     value = self._store_backend.get(self.key_to_tuple(key))
[2025-06-16T10:06:43.895+0000] {subprocess.py:93} INFO -             ^^^^^^^^^^^^^^^^^^^^^^^^^^^^^^^^^^^^^^^^^^^^^^^
[2025-06-16T10:06:43.897+0000] {subprocess.py:93} INFO -   File "/home/airflow/.local/lib/python3.12/site-packages/great_expectations/data_context/store/_store_backend.py", line 123, in get
[2025-06-16T10:06:43.899+0000] {subprocess.py:93} INFO -     value = self._get(key, **kwargs)
[2025-06-16T10:06:43.901+0000] {subprocess.py:93} INFO -             ^^^^^^^^^^^^^^^^^^^^^^^^
[2025-06-16T10:06:43.902+0000] {subprocess.py:93} INFO -   File "/home/airflow/.local/lib/python3.12/site-packages/great_expectations/data_context/store/in_memory_store_backend.py", line 58, in _get
[2025-06-16T10:06:43.904+0000] {subprocess.py:93} INFO -     raise InvalidKeyError(f"{e!s}")
[2025-06-16T10:06:43.907+0000] {subprocess.py:93} INFO - great_expectations.exceptions.exceptions.InvalidKeyError: ('validation_checkpoint',)
[2025-06-16T10:06:43.910+0000] {subprocess.py:93} INFO - 
[2025-06-16T10:06:43.912+0000] {subprocess.py:93} INFO - During handling of the above exception, another exception occurred:
[2025-06-16T10:06:43.913+0000] {subprocess.py:93} INFO - 
[2025-06-16T10:06:43.915+0000] {subprocess.py:93} INFO - Traceback (most recent call last):
[2025-06-16T10:06:43.916+0000] {subprocess.py:93} INFO -   File "/opt/airflow/src/etl/validate_data.py", line 38, in <module>
[2025-06-16T10:06:43.919+0000] {subprocess.py:93} INFO -     validate_data(data_file)
[2025-06-16T10:06:43.921+0000] {subprocess.py:93} INFO -   File "/opt/airflow/src/etl/validate_data.py", line 17, in validate_data
[2025-06-16T10:06:43.923+0000] {subprocess.py:93} INFO -     results = context.run_checkpoint(
[2025-06-16T10:06:43.924+0000] {subprocess.py:93} INFO -               ^^^^^^^^^^^^^^^^^^^^^^^
[2025-06-16T10:06:43.927+0000] {subprocess.py:93} INFO -   File "/home/airflow/.local/lib/python3.12/site-packages/great_expectations/core/usage_statistics/usage_statistics.py", line 260, in usage_statistics_wrapped_method
[2025-06-16T10:06:43.931+0000] {subprocess.py:93} INFO -     result = func(*args, **kwargs)
[2025-06-16T10:06:43.934+0000] {subprocess.py:93} INFO -              ^^^^^^^^^^^^^^^^^^^^^
[2025-06-16T10:06:43.936+0000] {subprocess.py:93} INFO -   File "/home/airflow/.local/lib/python3.12/site-packages/great_expectations/data_context/data_context/abstract_data_context.py", line 2215, in run_checkpoint
[2025-06-16T10:06:43.938+0000] {subprocess.py:93} INFO -     return self._run_checkpoint(
[2025-06-16T10:06:43.940+0000] {subprocess.py:93} INFO -            ^^^^^^^^^^^^^^^^^^^^^
[2025-06-16T10:06:43.942+0000] {subprocess.py:93} INFO -   File "/home/airflow/.local/lib/python3.12/site-packages/great_expectations/data_context/data_context/abstract_data_context.py", line 2255, in _run_checkpoint
[2025-06-16T10:06:43.945+0000] {subprocess.py:93} INFO -     checkpoint: Checkpoint = self.get_checkpoint(
[2025-06-16T10:06:43.947+0000] {subprocess.py:93} INFO -                              ^^^^^^^^^^^^^^^^^^^^
[2025-06-16T10:06:43.949+0000] {subprocess.py:93} INFO -   File "/home/airflow/.local/lib/python3.12/site-packages/great_expectations/data_context/data_context/abstract_data_context.py", line 2106, in get_checkpoint
[2025-06-16T10:06:43.952+0000] {subprocess.py:93} INFO -     checkpoint_config: CheckpointConfig = self.checkpoint_store.get_checkpoint(
[2025-06-16T10:06:43.955+0000] {subprocess.py:93} INFO -                                           ^^^^^^^^^^^^^^^^^^^^^^^^^^^^^^^^^^^^^
[2025-06-16T10:06:43.957+0000] {subprocess.py:93} INFO -   File "/home/airflow/.local/lib/python3.12/site-packages/great_expectations/data_context/store/checkpoint_store.py", line 159, in get_checkpoint
[2025-06-16T10:06:43.959+0000] {subprocess.py:93} INFO -     raise gx_exceptions.CheckpointNotFoundError(
[2025-06-16T10:06:43.960+0000] {subprocess.py:93} INFO - great_expectations.exceptions.exceptions.CheckpointNotFoundError: Non-existent Checkpoint configuration named "validation_checkpoint".
[2025-06-16T10:06:43.962+0000] {subprocess.py:93} INFO - 
[2025-06-16T10:06:43.963+0000] {subprocess.py:93} INFO - Details: ('validation_checkpoint',)
[2025-06-16T10:06:45.491+0000] {subprocess.py:97} INFO - Command exited with return code 1
[2025-06-16T10:06:45.501+0000] {taskinstance.py:441} INFO - ::group::Post task execution logs
[2025-06-16T10:06:45.743+0000] {taskinstance.py:2905} ERROR - Task failed with exception
Traceback (most recent call last):
  File "/home/airflow/.local/lib/python3.12/site-packages/airflow/models/taskinstance.py", line 465, in _execute_task
    result = _execute_callable(context=context, **execute_callable_kwargs)
             ^^^^^^^^^^^^^^^^^^^^^^^^^^^^^^^^^^^^^^^^^^^^^^^^^^^^^^^^^^^^^
  File "/home/airflow/.local/lib/python3.12/site-packages/airflow/models/taskinstance.py", line 432, in _execute_callable
    return execute_callable(context=context, **execute_callable_kwargs)
           ^^^^^^^^^^^^^^^^^^^^^^^^^^^^^^^^^^^^^^^^^^^^^^^^^^^^^^^^^^^^
  File "/home/airflow/.local/lib/python3.12/site-packages/airflow/models/baseoperator.py", line 400, in wrapper
    return func(self, *args, **kwargs)
           ^^^^^^^^^^^^^^^^^^^^^^^^^^^
  File "/home/airflow/.local/lib/python3.12/site-packages/airflow/operators/bash.py", line 243, in execute
    raise AirflowException(
airflow.exceptions.AirflowException: Bash command failed. The command returned a non-zero exit code 1.
[2025-06-16T10:06:45.830+0000] {taskinstance.py:1206} INFO - Marking task as FAILED. dag_id=etl_brazil_pipeline, task_id=run_ge_validation, run_id=manual__2025-06-16T09:55:18.909208+00:00, execution_date=20250616T095518, start_date=20250616T100610, end_date=20250616T100645
[2025-06-16T10:06:46.024+0000] {standard_task_runner.py:110} ERROR - Failed to execute job 12 for task run_ge_validation (Bash command failed. The command returned a non-zero exit code 1.; 228)
[2025-06-16T10:06:46.091+0000] {local_task_job_runner.py:240} INFO - Task exited with return code 1
[2025-06-16T10:06:46.327+0000] {taskinstance.py:3498} INFO - 0 downstream tasks scheduled from follow-on schedule check
[2025-06-16T10:06:46.332+0000] {local_task_job_runner.py:222} INFO - ::endgroup::
