[2025-06-16T12:51:49.106+0000] {task_context_logger.py:104} ERROR - Executor reports task instance <TaskInstance: etl_brazil_pipeline.run_gx_validations manual__2025-06-16T12:47:50.853434+00:00 [queued]> finished (failed) although the task says it's queued. (Info: None) Was the task killed externally?
