[2025-06-16T11:03:40.644+0000] {local_task_job_runner.py:120} INFO - ::group::Pre task execution logs
[2025-06-16T11:03:40.723+0000] {taskinstance.py:2076} INFO - Dependencies all met for dep_context=non-requeueable deps ti=<TaskInstance: etl_brazil_pipeline.run_gx_validations manual__2025-06-16T11:01:19.641930+00:00 [queued]>
[2025-06-16T11:03:40.742+0000] {taskinstance.py:2076} INFO - Dependencies all met for dep_context=requeueable deps ti=<TaskInstance: etl_brazil_pipeline.run_gx_validations manual__2025-06-16T11:01:19.641930+00:00 [queued]>
[2025-06-16T11:03:40.743+0000] {taskinstance.py:2306} INFO - Starting attempt 1 of 2
[2025-06-16T11:03:40.763+0000] {taskinstance.py:2330} INFO - Executing <Task(PythonOperator): run_gx_validations> on 2025-06-16 11:01:19.641930+00:00
[2025-06-16T11:03:40.798+0000] {warnings.py:110} WARNING - /home/airflow/.local/lib/python3.12/site-packages/airflow/task/task_runner/standard_task_runner.py:61: DeprecationWarning: This process (pid=1102) is multi-threaded, use of fork() may lead to deadlocks in the child.
  pid = os.fork()

[2025-06-16T11:03:40.799+0000] {standard_task_runner.py:90} INFO - Running: ['airflow', 'tasks', 'run', 'etl_brazil_pipeline', 'run_gx_validations', 'manual__2025-06-16T11:01:19.641930+00:00', '--job-id', '23', '--raw', '--subdir', 'DAGS_FOLDER/etl_brazil_pipeline.py', '--cfg-path', '/tmp/tmpaehpnf06']
[2025-06-16T11:03:40.801+0000] {standard_task_runner.py:63} INFO - Started process 1116 to run task
[2025-06-16T11:03:40.801+0000] {standard_task_runner.py:91} INFO - Job 23: Subtask run_gx_validations
[2025-06-16T11:03:40.829+0000] {warnings.py:110} WARNING - /home/airflow/.local/lib/python3.12/site-packages/airflow/settings.py:195: DeprecationWarning: The sql_alchemy_conn option in [core] has been moved to the sql_alchemy_conn option in [database] - the old setting has been used, but please update your config.
  SQL_ALCHEMY_CONN = conf.get("database", "SQL_ALCHEMY_CONN")

[2025-06-16T11:03:40.893+0000] {task_command.py:426} INFO - Running <TaskInstance: etl_brazil_pipeline.run_gx_validations manual__2025-06-16T11:01:19.641930+00:00 [running]> on host ad328373235b
[2025-06-16T11:03:41.033+0000] {taskinstance.py:2648} INFO - Exporting env vars: AIRFLOW_CTX_DAG_OWNER='vaishnavi' AIRFLOW_CTX_DAG_ID='etl_brazil_pipeline' AIRFLOW_CTX_TASK_ID='run_gx_validations' AIRFLOW_CTX_EXECUTION_DATE='2025-06-16T11:01:19.641930+00:00' AIRFLOW_CTX_TRY_NUMBER='1' AIRFLOW_CTX_DAG_RUN_ID='manual__2025-06-16T11:01:19.641930+00:00'
[2025-06-16T11:03:41.035+0000] {taskinstance.py:430} INFO - ::endgroup::
[2025-06-16T11:03:41.211+0000] {file_data_context.py:224} INFO - FileDataContext loading fluent config
[2025-06-16T11:03:41.251+0000] {config.py:185} INFO - Loading 'datasources' ->
[]
[2025-06-16T11:03:41.674+0000] {abstract_data_context.py:4703} WARNING - Cannot initialize datasource ***_brazil_etl: Cannot initialize datasource ***_brazil_etl, error: (psycopg2.OperationalError) connection to server at "localhost" (::1), port 5432 failed: Connection refused
	Is the server running on that host and accepting TCP/IP connections?
connection to server at "localhost" (127.0.0.1), port 5432 failed: Connection refused
	Is the server running on that host and accepting TCP/IP connections?

(Background on this error at: https://sqlalche.me/e/14/e3q8)
[2025-06-16T11:03:42.294+0000] {fluent_base_model.py:264} INFO - SQLDatasource.dict() - substituting config values
[2025-06-16T11:03:42.310+0000] {taskinstance.py:441} INFO - ::group::Post task execution logs
[2025-06-16T11:03:42.312+0000] {taskinstance.py:2905} ERROR - Task failed with exception
Traceback (most recent call last):
  File "/home/airflow/.local/lib/python3.12/site-packages/sqlalchemy/engine/base.py", line 3371, in _wrap_pool_connect
    return fn()
           ^^^^
  File "/home/airflow/.local/lib/python3.12/site-packages/sqlalchemy/pool/base.py", line 327, in connect
    return _ConnectionFairy._checkout(self)
           ^^^^^^^^^^^^^^^^^^^^^^^^^^^^^^^^
  File "/home/airflow/.local/lib/python3.12/site-packages/sqlalchemy/pool/base.py", line 894, in _checkout
    fairy = _ConnectionRecord.checkout(pool)
            ^^^^^^^^^^^^^^^^^^^^^^^^^^^^^^^^
  File "/home/airflow/.local/lib/python3.12/site-packages/sqlalchemy/pool/base.py", line 493, in checkout
    rec = pool._do_get()
          ^^^^^^^^^^^^^^
  File "/home/airflow/.local/lib/python3.12/site-packages/sqlalchemy/pool/impl.py", line 145, in _do_get
    with util.safe_reraise():
  File "/home/airflow/.local/lib/python3.12/site-packages/sqlalchemy/util/langhelpers.py", line 70, in __exit__
    compat.raise_(
  File "/home/airflow/.local/lib/python3.12/site-packages/sqlalchemy/util/compat.py", line 211, in raise_
    raise exception
  File "/home/airflow/.local/lib/python3.12/site-packages/sqlalchemy/pool/impl.py", line 143, in _do_get
    return self._create_connection()
           ^^^^^^^^^^^^^^^^^^^^^^^^^
  File "/home/airflow/.local/lib/python3.12/site-packages/sqlalchemy/pool/base.py", line 273, in _create_connection
    return _ConnectionRecord(self)
           ^^^^^^^^^^^^^^^^^^^^^^^
  File "/home/airflow/.local/lib/python3.12/site-packages/sqlalchemy/pool/base.py", line 388, in __init__
    self.__connect()
  File "/home/airflow/.local/lib/python3.12/site-packages/sqlalchemy/pool/base.py", line 690, in __connect
    with util.safe_reraise():
  File "/home/airflow/.local/lib/python3.12/site-packages/sqlalchemy/util/langhelpers.py", line 70, in __exit__
    compat.raise_(
  File "/home/airflow/.local/lib/python3.12/site-packages/sqlalchemy/util/compat.py", line 211, in raise_
    raise exception
  File "/home/airflow/.local/lib/python3.12/site-packages/sqlalchemy/pool/base.py", line 686, in __connect
    self.dbapi_connection = connection = pool._invoke_creator(self)
                                         ^^^^^^^^^^^^^^^^^^^^^^^^^^
  File "/home/airflow/.local/lib/python3.12/site-packages/sqlalchemy/engine/create.py", line 574, in connect
    return dialect.connect(*cargs, **cparams)
           ^^^^^^^^^^^^^^^^^^^^^^^^^^^^^^^^^^
  File "/home/airflow/.local/lib/python3.12/site-packages/sqlalchemy/engine/default.py", line 598, in connect
    return self.dbapi.connect(*cargs, **cparams)
           ^^^^^^^^^^^^^^^^^^^^^^^^^^^^^^^^^^^^^
  File "/home/airflow/.local/lib/python3.12/site-packages/psycopg2/__init__.py", line 122, in connect
    conn = _connect(dsn, connection_factory=connection_factory, **kwasync)
           ^^^^^^^^^^^^^^^^^^^^^^^^^^^^^^^^^^^^^^^^^^^^^^^^^^^^^^^^^^^^^^^
psycopg2.OperationalError: connection to server at "***" (172.18.0.3), port 5432 failed: FATAL:  password authentication failed for user "None"


The above exception was the direct cause of the following exception:

Traceback (most recent call last):
  File "/home/airflow/.local/lib/python3.12/site-packages/great_expectations/datasource/fluent/sql_datasource.py", line 1070, in test_connection
    engine.connect()
  File "/home/airflow/.local/lib/python3.12/site-packages/sqlalchemy/engine/base.py", line 3325, in connect
    return self._connection_cls(self, close_with_result=close_with_result)
           ^^^^^^^^^^^^^^^^^^^^^^^^^^^^^^^^^^^^^^^^^^^^^^^^^^^^^^^^^^^^^^^
  File "/home/airflow/.local/lib/python3.12/site-packages/sqlalchemy/engine/base.py", line 96, in __init__
    else engine.raw_connection()
         ^^^^^^^^^^^^^^^^^^^^^^^
  File "/home/airflow/.local/lib/python3.12/site-packages/sqlalchemy/engine/base.py", line 3404, in raw_connection
    return self._wrap_pool_connect(self.pool.connect, _connection)
           ^^^^^^^^^^^^^^^^^^^^^^^^^^^^^^^^^^^^^^^^^^^^^^^^^^^^^^^
  File "/home/airflow/.local/lib/python3.12/site-packages/sqlalchemy/engine/base.py", line 3374, in _wrap_pool_connect
    Connection._handle_dbapi_exception_noconnection(
  File "/home/airflow/.local/lib/python3.12/site-packages/sqlalchemy/engine/base.py", line 2208, in _handle_dbapi_exception_noconnection
    util.raise_(
  File "/home/airflow/.local/lib/python3.12/site-packages/sqlalchemy/util/compat.py", line 211, in raise_
    raise exception
  File "/home/airflow/.local/lib/python3.12/site-packages/sqlalchemy/engine/base.py", line 3371, in _wrap_pool_connect
    return fn()
           ^^^^
  File "/home/airflow/.local/lib/python3.12/site-packages/sqlalchemy/pool/base.py", line 327, in connect
    return _ConnectionFairy._checkout(self)
           ^^^^^^^^^^^^^^^^^^^^^^^^^^^^^^^^
  File "/home/airflow/.local/lib/python3.12/site-packages/sqlalchemy/pool/base.py", line 894, in _checkout
    fairy = _ConnectionRecord.checkout(pool)
            ^^^^^^^^^^^^^^^^^^^^^^^^^^^^^^^^
  File "/home/airflow/.local/lib/python3.12/site-packages/sqlalchemy/pool/base.py", line 493, in checkout
    rec = pool._do_get()
          ^^^^^^^^^^^^^^
  File "/home/airflow/.local/lib/python3.12/site-packages/sqlalchemy/pool/impl.py", line 145, in _do_get
    with util.safe_reraise():
  File "/home/airflow/.local/lib/python3.12/site-packages/sqlalchemy/util/langhelpers.py", line 70, in __exit__
    compat.raise_(
  File "/home/airflow/.local/lib/python3.12/site-packages/sqlalchemy/util/compat.py", line 211, in raise_
    raise exception
  File "/home/airflow/.local/lib/python3.12/site-packages/sqlalchemy/pool/impl.py", line 143, in _do_get
    return self._create_connection()
           ^^^^^^^^^^^^^^^^^^^^^^^^^
  File "/home/airflow/.local/lib/python3.12/site-packages/sqlalchemy/pool/base.py", line 273, in _create_connection
    return _ConnectionRecord(self)
           ^^^^^^^^^^^^^^^^^^^^^^^
  File "/home/airflow/.local/lib/python3.12/site-packages/sqlalchemy/pool/base.py", line 388, in __init__
    self.__connect()
  File "/home/airflow/.local/lib/python3.12/site-packages/sqlalchemy/pool/base.py", line 690, in __connect
    with util.safe_reraise():
  File "/home/airflow/.local/lib/python3.12/site-packages/sqlalchemy/util/langhelpers.py", line 70, in __exit__
    compat.raise_(
  File "/home/airflow/.local/lib/python3.12/site-packages/sqlalchemy/util/compat.py", line 211, in raise_
    raise exception
  File "/home/airflow/.local/lib/python3.12/site-packages/sqlalchemy/pool/base.py", line 686, in __connect
    self.dbapi_connection = connection = pool._invoke_creator(self)
                                         ^^^^^^^^^^^^^^^^^^^^^^^^^^
  File "/home/airflow/.local/lib/python3.12/site-packages/sqlalchemy/engine/create.py", line 574, in connect
    return dialect.connect(*cargs, **cparams)
           ^^^^^^^^^^^^^^^^^^^^^^^^^^^^^^^^^^
  File "/home/airflow/.local/lib/python3.12/site-packages/sqlalchemy/engine/default.py", line 598, in connect
    return self.dbapi.connect(*cargs, **cparams)
           ^^^^^^^^^^^^^^^^^^^^^^^^^^^^^^^^^^^^^
  File "/home/airflow/.local/lib/python3.12/site-packages/psycopg2/__init__.py", line 122, in connect
    conn = _connect(dsn, connection_factory=connection_factory, **kwasync)
           ^^^^^^^^^^^^^^^^^^^^^^^^^^^^^^^^^^^^^^^^^^^^^^^^^^^^^^^^^^^^^^^
sqlalchemy.exc.OperationalError: (psycopg2.OperationalError) connection to server at "***" (172.18.0.3), port 5432 failed: FATAL:  password authentication failed for user "None"

(Background on this error at: https://sqlalche.me/e/14/e3q8)

The above exception was the direct cause of the following exception:

Traceback (most recent call last):
  File "/home/airflow/.local/lib/python3.12/site-packages/airflow/models/taskinstance.py", line 465, in _execute_task
    result = _execute_callable(context=context, **execute_callable_kwargs)
             ^^^^^^^^^^^^^^^^^^^^^^^^^^^^^^^^^^^^^^^^^^^^^^^^^^^^^^^^^^^^^
  File "/home/airflow/.local/lib/python3.12/site-packages/airflow/models/taskinstance.py", line 432, in _execute_callable
    return execute_callable(context=context, **execute_callable_kwargs)
           ^^^^^^^^^^^^^^^^^^^^^^^^^^^^^^^^^^^^^^^^^^^^^^^^^^^^^^^^^^^^
  File "/home/airflow/.local/lib/python3.12/site-packages/airflow/models/baseoperator.py", line 400, in wrapper
    return func(self, *args, **kwargs)
           ^^^^^^^^^^^^^^^^^^^^^^^^^^^
  File "/home/airflow/.local/lib/python3.12/site-packages/airflow/operators/python.py", line 235, in execute
    return_value = self.execute_callable()
                   ^^^^^^^^^^^^^^^^^^^^^^^
  File "/home/airflow/.local/lib/python3.12/site-packages/airflow/operators/python.py", line 252, in execute_callable
    return self.python_callable(*self.op_args, **self.op_kwargs)
           ^^^^^^^^^^^^^^^^^^^^^^^^^^^^^^^^^^^^^^^^^^^^^^^^^^^^^
  File "/opt/airflow/src/validation/gx_runner.py", line 19, in run_all_checkpoints
    _ensure_datasource(context)
  File "/opt/airflow/src/validation/gx_runner.py", line 12, in _ensure_datasource
    context.sources.add_sql(
  File "/home/airflow/.local/lib/python3.12/site-packages/great_expectations/datasource/fluent/sources.py", line 472, in add_datasource
    datasource.test_connection()
  File "/home/airflow/.local/lib/python3.12/site-packages/great_expectations/datasource/fluent/sql_datasource.py", line 1072, in test_connection
    raise TestConnectionError(
great_expectations.datasource.fluent.interfaces.TestConnectionError: Attempt to connect to datasource failed with the following error message: (psycopg2.OperationalError) connection to server at "***" (172.18.0.3), port 5432 failed: FATAL:  password authentication failed for user "None"

(Background on this error at: https://sqlalche.me/e/14/e3q8)
[2025-06-16T11:03:42.372+0000] {taskinstance.py:1206} INFO - Marking task as UP_FOR_RETRY. dag_id=etl_brazil_pipeline, task_id=run_gx_validations, run_id=manual__2025-06-16T11:01:19.641930+00:00, execution_date=20250616T110119, start_date=20250616T110340, end_date=20250616T110342
[2025-06-16T11:03:42.388+0000] {standard_task_runner.py:110} ERROR - Failed to execute job 23 for task run_gx_validations (Attempt to connect to datasource failed with the following error message: (psycopg2.OperationalError) connection to server at "***" (172.18.0.3), port 5432 failed: FATAL:  password authentication failed for user "None"

(Background on this error at: https://sqlalche.me/e/14/e3q8); 1116)
[2025-06-16T11:03:42.403+0000] {local_task_job_runner.py:240} INFO - Task exited with return code 1
[2025-06-16T11:03:42.430+0000] {taskinstance.py:3498} INFO - 0 downstream tasks scheduled from follow-on schedule check
[2025-06-16T11:03:42.434+0000] {local_task_job_runner.py:222} INFO - ::endgroup::
