[2025-06-16T10:12:47.639+0000] {local_task_job_runner.py:120} INFO - ::group::Pre task execution logs
[2025-06-16T10:12:47.699+0000] {taskinstance.py:2076} INFO - Dependencies all met for dep_context=non-requeueable deps ti=<TaskInstance: etl_brazil_pipeline.run_ge_validation manual__2025-06-16T10:07:39.958242+00:00 [queued]>
[2025-06-16T10:12:47.713+0000] {taskinstance.py:2076} INFO - Dependencies all met for dep_context=requeueable deps ti=<TaskInstance: etl_brazil_pipeline.run_ge_validation manual__2025-06-16T10:07:39.958242+00:00 [queued]>
[2025-06-16T10:12:47.715+0000] {taskinstance.py:2306} INFO - Starting attempt 1 of 2
[2025-06-16T10:12:47.733+0000] {taskinstance.py:2330} INFO - Executing <Task(BashOperator): run_ge_validation> on 2025-06-16 10:07:39.958242+00:00
[2025-06-16T10:12:47.749+0000] {logging_mixin.py:188} WARNING - /home/airflow/.local/lib/python3.12/site-packages/airflow/task/task_runner/standard_task_runner.py:61 DeprecationWarning: This process (pid=336) is multi-threaded, use of fork() may lead to deadlocks in the child.
[2025-06-16T10:12:47.749+0000] {standard_task_runner.py:90} INFO - Running: ['airflow', 'tasks', 'run', 'etl_brazil_pipeline', 'run_ge_validation', 'manual__2025-06-16T10:07:39.958242+00:00', '--job-id', '16', '--raw', '--subdir', 'DAGS_FOLDER/etl_brazil_pipeline.py', '--cfg-path', '/tmp/tmpi1r0m6ox']
[2025-06-16T10:12:47.751+0000] {standard_task_runner.py:63} INFO - Started process 337 to run task
[2025-06-16T10:12:47.752+0000] {standard_task_runner.py:91} INFO - Job 16: Subtask run_ge_validation
[2025-06-16T10:12:47.783+0000] {logging_mixin.py:188} WARNING - /home/airflow/.local/lib/python3.12/site-packages/airflow/settings.py:195 DeprecationWarning: The sql_alchemy_conn option in [core] has been moved to the sql_alchemy_conn option in [database] - the old setting has been used, but please update your config.
[2025-06-16T10:12:47.843+0000] {task_command.py:426} INFO - Running <TaskInstance: etl_brazil_pipeline.run_ge_validation manual__2025-06-16T10:07:39.958242+00:00 [running]> on host 155077edd2ca
[2025-06-16T10:12:48.008+0000] {taskinstance.py:2648} INFO - Exporting env vars: AIRFLOW_CTX_DAG_OWNER='vaishnavi' AIRFLOW_CTX_DAG_ID='etl_brazil_pipeline' AIRFLOW_CTX_TASK_ID='run_ge_validation' AIRFLOW_CTX_EXECUTION_DATE='2025-06-16T10:07:39.958242+00:00' AIRFLOW_CTX_TRY_NUMBER='1' AIRFLOW_CTX_DAG_RUN_ID='manual__2025-06-16T10:07:39.958242+00:00'
[2025-06-16T10:12:48.012+0000] {taskinstance.py:430} INFO - ::endgroup::
[2025-06-16T10:12:48.071+0000] {subprocess.py:63} INFO - Tmp dir root location: /tmp
[2025-06-16T10:12:48.077+0000] {subprocess.py:75} INFO - Running command: ['/usr/bin/bash', '-c', 'python3 /opt/airflow/src/etl/validate_data.py processed_sales.csv']
[2025-06-16T10:12:48.106+0000] {subprocess.py:86} INFO - Output:
[2025-06-16T10:13:04.286+0000] {subprocess.py:93} INFO - Traceback (most recent call last):
[2025-06-16T10:13:04.293+0000] {subprocess.py:93} INFO -   File "/home/airflow/.local/lib/python3.12/site-packages/great_expectations/data_context/store/in_memory_store_backend.py", line 56, in _get
[2025-06-16T10:13:04.295+0000] {subprocess.py:93} INFO -     return self._store[key]
[2025-06-16T10:13:04.296+0000] {subprocess.py:93} INFO -            ~~~~~~~~~~~^^^^^
[2025-06-16T10:13:04.299+0000] {subprocess.py:93} INFO - KeyError: ('validation_checkpoint',)
[2025-06-16T10:13:04.301+0000] {subprocess.py:93} INFO - 
[2025-06-16T10:13:04.302+0000] {subprocess.py:93} INFO - During handling of the above exception, another exception occurred:
[2025-06-16T10:13:04.303+0000] {subprocess.py:93} INFO - 
[2025-06-16T10:13:04.305+0000] {subprocess.py:93} INFO - Traceback (most recent call last):
[2025-06-16T10:13:04.306+0000] {subprocess.py:93} INFO -   File "/home/airflow/.local/lib/python3.12/site-packages/great_expectations/data_context/store/checkpoint_store.py", line 154, in get_checkpoint
[2025-06-16T10:13:04.306+0000] {subprocess.py:93} INFO -     checkpoint_config: Optional[Any] = self.get(key=key)
[2025-06-16T10:13:04.307+0000] {subprocess.py:93} INFO -                                        ^^^^^^^^^^^^^^^^^
[2025-06-16T10:13:04.308+0000] {subprocess.py:93} INFO -   File "/home/airflow/.local/lib/python3.12/site-packages/great_expectations/data_context/store/store.py", line 212, in get
[2025-06-16T10:13:04.309+0000] {subprocess.py:93} INFO -     value = self._store_backend.get(self.key_to_tuple(key))
[2025-06-16T10:13:04.310+0000] {subprocess.py:93} INFO -             ^^^^^^^^^^^^^^^^^^^^^^^^^^^^^^^^^^^^^^^^^^^^^^^
[2025-06-16T10:13:04.311+0000] {subprocess.py:93} INFO -   File "/home/airflow/.local/lib/python3.12/site-packages/great_expectations/data_context/store/_store_backend.py", line 123, in get
[2025-06-16T10:13:04.311+0000] {subprocess.py:93} INFO -     value = self._get(key, **kwargs)
[2025-06-16T10:13:04.312+0000] {subprocess.py:93} INFO -             ^^^^^^^^^^^^^^^^^^^^^^^^
[2025-06-16T10:13:04.313+0000] {subprocess.py:93} INFO -   File "/home/airflow/.local/lib/python3.12/site-packages/great_expectations/data_context/store/in_memory_store_backend.py", line 58, in _get
[2025-06-16T10:13:04.314+0000] {subprocess.py:93} INFO -     raise InvalidKeyError(f"{e!s}")
[2025-06-16T10:13:04.315+0000] {subprocess.py:93} INFO - great_expectations.exceptions.exceptions.InvalidKeyError: ('validation_checkpoint',)
[2025-06-16T10:13:04.316+0000] {subprocess.py:93} INFO - 
[2025-06-16T10:13:04.316+0000] {subprocess.py:93} INFO - During handling of the above exception, another exception occurred:
[2025-06-16T10:13:04.317+0000] {subprocess.py:93} INFO - 
[2025-06-16T10:13:04.318+0000] {subprocess.py:93} INFO - Traceback (most recent call last):
[2025-06-16T10:13:04.319+0000] {subprocess.py:93} INFO -   File "/opt/airflow/src/etl/validate_data.py", line 38, in <module>
[2025-06-16T10:13:04.320+0000] {subprocess.py:93} INFO -     validate_data(data_file)
[2025-06-16T10:13:04.321+0000] {subprocess.py:93} INFO -   File "/opt/airflow/src/etl/validate_data.py", line 17, in validate_data
[2025-06-16T10:13:04.322+0000] {subprocess.py:93} INFO -     results = context.run_checkpoint(
[2025-06-16T10:13:04.323+0000] {subprocess.py:93} INFO -               ^^^^^^^^^^^^^^^^^^^^^^^
[2025-06-16T10:13:04.324+0000] {subprocess.py:93} INFO -   File "/home/airflow/.local/lib/python3.12/site-packages/great_expectations/core/usage_statistics/usage_statistics.py", line 260, in usage_statistics_wrapped_method
[2025-06-16T10:13:04.325+0000] {subprocess.py:93} INFO -     result = func(*args, **kwargs)
[2025-06-16T10:13:04.326+0000] {subprocess.py:93} INFO -              ^^^^^^^^^^^^^^^^^^^^^
[2025-06-16T10:13:04.327+0000] {subprocess.py:93} INFO -   File "/home/airflow/.local/lib/python3.12/site-packages/great_expectations/data_context/data_context/abstract_data_context.py", line 2215, in run_checkpoint
[2025-06-16T10:13:04.328+0000] {subprocess.py:93} INFO -     return self._run_checkpoint(
[2025-06-16T10:13:04.330+0000] {subprocess.py:93} INFO -            ^^^^^^^^^^^^^^^^^^^^^
[2025-06-16T10:13:04.331+0000] {subprocess.py:93} INFO -   File "/home/airflow/.local/lib/python3.12/site-packages/great_expectations/data_context/data_context/abstract_data_context.py", line 2255, in _run_checkpoint
[2025-06-16T10:13:04.332+0000] {subprocess.py:93} INFO -     checkpoint: Checkpoint = self.get_checkpoint(
[2025-06-16T10:13:04.333+0000] {subprocess.py:93} INFO -                              ^^^^^^^^^^^^^^^^^^^^
[2025-06-16T10:13:04.334+0000] {subprocess.py:93} INFO -   File "/home/airflow/.local/lib/python3.12/site-packages/great_expectations/data_context/data_context/abstract_data_context.py", line 2106, in get_checkpoint
[2025-06-16T10:13:04.335+0000] {subprocess.py:93} INFO -     checkpoint_config: CheckpointConfig = self.checkpoint_store.get_checkpoint(
[2025-06-16T10:13:04.336+0000] {subprocess.py:93} INFO -                                           ^^^^^^^^^^^^^^^^^^^^^^^^^^^^^^^^^^^^^
[2025-06-16T10:13:04.337+0000] {subprocess.py:93} INFO -   File "/home/airflow/.local/lib/python3.12/site-packages/great_expectations/data_context/store/checkpoint_store.py", line 159, in get_checkpoint
[2025-06-16T10:13:04.339+0000] {subprocess.py:93} INFO -     raise gx_exceptions.CheckpointNotFoundError(
[2025-06-16T10:13:04.340+0000] {subprocess.py:93} INFO - great_expectations.exceptions.exceptions.CheckpointNotFoundError: Non-existent Checkpoint configuration named "validation_checkpoint".
[2025-06-16T10:13:04.341+0000] {subprocess.py:93} INFO - 
[2025-06-16T10:13:04.342+0000] {subprocess.py:93} INFO - Details: ('validation_checkpoint',)
[2025-06-16T10:13:05.136+0000] {subprocess.py:97} INFO - Command exited with return code 1
[2025-06-16T10:13:05.139+0000] {taskinstance.py:441} INFO - ::group::Post task execution logs
[2025-06-16T10:13:05.157+0000] {taskinstance.py:2905} ERROR - Task failed with exception
Traceback (most recent call last):
  File "/home/airflow/.local/lib/python3.12/site-packages/airflow/models/taskinstance.py", line 465, in _execute_task
    result = _execute_callable(context=context, **execute_callable_kwargs)
             ^^^^^^^^^^^^^^^^^^^^^^^^^^^^^^^^^^^^^^^^^^^^^^^^^^^^^^^^^^^^^
  File "/home/airflow/.local/lib/python3.12/site-packages/airflow/models/taskinstance.py", line 432, in _execute_callable
    return execute_callable(context=context, **execute_callable_kwargs)
           ^^^^^^^^^^^^^^^^^^^^^^^^^^^^^^^^^^^^^^^^^^^^^^^^^^^^^^^^^^^^
  File "/home/airflow/.local/lib/python3.12/site-packages/airflow/models/baseoperator.py", line 400, in wrapper
    return func(self, *args, **kwargs)
           ^^^^^^^^^^^^^^^^^^^^^^^^^^^
  File "/home/airflow/.local/lib/python3.12/site-packages/airflow/operators/bash.py", line 243, in execute
    raise AirflowException(
airflow.exceptions.AirflowException: Bash command failed. The command returned a non-zero exit code 1.
[2025-06-16T10:13:05.163+0000] {taskinstance.py:1206} INFO - Marking task as UP_FOR_RETRY. dag_id=etl_brazil_pipeline, task_id=run_ge_validation, run_id=manual__2025-06-16T10:07:39.958242+00:00, execution_date=20250616T100739, start_date=20250616T101247, end_date=20250616T101305
[2025-06-16T10:13:05.181+0000] {standard_task_runner.py:110} ERROR - Failed to execute job 16 for task run_ge_validation (Bash command failed. The command returned a non-zero exit code 1.; 337)
[2025-06-16T10:13:05.226+0000] {local_task_job_runner.py:240} INFO - Task exited with return code 1
[2025-06-16T10:13:05.253+0000] {taskinstance.py:3498} INFO - 0 downstream tasks scheduled from follow-on schedule check
[2025-06-16T10:13:05.257+0000] {local_task_job_runner.py:222} INFO - ::endgroup::
