[2025-06-11T10:22:38.842+0000] {processor.py:161} INFO - Started process (PID=220) to work on /opt/airflow/dags/etl_pipeline_dag.py
[2025-06-11T10:22:38.857+0000] {processor.py:830} INFO - Processing file /opt/airflow/dags/etl_pipeline_dag.py for tasks to queue
[2025-06-11T10:22:38.879+0000] {logging_mixin.py:188} INFO - [2025-06-11T10:22:38.878+0000] {dagbag.py:545} INFO - Filling up the DagBag from /opt/airflow/dags/etl_pipeline_dag.py
[2025-06-11T10:22:38.964+0000] {logging_mixin.py:188} INFO - [2025-06-11T10:22:38.933+0000] {dagbag.py:355} ERROR - Failed to import: /opt/airflow/dags/etl_pipeline_dag.py
Traceback (most recent call last):
  File "/home/airflow/.local/lib/python3.12/site-packages/airflow/models/dagbag.py", line 351, in parse
    loader.exec_module(new_module)
  File "<frozen importlib._bootstrap_external>", line 995, in exec_module
  File "<frozen importlib._bootstrap>", line 488, in _call_with_frames_removed
  File "/opt/airflow/dags/etl_pipeline_dag.py", line 8, in <module>
    from main_etl import run_etl
ModuleNotFoundError: No module named 'main_etl'
[2025-06-11T10:22:38.973+0000] {processor.py:842} WARNING - No viable dags retrieved from /opt/airflow/dags/etl_pipeline_dag.py
[2025-06-11T10:22:39.220+0000] {processor.py:183} INFO - Processing /opt/airflow/dags/etl_pipeline_dag.py took 0.466 seconds
[2025-06-11T10:23:10.028+0000] {processor.py:161} INFO - Started process (PID=225) to work on /opt/airflow/dags/etl_pipeline_dag.py
[2025-06-11T10:23:10.034+0000] {processor.py:830} INFO - Processing file /opt/airflow/dags/etl_pipeline_dag.py for tasks to queue
[2025-06-11T10:23:10.043+0000] {logging_mixin.py:188} INFO - [2025-06-11T10:23:10.042+0000] {dagbag.py:545} INFO - Filling up the DagBag from /opt/airflow/dags/etl_pipeline_dag.py
[2025-06-11T10:23:10.113+0000] {logging_mixin.py:188} INFO - [2025-06-11T10:23:10.100+0000] {dagbag.py:355} ERROR - Failed to import: /opt/airflow/dags/etl_pipeline_dag.py
Traceback (most recent call last):
  File "/home/airflow/.local/lib/python3.12/site-packages/airflow/models/dagbag.py", line 351, in parse
    loader.exec_module(new_module)
  File "<frozen importlib._bootstrap_external>", line 995, in exec_module
  File "<frozen importlib._bootstrap>", line 488, in _call_with_frames_removed
  File "/opt/airflow/dags/etl_pipeline_dag.py", line 8, in <module>
    from main_etl import run_etl
ModuleNotFoundError: No module named 'main_etl'
[2025-06-11T10:23:10.118+0000] {processor.py:842} WARNING - No viable dags retrieved from /opt/airflow/dags/etl_pipeline_dag.py
[2025-06-11T10:23:10.267+0000] {processor.py:183} INFO - Processing /opt/airflow/dags/etl_pipeline_dag.py took 0.264 seconds
[2025-06-11T10:23:41.440+0000] {processor.py:161} INFO - Started process (PID=230) to work on /opt/airflow/dags/etl_pipeline_dag.py
[2025-06-11T10:23:41.482+0000] {processor.py:830} INFO - Processing file /opt/airflow/dags/etl_pipeline_dag.py for tasks to queue
[2025-06-11T10:23:41.606+0000] {logging_mixin.py:188} INFO - [2025-06-11T10:23:41.587+0000] {dagbag.py:545} INFO - Filling up the DagBag from /opt/airflow/dags/etl_pipeline_dag.py
[2025-06-11T10:23:41.908+0000] {logging_mixin.py:188} INFO - [2025-06-11T10:23:41.849+0000] {dagbag.py:355} ERROR - Failed to import: /opt/airflow/dags/etl_pipeline_dag.py
Traceback (most recent call last):
  File "/home/airflow/.local/lib/python3.12/site-packages/airflow/models/dagbag.py", line 351, in parse
    loader.exec_module(new_module)
  File "<frozen importlib._bootstrap_external>", line 995, in exec_module
  File "<frozen importlib._bootstrap>", line 488, in _call_with_frames_removed
  File "/opt/airflow/dags/etl_pipeline_dag.py", line 8, in <module>
    from main_etl import run_etl
ModuleNotFoundError: No module named 'main_etl'
[2025-06-11T10:23:41.916+0000] {processor.py:842} WARNING - No viable dags retrieved from /opt/airflow/dags/etl_pipeline_dag.py
[2025-06-11T10:23:42.393+0000] {processor.py:183} INFO - Processing /opt/airflow/dags/etl_pipeline_dag.py took 1.287 seconds
[2025-06-11T10:24:12.858+0000] {processor.py:161} INFO - Started process (PID=235) to work on /opt/airflow/dags/etl_pipeline_dag.py
[2025-06-11T10:24:12.861+0000] {processor.py:830} INFO - Processing file /opt/airflow/dags/etl_pipeline_dag.py for tasks to queue
[2025-06-11T10:24:12.867+0000] {logging_mixin.py:188} INFO - [2025-06-11T10:24:12.866+0000] {dagbag.py:545} INFO - Filling up the DagBag from /opt/airflow/dags/etl_pipeline_dag.py
[2025-06-11T10:24:12.952+0000] {logging_mixin.py:188} INFO - [2025-06-11T10:24:12.931+0000] {dagbag.py:355} ERROR - Failed to import: /opt/airflow/dags/etl_pipeline_dag.py
Traceback (most recent call last):
  File "/home/airflow/.local/lib/python3.12/site-packages/airflow/models/dagbag.py", line 351, in parse
    loader.exec_module(new_module)
  File "<frozen importlib._bootstrap_external>", line 995, in exec_module
  File "<frozen importlib._bootstrap>", line 488, in _call_with_frames_removed
  File "/opt/airflow/dags/etl_pipeline_dag.py", line 8, in <module>
    from main_etl import run_etl
ModuleNotFoundError: No module named 'main_etl'
[2025-06-11T10:24:12.960+0000] {processor.py:842} WARNING - No viable dags retrieved from /opt/airflow/dags/etl_pipeline_dag.py
[2025-06-11T10:24:13.086+0000] {processor.py:183} INFO - Processing /opt/airflow/dags/etl_pipeline_dag.py took 0.237 seconds
[2025-06-11T10:24:43.949+0000] {processor.py:161} INFO - Started process (PID=240) to work on /opt/airflow/dags/etl_pipeline_dag.py
[2025-06-11T10:24:43.953+0000] {processor.py:830} INFO - Processing file /opt/airflow/dags/etl_pipeline_dag.py for tasks to queue
[2025-06-11T10:24:43.958+0000] {logging_mixin.py:188} INFO - [2025-06-11T10:24:43.958+0000] {dagbag.py:545} INFO - Filling up the DagBag from /opt/airflow/dags/etl_pipeline_dag.py
[2025-06-11T10:24:44.033+0000] {logging_mixin.py:188} INFO - [2025-06-11T10:24:44.018+0000] {dagbag.py:355} ERROR - Failed to import: /opt/airflow/dags/etl_pipeline_dag.py
Traceback (most recent call last):
  File "/home/airflow/.local/lib/python3.12/site-packages/airflow/models/dagbag.py", line 351, in parse
    loader.exec_module(new_module)
  File "<frozen importlib._bootstrap_external>", line 995, in exec_module
  File "<frozen importlib._bootstrap>", line 488, in _call_with_frames_removed
  File "/opt/airflow/dags/etl_pipeline_dag.py", line 8, in <module>
    from main_etl import run_etl
ModuleNotFoundError: No module named 'main_etl'
[2025-06-11T10:24:44.037+0000] {processor.py:842} WARNING - No viable dags retrieved from /opt/airflow/dags/etl_pipeline_dag.py
[2025-06-11T10:24:44.180+0000] {processor.py:183} INFO - Processing /opt/airflow/dags/etl_pipeline_dag.py took 0.237 seconds
[2025-06-11T10:25:14.816+0000] {processor.py:161} INFO - Started process (PID=245) to work on /opt/airflow/dags/etl_pipeline_dag.py
[2025-06-11T10:25:14.818+0000] {processor.py:830} INFO - Processing file /opt/airflow/dags/etl_pipeline_dag.py for tasks to queue
[2025-06-11T10:25:14.821+0000] {logging_mixin.py:188} INFO - [2025-06-11T10:25:14.821+0000] {dagbag.py:545} INFO - Filling up the DagBag from /opt/airflow/dags/etl_pipeline_dag.py
[2025-06-11T10:25:14.934+0000] {logging_mixin.py:188} INFO - [2025-06-11T10:25:14.907+0000] {dagbag.py:355} ERROR - Failed to import: /opt/airflow/dags/etl_pipeline_dag.py
Traceback (most recent call last):
  File "/home/airflow/.local/lib/python3.12/site-packages/airflow/models/dagbag.py", line 351, in parse
    loader.exec_module(new_module)
  File "<frozen importlib._bootstrap_external>", line 995, in exec_module
  File "<frozen importlib._bootstrap>", line 488, in _call_with_frames_removed
  File "/opt/airflow/dags/etl_pipeline_dag.py", line 8, in <module>
    from main_etl import run_etl
ModuleNotFoundError: No module named 'main_etl'
[2025-06-11T10:25:14.938+0000] {processor.py:842} WARNING - No viable dags retrieved from /opt/airflow/dags/etl_pipeline_dag.py
[2025-06-11T10:25:15.107+0000] {processor.py:183} INFO - Processing /opt/airflow/dags/etl_pipeline_dag.py took 0.301 seconds
[2025-06-11T10:25:45.818+0000] {processor.py:161} INFO - Started process (PID=250) to work on /opt/airflow/dags/etl_pipeline_dag.py
[2025-06-11T10:25:45.820+0000] {processor.py:830} INFO - Processing file /opt/airflow/dags/etl_pipeline_dag.py for tasks to queue
[2025-06-11T10:25:45.824+0000] {logging_mixin.py:188} INFO - [2025-06-11T10:25:45.823+0000] {dagbag.py:545} INFO - Filling up the DagBag from /opt/airflow/dags/etl_pipeline_dag.py
[2025-06-11T10:25:45.888+0000] {logging_mixin.py:188} INFO - [2025-06-11T10:25:45.881+0000] {dagbag.py:355} ERROR - Failed to import: /opt/airflow/dags/etl_pipeline_dag.py
Traceback (most recent call last):
  File "/home/airflow/.local/lib/python3.12/site-packages/airflow/models/dagbag.py", line 351, in parse
    loader.exec_module(new_module)
  File "<frozen importlib._bootstrap_external>", line 995, in exec_module
  File "<frozen importlib._bootstrap>", line 488, in _call_with_frames_removed
  File "/opt/airflow/dags/etl_pipeline_dag.py", line 8, in <module>
    from main_etl import run_etl
ModuleNotFoundError: No module named 'main_etl'
[2025-06-11T10:25:45.892+0000] {processor.py:842} WARNING - No viable dags retrieved from /opt/airflow/dags/etl_pipeline_dag.py
[2025-06-11T10:25:45.953+0000] {processor.py:183} INFO - Processing /opt/airflow/dags/etl_pipeline_dag.py took 0.141 seconds
[2025-06-11T10:26:16.585+0000] {processor.py:161} INFO - Started process (PID=255) to work on /opt/airflow/dags/etl_pipeline_dag.py
[2025-06-11T10:26:16.586+0000] {processor.py:830} INFO - Processing file /opt/airflow/dags/etl_pipeline_dag.py for tasks to queue
[2025-06-11T10:26:16.590+0000] {logging_mixin.py:188} INFO - [2025-06-11T10:26:16.588+0000] {dagbag.py:545} INFO - Filling up the DagBag from /opt/airflow/dags/etl_pipeline_dag.py
[2025-06-11T10:26:16.654+0000] {logging_mixin.py:188} INFO - [2025-06-11T10:26:16.645+0000] {dagbag.py:355} ERROR - Failed to import: /opt/airflow/dags/etl_pipeline_dag.py
Traceback (most recent call last):
  File "/home/airflow/.local/lib/python3.12/site-packages/airflow/models/dagbag.py", line 351, in parse
    loader.exec_module(new_module)
  File "<frozen importlib._bootstrap_external>", line 995, in exec_module
  File "<frozen importlib._bootstrap>", line 488, in _call_with_frames_removed
  File "/opt/airflow/dags/etl_pipeline_dag.py", line 8, in <module>
    from main_etl import run_etl
ModuleNotFoundError: No module named 'main_etl'
[2025-06-11T10:26:16.657+0000] {processor.py:842} WARNING - No viable dags retrieved from /opt/airflow/dags/etl_pipeline_dag.py
[2025-06-11T10:26:16.738+0000] {processor.py:183} INFO - Processing /opt/airflow/dags/etl_pipeline_dag.py took 0.160 seconds
[2025-06-11T10:26:47.475+0000] {processor.py:161} INFO - Started process (PID=260) to work on /opt/airflow/dags/etl_pipeline_dag.py
[2025-06-11T10:26:47.479+0000] {processor.py:830} INFO - Processing file /opt/airflow/dags/etl_pipeline_dag.py for tasks to queue
[2025-06-11T10:26:47.483+0000] {logging_mixin.py:188} INFO - [2025-06-11T10:26:47.482+0000] {dagbag.py:545} INFO - Filling up the DagBag from /opt/airflow/dags/etl_pipeline_dag.py
[2025-06-11T10:26:47.543+0000] {logging_mixin.py:188} INFO - [2025-06-11T10:26:47.534+0000] {dagbag.py:355} ERROR - Failed to import: /opt/airflow/dags/etl_pipeline_dag.py
Traceback (most recent call last):
  File "/home/airflow/.local/lib/python3.12/site-packages/airflow/models/dagbag.py", line 351, in parse
    loader.exec_module(new_module)
  File "<frozen importlib._bootstrap_external>", line 995, in exec_module
  File "<frozen importlib._bootstrap>", line 488, in _call_with_frames_removed
  File "/opt/airflow/dags/etl_pipeline_dag.py", line 8, in <module>
    from main_etl import run_etl
ModuleNotFoundError: No module named 'main_etl'
[2025-06-11T10:26:47.547+0000] {processor.py:842} WARNING - No viable dags retrieved from /opt/airflow/dags/etl_pipeline_dag.py
[2025-06-11T10:26:47.574+0000] {processor.py:183} INFO - Processing /opt/airflow/dags/etl_pipeline_dag.py took 0.108 seconds
[2025-06-11T10:27:18.261+0000] {processor.py:161} INFO - Started process (PID=265) to work on /opt/airflow/dags/etl_pipeline_dag.py
[2025-06-11T10:27:18.262+0000] {processor.py:830} INFO - Processing file /opt/airflow/dags/etl_pipeline_dag.py for tasks to queue
[2025-06-11T10:27:18.264+0000] {logging_mixin.py:188} INFO - [2025-06-11T10:27:18.264+0000] {dagbag.py:545} INFO - Filling up the DagBag from /opt/airflow/dags/etl_pipeline_dag.py
[2025-06-11T10:27:18.320+0000] {logging_mixin.py:188} INFO - [2025-06-11T10:27:18.310+0000] {dagbag.py:355} ERROR - Failed to import: /opt/airflow/dags/etl_pipeline_dag.py
Traceback (most recent call last):
  File "/home/airflow/.local/lib/python3.12/site-packages/airflow/models/dagbag.py", line 351, in parse
    loader.exec_module(new_module)
  File "<frozen importlib._bootstrap_external>", line 995, in exec_module
  File "<frozen importlib._bootstrap>", line 488, in _call_with_frames_removed
  File "/opt/airflow/dags/etl_pipeline_dag.py", line 8, in <module>
    from main_etl import run_etl
ModuleNotFoundError: No module named 'main_etl'
[2025-06-11T10:27:18.323+0000] {processor.py:842} WARNING - No viable dags retrieved from /opt/airflow/dags/etl_pipeline_dag.py
[2025-06-11T10:27:18.345+0000] {processor.py:183} INFO - Processing /opt/airflow/dags/etl_pipeline_dag.py took 0.090 seconds
[2025-06-11T10:27:49.224+0000] {processor.py:161} INFO - Started process (PID=270) to work on /opt/airflow/dags/etl_pipeline_dag.py
[2025-06-11T10:27:49.226+0000] {processor.py:830} INFO - Processing file /opt/airflow/dags/etl_pipeline_dag.py for tasks to queue
[2025-06-11T10:27:49.228+0000] {logging_mixin.py:188} INFO - [2025-06-11T10:27:49.228+0000] {dagbag.py:545} INFO - Filling up the DagBag from /opt/airflow/dags/etl_pipeline_dag.py
[2025-06-11T10:27:49.280+0000] {logging_mixin.py:188} INFO - [2025-06-11T10:27:49.271+0000] {dagbag.py:355} ERROR - Failed to import: /opt/airflow/dags/etl_pipeline_dag.py
Traceback (most recent call last):
  File "/home/airflow/.local/lib/python3.12/site-packages/airflow/models/dagbag.py", line 351, in parse
    loader.exec_module(new_module)
  File "<frozen importlib._bootstrap_external>", line 995, in exec_module
  File "<frozen importlib._bootstrap>", line 488, in _call_with_frames_removed
  File "/opt/airflow/dags/etl_pipeline_dag.py", line 8, in <module>
    from main_etl import run_etl
ModuleNotFoundError: No module named 'main_etl'
[2025-06-11T10:27:49.284+0000] {processor.py:842} WARNING - No viable dags retrieved from /opt/airflow/dags/etl_pipeline_dag.py
[2025-06-11T10:27:49.317+0000] {processor.py:183} INFO - Processing /opt/airflow/dags/etl_pipeline_dag.py took 0.105 seconds
[2025-06-11T10:28:20.223+0000] {processor.py:161} INFO - Started process (PID=275) to work on /opt/airflow/dags/etl_pipeline_dag.py
[2025-06-11T10:28:20.228+0000] {processor.py:830} INFO - Processing file /opt/airflow/dags/etl_pipeline_dag.py for tasks to queue
[2025-06-11T10:28:20.235+0000] {logging_mixin.py:188} INFO - [2025-06-11T10:28:20.235+0000] {dagbag.py:545} INFO - Filling up the DagBag from /opt/airflow/dags/etl_pipeline_dag.py
[2025-06-11T10:28:20.323+0000] {logging_mixin.py:188} INFO - [2025-06-11T10:28:20.309+0000] {dagbag.py:355} ERROR - Failed to import: /opt/airflow/dags/etl_pipeline_dag.py
Traceback (most recent call last):
  File "/home/airflow/.local/lib/python3.12/site-packages/airflow/models/dagbag.py", line 351, in parse
    loader.exec_module(new_module)
  File "<frozen importlib._bootstrap_external>", line 995, in exec_module
  File "<frozen importlib._bootstrap>", line 488, in _call_with_frames_removed
  File "/opt/airflow/dags/etl_pipeline_dag.py", line 8, in <module>
    from main_etl import run_etl
ModuleNotFoundError: No module named 'main_etl'
[2025-06-11T10:28:20.327+0000] {processor.py:842} WARNING - No viable dags retrieved from /opt/airflow/dags/etl_pipeline_dag.py
[2025-06-11T10:28:20.460+0000] {processor.py:183} INFO - Processing /opt/airflow/dags/etl_pipeline_dag.py took 0.255 seconds
[2025-06-11T10:28:50.995+0000] {processor.py:161} INFO - Started process (PID=280) to work on /opt/airflow/dags/etl_pipeline_dag.py
[2025-06-11T10:28:50.997+0000] {processor.py:830} INFO - Processing file /opt/airflow/dags/etl_pipeline_dag.py for tasks to queue
[2025-06-11T10:28:51.000+0000] {logging_mixin.py:188} INFO - [2025-06-11T10:28:50.999+0000] {dagbag.py:545} INFO - Filling up the DagBag from /opt/airflow/dags/etl_pipeline_dag.py
[2025-06-11T10:28:51.062+0000] {logging_mixin.py:188} INFO - [2025-06-11T10:28:51.052+0000] {dagbag.py:355} ERROR - Failed to import: /opt/airflow/dags/etl_pipeline_dag.py
Traceback (most recent call last):
  File "/home/airflow/.local/lib/python3.12/site-packages/airflow/models/dagbag.py", line 351, in parse
    loader.exec_module(new_module)
  File "<frozen importlib._bootstrap_external>", line 995, in exec_module
  File "<frozen importlib._bootstrap>", line 488, in _call_with_frames_removed
  File "/opt/airflow/dags/etl_pipeline_dag.py", line 8, in <module>
    from main_etl import run_etl
ModuleNotFoundError: No module named 'main_etl'
[2025-06-11T10:28:51.066+0000] {processor.py:842} WARNING - No viable dags retrieved from /opt/airflow/dags/etl_pipeline_dag.py
[2025-06-11T10:28:51.095+0000] {processor.py:183} INFO - Processing /opt/airflow/dags/etl_pipeline_dag.py took 0.106 seconds
[2025-06-11T10:29:21.724+0000] {processor.py:161} INFO - Started process (PID=285) to work on /opt/airflow/dags/etl_pipeline_dag.py
[2025-06-11T10:29:21.727+0000] {processor.py:830} INFO - Processing file /opt/airflow/dags/etl_pipeline_dag.py for tasks to queue
[2025-06-11T10:29:21.732+0000] {logging_mixin.py:188} INFO - [2025-06-11T10:29:21.731+0000] {dagbag.py:545} INFO - Filling up the DagBag from /opt/airflow/dags/etl_pipeline_dag.py
[2025-06-11T10:29:21.792+0000] {logging_mixin.py:188} INFO - [2025-06-11T10:29:21.783+0000] {dagbag.py:355} ERROR - Failed to import: /opt/airflow/dags/etl_pipeline_dag.py
Traceback (most recent call last):
  File "/home/airflow/.local/lib/python3.12/site-packages/airflow/models/dagbag.py", line 351, in parse
    loader.exec_module(new_module)
  File "<frozen importlib._bootstrap_external>", line 995, in exec_module
  File "<frozen importlib._bootstrap>", line 488, in _call_with_frames_removed
  File "/opt/airflow/dags/etl_pipeline_dag.py", line 8, in <module>
    from main_etl import run_etl
ModuleNotFoundError: No module named 'main_etl'
[2025-06-11T10:29:21.795+0000] {processor.py:842} WARNING - No viable dags retrieved from /opt/airflow/dags/etl_pipeline_dag.py
[2025-06-11T10:29:21.837+0000] {processor.py:183} INFO - Processing /opt/airflow/dags/etl_pipeline_dag.py took 0.120 seconds
[2025-06-11T10:29:52.428+0000] {processor.py:161} INFO - Started process (PID=290) to work on /opt/airflow/dags/etl_pipeline_dag.py
[2025-06-11T10:29:52.430+0000] {processor.py:830} INFO - Processing file /opt/airflow/dags/etl_pipeline_dag.py for tasks to queue
[2025-06-11T10:29:52.433+0000] {logging_mixin.py:188} INFO - [2025-06-11T10:29:52.433+0000] {dagbag.py:545} INFO - Filling up the DagBag from /opt/airflow/dags/etl_pipeline_dag.py
[2025-06-11T10:29:52.487+0000] {logging_mixin.py:188} INFO - [2025-06-11T10:29:52.477+0000] {dagbag.py:355} ERROR - Failed to import: /opt/airflow/dags/etl_pipeline_dag.py
Traceback (most recent call last):
  File "/home/airflow/.local/lib/python3.12/site-packages/airflow/models/dagbag.py", line 351, in parse
    loader.exec_module(new_module)
  File "<frozen importlib._bootstrap_external>", line 995, in exec_module
  File "<frozen importlib._bootstrap>", line 488, in _call_with_frames_removed
  File "/opt/airflow/dags/etl_pipeline_dag.py", line 8, in <module>
    from main_etl import run_etl
ModuleNotFoundError: No module named 'main_etl'
[2025-06-11T10:29:52.490+0000] {processor.py:842} WARNING - No viable dags retrieved from /opt/airflow/dags/etl_pipeline_dag.py
[2025-06-11T10:29:52.520+0000] {processor.py:183} INFO - Processing /opt/airflow/dags/etl_pipeline_dag.py took 0.099 seconds
[2025-06-11T10:30:23.213+0000] {processor.py:161} INFO - Started process (PID=295) to work on /opt/airflow/dags/etl_pipeline_dag.py
[2025-06-11T10:30:23.215+0000] {processor.py:830} INFO - Processing file /opt/airflow/dags/etl_pipeline_dag.py for tasks to queue
[2025-06-11T10:30:23.220+0000] {logging_mixin.py:188} INFO - [2025-06-11T10:30:23.219+0000] {dagbag.py:545} INFO - Filling up the DagBag from /opt/airflow/dags/etl_pipeline_dag.py
[2025-06-11T10:30:23.269+0000] {logging_mixin.py:188} INFO - [2025-06-11T10:30:23.262+0000] {dagbag.py:355} ERROR - Failed to import: /opt/airflow/dags/etl_pipeline_dag.py
Traceback (most recent call last):
  File "/home/airflow/.local/lib/python3.12/site-packages/airflow/models/dagbag.py", line 351, in parse
    loader.exec_module(new_module)
  File "<frozen importlib._bootstrap_external>", line 995, in exec_module
  File "<frozen importlib._bootstrap>", line 488, in _call_with_frames_removed
  File "/opt/airflow/dags/etl_pipeline_dag.py", line 8, in <module>
    from main_etl import run_etl
ModuleNotFoundError: No module named 'main_etl'
[2025-06-11T10:30:23.272+0000] {processor.py:842} WARNING - No viable dags retrieved from /opt/airflow/dags/etl_pipeline_dag.py
[2025-06-11T10:30:23.296+0000] {processor.py:183} INFO - Processing /opt/airflow/dags/etl_pipeline_dag.py took 0.092 seconds
[2025-06-11T10:30:54.264+0000] {processor.py:161} INFO - Started process (PID=300) to work on /opt/airflow/dags/etl_pipeline_dag.py
[2025-06-11T10:30:54.265+0000] {processor.py:830} INFO - Processing file /opt/airflow/dags/etl_pipeline_dag.py for tasks to queue
[2025-06-11T10:30:54.268+0000] {logging_mixin.py:188} INFO - [2025-06-11T10:30:54.268+0000] {dagbag.py:545} INFO - Filling up the DagBag from /opt/airflow/dags/etl_pipeline_dag.py
[2025-06-11T10:30:54.320+0000] {logging_mixin.py:188} INFO - [2025-06-11T10:30:54.311+0000] {dagbag.py:355} ERROR - Failed to import: /opt/airflow/dags/etl_pipeline_dag.py
Traceback (most recent call last):
  File "/home/airflow/.local/lib/python3.12/site-packages/airflow/models/dagbag.py", line 351, in parse
    loader.exec_module(new_module)
  File "<frozen importlib._bootstrap_external>", line 995, in exec_module
  File "<frozen importlib._bootstrap>", line 488, in _call_with_frames_removed
  File "/opt/airflow/dags/etl_pipeline_dag.py", line 8, in <module>
    from main_etl import run_etl
ModuleNotFoundError: No module named 'main_etl'
[2025-06-11T10:30:54.324+0000] {processor.py:842} WARNING - No viable dags retrieved from /opt/airflow/dags/etl_pipeline_dag.py
[2025-06-11T10:30:54.350+0000] {processor.py:183} INFO - Processing /opt/airflow/dags/etl_pipeline_dag.py took 0.091 seconds
[2025-06-11T10:31:25.109+0000] {processor.py:161} INFO - Started process (PID=305) to work on /opt/airflow/dags/etl_pipeline_dag.py
[2025-06-11T10:31:25.111+0000] {processor.py:830} INFO - Processing file /opt/airflow/dags/etl_pipeline_dag.py for tasks to queue
[2025-06-11T10:31:25.114+0000] {logging_mixin.py:188} INFO - [2025-06-11T10:31:25.114+0000] {dagbag.py:545} INFO - Filling up the DagBag from /opt/airflow/dags/etl_pipeline_dag.py
[2025-06-11T10:31:25.172+0000] {logging_mixin.py:188} INFO - [2025-06-11T10:31:25.162+0000] {dagbag.py:355} ERROR - Failed to import: /opt/airflow/dags/etl_pipeline_dag.py
Traceback (most recent call last):
  File "/home/airflow/.local/lib/python3.12/site-packages/airflow/models/dagbag.py", line 351, in parse
    loader.exec_module(new_module)
  File "<frozen importlib._bootstrap_external>", line 995, in exec_module
  File "<frozen importlib._bootstrap>", line 488, in _call_with_frames_removed
  File "/opt/airflow/dags/etl_pipeline_dag.py", line 8, in <module>
    from main_etl import run_etl
ModuleNotFoundError: No module named 'main_etl'
[2025-06-11T10:31:25.176+0000] {processor.py:842} WARNING - No viable dags retrieved from /opt/airflow/dags/etl_pipeline_dag.py
[2025-06-11T10:31:25.202+0000] {processor.py:183} INFO - Processing /opt/airflow/dags/etl_pipeline_dag.py took 0.099 seconds
[2025-06-11T10:31:56.028+0000] {processor.py:161} INFO - Started process (PID=310) to work on /opt/airflow/dags/etl_pipeline_dag.py
[2025-06-11T10:31:56.030+0000] {processor.py:830} INFO - Processing file /opt/airflow/dags/etl_pipeline_dag.py for tasks to queue
[2025-06-11T10:31:56.033+0000] {logging_mixin.py:188} INFO - [2025-06-11T10:31:56.033+0000] {dagbag.py:545} INFO - Filling up the DagBag from /opt/airflow/dags/etl_pipeline_dag.py
[2025-06-11T10:31:56.101+0000] {logging_mixin.py:188} INFO - [2025-06-11T10:31:56.091+0000] {dagbag.py:355} ERROR - Failed to import: /opt/airflow/dags/etl_pipeline_dag.py
Traceback (most recent call last):
  File "/home/airflow/.local/lib/python3.12/site-packages/airflow/models/dagbag.py", line 351, in parse
    loader.exec_module(new_module)
  File "<frozen importlib._bootstrap_external>", line 995, in exec_module
  File "<frozen importlib._bootstrap>", line 488, in _call_with_frames_removed
  File "/opt/airflow/dags/etl_pipeline_dag.py", line 8, in <module>
    from main_etl import run_etl
ModuleNotFoundError: No module named 'main_etl'
[2025-06-11T10:31:56.105+0000] {processor.py:842} WARNING - No viable dags retrieved from /opt/airflow/dags/etl_pipeline_dag.py
[2025-06-11T10:31:56.127+0000] {processor.py:183} INFO - Processing /opt/airflow/dags/etl_pipeline_dag.py took 0.105 seconds
[2025-06-11T10:32:27.019+0000] {processor.py:161} INFO - Started process (PID=315) to work on /opt/airflow/dags/etl_pipeline_dag.py
[2025-06-11T10:32:27.021+0000] {processor.py:830} INFO - Processing file /opt/airflow/dags/etl_pipeline_dag.py for tasks to queue
[2025-06-11T10:32:27.025+0000] {logging_mixin.py:188} INFO - [2025-06-11T10:32:27.024+0000] {dagbag.py:545} INFO - Filling up the DagBag from /opt/airflow/dags/etl_pipeline_dag.py
[2025-06-11T10:32:27.101+0000] {logging_mixin.py:188} INFO - [2025-06-11T10:32:27.089+0000] {dagbag.py:355} ERROR - Failed to import: /opt/airflow/dags/etl_pipeline_dag.py
Traceback (most recent call last):
  File "/home/airflow/.local/lib/python3.12/site-packages/airflow/models/dagbag.py", line 351, in parse
    loader.exec_module(new_module)
  File "<frozen importlib._bootstrap_external>", line 995, in exec_module
  File "<frozen importlib._bootstrap>", line 488, in _call_with_frames_removed
  File "/opt/airflow/dags/etl_pipeline_dag.py", line 8, in <module>
    from main_etl import run_etl
ModuleNotFoundError: No module named 'main_etl'
[2025-06-11T10:32:27.105+0000] {processor.py:842} WARNING - No viable dags retrieved from /opt/airflow/dags/etl_pipeline_dag.py
[2025-06-11T10:32:27.138+0000] {processor.py:183} INFO - Processing /opt/airflow/dags/etl_pipeline_dag.py took 0.126 seconds
[2025-06-11T10:32:57.707+0000] {processor.py:161} INFO - Started process (PID=320) to work on /opt/airflow/dags/etl_pipeline_dag.py
[2025-06-11T10:32:57.709+0000] {processor.py:830} INFO - Processing file /opt/airflow/dags/etl_pipeline_dag.py for tasks to queue
[2025-06-11T10:32:57.712+0000] {logging_mixin.py:188} INFO - [2025-06-11T10:32:57.712+0000] {dagbag.py:545} INFO - Filling up the DagBag from /opt/airflow/dags/etl_pipeline_dag.py
[2025-06-11T10:32:57.155+0000] {logging_mixin.py:188} INFO - [2025-06-11T10:32:57.146+0000] {dagbag.py:355} ERROR - Failed to import: /opt/airflow/dags/etl_pipeline_dag.py
Traceback (most recent call last):
  File "/home/airflow/.local/lib/python3.12/site-packages/airflow/models/dagbag.py", line 351, in parse
    loader.exec_module(new_module)
  File "<frozen importlib._bootstrap_external>", line 995, in exec_module
  File "<frozen importlib._bootstrap>", line 488, in _call_with_frames_removed
  File "/opt/airflow/dags/etl_pipeline_dag.py", line 8, in <module>
    from main_etl import run_etl
ModuleNotFoundError: No module named 'main_etl'
[2025-06-11T10:32:57.158+0000] {processor.py:842} WARNING - No viable dags retrieved from /opt/airflow/dags/etl_pipeline_dag.py
[2025-06-11T10:32:57.197+0000] {processor.py:183} INFO - Processing /opt/airflow/dags/etl_pipeline_dag.py took 0.118 seconds
[2025-06-11T10:33:27.582+0000] {processor.py:161} INFO - Started process (PID=325) to work on /opt/airflow/dags/etl_pipeline_dag.py
[2025-06-11T10:33:27.584+0000] {processor.py:830} INFO - Processing file /opt/airflow/dags/etl_pipeline_dag.py for tasks to queue
[2025-06-11T10:33:27.586+0000] {logging_mixin.py:188} INFO - [2025-06-11T10:33:27.586+0000] {dagbag.py:545} INFO - Filling up the DagBag from /opt/airflow/dags/etl_pipeline_dag.py
[2025-06-11T10:33:27.639+0000] {logging_mixin.py:188} INFO - [2025-06-11T10:33:27.629+0000] {dagbag.py:355} ERROR - Failed to import: /opt/airflow/dags/etl_pipeline_dag.py
Traceback (most recent call last):
  File "/home/airflow/.local/lib/python3.12/site-packages/airflow/models/dagbag.py", line 351, in parse
    loader.exec_module(new_module)
  File "<frozen importlib._bootstrap_external>", line 995, in exec_module
  File "<frozen importlib._bootstrap>", line 488, in _call_with_frames_removed
  File "/opt/airflow/dags/etl_pipeline_dag.py", line 8, in <module>
    from main_etl import run_etl
ModuleNotFoundError: No module named 'main_etl'
[2025-06-11T10:33:27.644+0000] {processor.py:842} WARNING - No viable dags retrieved from /opt/airflow/dags/etl_pipeline_dag.py
[2025-06-11T10:33:27.696+0000] {processor.py:183} INFO - Processing /opt/airflow/dags/etl_pipeline_dag.py took 0.119 seconds
[2025-06-11T10:33:58.298+0000] {processor.py:161} INFO - Started process (PID=330) to work on /opt/airflow/dags/etl_pipeline_dag.py
[2025-06-11T10:33:58.299+0000] {processor.py:830} INFO - Processing file /opt/airflow/dags/etl_pipeline_dag.py for tasks to queue
[2025-06-11T10:33:58.304+0000] {logging_mixin.py:188} INFO - [2025-06-11T10:33:58.304+0000] {dagbag.py:545} INFO - Filling up the DagBag from /opt/airflow/dags/etl_pipeline_dag.py
[2025-06-11T10:33:58.368+0000] {logging_mixin.py:188} INFO - [2025-06-11T10:33:58.358+0000] {dagbag.py:355} ERROR - Failed to import: /opt/airflow/dags/etl_pipeline_dag.py
Traceback (most recent call last):
  File "/home/airflow/.local/lib/python3.12/site-packages/airflow/models/dagbag.py", line 351, in parse
    loader.exec_module(new_module)
  File "<frozen importlib._bootstrap_external>", line 995, in exec_module
  File "<frozen importlib._bootstrap>", line 488, in _call_with_frames_removed
  File "/opt/airflow/dags/etl_pipeline_dag.py", line 8, in <module>
    from main_etl import run_etl
ModuleNotFoundError: No module named 'main_etl'
[2025-06-11T10:33:58.373+0000] {processor.py:842} WARNING - No viable dags retrieved from /opt/airflow/dags/etl_pipeline_dag.py
[2025-06-11T10:33:58.432+0000] {processor.py:183} INFO - Processing /opt/airflow/dags/etl_pipeline_dag.py took 0.141 seconds
[2025-06-11T10:34:29.726+0000] {processor.py:161} INFO - Started process (PID=335) to work on /opt/airflow/dags/etl_pipeline_dag.py
[2025-06-11T10:34:29.745+0000] {processor.py:830} INFO - Processing file /opt/airflow/dags/etl_pipeline_dag.py for tasks to queue
[2025-06-11T10:34:29.779+0000] {logging_mixin.py:188} INFO - [2025-06-11T10:34:29.770+0000] {dagbag.py:545} INFO - Filling up the DagBag from /opt/airflow/dags/etl_pipeline_dag.py
[2025-06-11T10:34:29.871+0000] {logging_mixin.py:188} INFO - [2025-06-11T10:34:29.856+0000] {dagbag.py:355} ERROR - Failed to import: /opt/airflow/dags/etl_pipeline_dag.py
Traceback (most recent call last):
  File "/home/airflow/.local/lib/python3.12/site-packages/airflow/models/dagbag.py", line 351, in parse
    loader.exec_module(new_module)
  File "<frozen importlib._bootstrap_external>", line 995, in exec_module
  File "<frozen importlib._bootstrap>", line 488, in _call_with_frames_removed
  File "/opt/airflow/dags/etl_pipeline_dag.py", line 8, in <module>
    from main_etl import run_etl
ModuleNotFoundError: No module named 'main_etl'
[2025-06-11T10:34:29.878+0000] {processor.py:842} WARNING - No viable dags retrieved from /opt/airflow/dags/etl_pipeline_dag.py
[2025-06-11T10:34:30.041+0000] {processor.py:183} INFO - Processing /opt/airflow/dags/etl_pipeline_dag.py took 0.444 seconds
[2025-06-11T10:35:00.321+0000] {processor.py:161} INFO - Started process (PID=340) to work on /opt/airflow/dags/etl_pipeline_dag.py
[2025-06-11T10:35:00.334+0000] {processor.py:830} INFO - Processing file /opt/airflow/dags/etl_pipeline_dag.py for tasks to queue
[2025-06-11T10:35:00.352+0000] {logging_mixin.py:188} INFO - [2025-06-11T10:35:00.344+0000] {dagbag.py:545} INFO - Filling up the DagBag from /opt/airflow/dags/etl_pipeline_dag.py
[2025-06-11T10:35:00.535+0000] {logging_mixin.py:188} INFO - [2025-06-11T10:35:00.501+0000] {dagbag.py:355} ERROR - Failed to import: /opt/airflow/dags/etl_pipeline_dag.py
Traceback (most recent call last):
  File "/home/airflow/.local/lib/python3.12/site-packages/airflow/models/dagbag.py", line 351, in parse
    loader.exec_module(new_module)
  File "<frozen importlib._bootstrap_external>", line 995, in exec_module
  File "<frozen importlib._bootstrap>", line 488, in _call_with_frames_removed
  File "/opt/airflow/dags/etl_pipeline_dag.py", line 8, in <module>
    from main_etl import run_etl
ModuleNotFoundError: No module named 'main_etl'
[2025-06-11T10:35:00.545+0000] {processor.py:842} WARNING - No viable dags retrieved from /opt/airflow/dags/etl_pipeline_dag.py
[2025-06-11T10:35:00.754+0000] {processor.py:183} INFO - Processing /opt/airflow/dags/etl_pipeline_dag.py took 0.482 seconds
[2025-06-11T10:35:30.943+0000] {processor.py:161} INFO - Started process (PID=345) to work on /opt/airflow/dags/etl_pipeline_dag.py
[2025-06-11T10:35:30.946+0000] {processor.py:830} INFO - Processing file /opt/airflow/dags/etl_pipeline_dag.py for tasks to queue
[2025-06-11T10:35:30.956+0000] {logging_mixin.py:188} INFO - [2025-06-11T10:35:30.954+0000] {dagbag.py:545} INFO - Filling up the DagBag from /opt/airflow/dags/etl_pipeline_dag.py
[2025-06-11T10:35:31.023+0000] {logging_mixin.py:188} INFO - [2025-06-11T10:35:31.013+0000] {dagbag.py:355} ERROR - Failed to import: /opt/airflow/dags/etl_pipeline_dag.py
Traceback (most recent call last):
  File "/home/airflow/.local/lib/python3.12/site-packages/airflow/models/dagbag.py", line 351, in parse
    loader.exec_module(new_module)
  File "<frozen importlib._bootstrap_external>", line 995, in exec_module
  File "<frozen importlib._bootstrap>", line 488, in _call_with_frames_removed
  File "/opt/airflow/dags/etl_pipeline_dag.py", line 8, in <module>
    from main_etl import run_etl
ModuleNotFoundError: No module named 'main_etl'
[2025-06-11T10:35:31.027+0000] {processor.py:842} WARNING - No viable dags retrieved from /opt/airflow/dags/etl_pipeline_dag.py
[2025-06-11T10:35:31.106+0000] {processor.py:183} INFO - Processing /opt/airflow/dags/etl_pipeline_dag.py took 0.185 seconds
[2025-06-11T10:36:01.692+0000] {processor.py:161} INFO - Started process (PID=350) to work on /opt/airflow/dags/etl_pipeline_dag.py
[2025-06-11T10:36:01.695+0000] {processor.py:830} INFO - Processing file /opt/airflow/dags/etl_pipeline_dag.py for tasks to queue
[2025-06-11T10:36:01.699+0000] {logging_mixin.py:188} INFO - [2025-06-11T10:36:01.698+0000] {dagbag.py:545} INFO - Filling up the DagBag from /opt/airflow/dags/etl_pipeline_dag.py
[2025-06-11T10:36:01.757+0000] {logging_mixin.py:188} INFO - [2025-06-11T10:36:01.747+0000] {dagbag.py:355} ERROR - Failed to import: /opt/airflow/dags/etl_pipeline_dag.py
Traceback (most recent call last):
  File "/home/airflow/.local/lib/python3.12/site-packages/airflow/models/dagbag.py", line 351, in parse
    loader.exec_module(new_module)
  File "<frozen importlib._bootstrap_external>", line 995, in exec_module
  File "<frozen importlib._bootstrap>", line 488, in _call_with_frames_removed
  File "/opt/airflow/dags/etl_pipeline_dag.py", line 8, in <module>
    from main_etl import run_etl
ModuleNotFoundError: No module named 'main_etl'
[2025-06-11T10:36:01.760+0000] {processor.py:842} WARNING - No viable dags retrieved from /opt/airflow/dags/etl_pipeline_dag.py
[2025-06-11T10:36:01.795+0000] {processor.py:183} INFO - Processing /opt/airflow/dags/etl_pipeline_dag.py took 0.109 seconds
[2025-06-11T10:36:32.572+0000] {processor.py:161} INFO - Started process (PID=355) to work on /opt/airflow/dags/etl_pipeline_dag.py
[2025-06-11T10:36:32.576+0000] {processor.py:830} INFO - Processing file /opt/airflow/dags/etl_pipeline_dag.py for tasks to queue
[2025-06-11T10:36:32.589+0000] {logging_mixin.py:188} INFO - [2025-06-11T10:36:32.588+0000] {dagbag.py:545} INFO - Filling up the DagBag from /opt/airflow/dags/etl_pipeline_dag.py
[2025-06-11T10:36:32.653+0000] {logging_mixin.py:188} INFO - [2025-06-11T10:36:32.642+0000] {dagbag.py:355} ERROR - Failed to import: /opt/airflow/dags/etl_pipeline_dag.py
Traceback (most recent call last):
  File "/home/airflow/.local/lib/python3.12/site-packages/airflow/models/dagbag.py", line 351, in parse
    loader.exec_module(new_module)
  File "<frozen importlib._bootstrap_external>", line 995, in exec_module
  File "<frozen importlib._bootstrap>", line 488, in _call_with_frames_removed
  File "/opt/airflow/dags/etl_pipeline_dag.py", line 8, in <module>
    from main_etl import run_etl
ModuleNotFoundError: No module named 'main_etl'
[2025-06-11T10:36:32.656+0000] {processor.py:842} WARNING - No viable dags retrieved from /opt/airflow/dags/etl_pipeline_dag.py
[2025-06-11T10:36:32.710+0000] {processor.py:183} INFO - Processing /opt/airflow/dags/etl_pipeline_dag.py took 0.159 seconds
[2025-06-11T10:37:03.268+0000] {processor.py:161} INFO - Started process (PID=360) to work on /opt/airflow/dags/etl_pipeline_dag.py
[2025-06-11T10:37:03.287+0000] {processor.py:830} INFO - Processing file /opt/airflow/dags/etl_pipeline_dag.py for tasks to queue
[2025-06-11T10:37:03.297+0000] {logging_mixin.py:188} INFO - [2025-06-11T10:37:03.296+0000] {dagbag.py:545} INFO - Filling up the DagBag from /opt/airflow/dags/etl_pipeline_dag.py
[2025-06-11T10:37:03.370+0000] {logging_mixin.py:188} INFO - [2025-06-11T10:37:03.363+0000] {dagbag.py:355} ERROR - Failed to import: /opt/airflow/dags/etl_pipeline_dag.py
Traceback (most recent call last):
  File "/home/airflow/.local/lib/python3.12/site-packages/airflow/models/dagbag.py", line 351, in parse
    loader.exec_module(new_module)
  File "<frozen importlib._bootstrap_external>", line 995, in exec_module
  File "<frozen importlib._bootstrap>", line 488, in _call_with_frames_removed
  File "/opt/airflow/dags/etl_pipeline_dag.py", line 8, in <module>
    from main_etl import run_etl
ModuleNotFoundError: No module named 'main_etl'
[2025-06-11T10:37:03.372+0000] {processor.py:842} WARNING - No viable dags retrieved from /opt/airflow/dags/etl_pipeline_dag.py
[2025-06-11T10:37:03.401+0000] {processor.py:183} INFO - Processing /opt/airflow/dags/etl_pipeline_dag.py took 0.158 seconds
[2025-06-11T10:37:34.104+0000] {processor.py:161} INFO - Started process (PID=365) to work on /opt/airflow/dags/etl_pipeline_dag.py
[2025-06-11T10:37:34.106+0000] {processor.py:830} INFO - Processing file /opt/airflow/dags/etl_pipeline_dag.py for tasks to queue
[2025-06-11T10:37:34.109+0000] {logging_mixin.py:188} INFO - [2025-06-11T10:37:34.109+0000] {dagbag.py:545} INFO - Filling up the DagBag from /opt/airflow/dags/etl_pipeline_dag.py
[2025-06-11T10:37:34.169+0000] {logging_mixin.py:188} INFO - [2025-06-11T10:37:34.160+0000] {dagbag.py:355} ERROR - Failed to import: /opt/airflow/dags/etl_pipeline_dag.py
Traceback (most recent call last):
  File "/home/airflow/.local/lib/python3.12/site-packages/airflow/models/dagbag.py", line 351, in parse
    loader.exec_module(new_module)
  File "<frozen importlib._bootstrap_external>", line 995, in exec_module
  File "<frozen importlib._bootstrap>", line 488, in _call_with_frames_removed
  File "/opt/airflow/dags/etl_pipeline_dag.py", line 8, in <module>
    from main_etl import run_etl
ModuleNotFoundError: No module named 'main_etl'
[2025-06-11T10:37:34.174+0000] {processor.py:842} WARNING - No viable dags retrieved from /opt/airflow/dags/etl_pipeline_dag.py
[2025-06-11T10:37:34.201+0000] {processor.py:183} INFO - Processing /opt/airflow/dags/etl_pipeline_dag.py took 0.104 seconds
[2025-06-11T10:38:04.893+0000] {processor.py:161} INFO - Started process (PID=370) to work on /opt/airflow/dags/etl_pipeline_dag.py
[2025-06-11T10:38:04.895+0000] {processor.py:830} INFO - Processing file /opt/airflow/dags/etl_pipeline_dag.py for tasks to queue
[2025-06-11T10:38:04.898+0000] {logging_mixin.py:188} INFO - [2025-06-11T10:38:04.897+0000] {dagbag.py:545} INFO - Filling up the DagBag from /opt/airflow/dags/etl_pipeline_dag.py
[2025-06-11T10:38:04.950+0000] {logging_mixin.py:188} INFO - [2025-06-11T10:38:04.941+0000] {dagbag.py:355} ERROR - Failed to import: /opt/airflow/dags/etl_pipeline_dag.py
Traceback (most recent call last):
  File "/home/airflow/.local/lib/python3.12/site-packages/airflow/models/dagbag.py", line 351, in parse
    loader.exec_module(new_module)
  File "<frozen importlib._bootstrap_external>", line 995, in exec_module
  File "<frozen importlib._bootstrap>", line 488, in _call_with_frames_removed
  File "/opt/airflow/dags/etl_pipeline_dag.py", line 8, in <module>
    from main_etl import run_etl
ModuleNotFoundError: No module named 'main_etl'
[2025-06-11T10:38:04.953+0000] {processor.py:842} WARNING - No viable dags retrieved from /opt/airflow/dags/etl_pipeline_dag.py
[2025-06-11T10:38:04.980+0000] {processor.py:183} INFO - Processing /opt/airflow/dags/etl_pipeline_dag.py took 0.093 seconds
[2025-06-11T10:38:35.654+0000] {processor.py:161} INFO - Started process (PID=375) to work on /opt/airflow/dags/etl_pipeline_dag.py
[2025-06-11T10:38:35.656+0000] {processor.py:830} INFO - Processing file /opt/airflow/dags/etl_pipeline_dag.py for tasks to queue
[2025-06-11T10:38:35.664+0000] {logging_mixin.py:188} INFO - [2025-06-11T10:38:35.663+0000] {dagbag.py:545} INFO - Filling up the DagBag from /opt/airflow/dags/etl_pipeline_dag.py
[2025-06-11T10:38:35.727+0000] {logging_mixin.py:188} INFO - [2025-06-11T10:38:35.717+0000] {dagbag.py:355} ERROR - Failed to import: /opt/airflow/dags/etl_pipeline_dag.py
Traceback (most recent call last):
  File "/home/airflow/.local/lib/python3.12/site-packages/airflow/models/dagbag.py", line 351, in parse
    loader.exec_module(new_module)
  File "<frozen importlib._bootstrap_external>", line 995, in exec_module
  File "<frozen importlib._bootstrap>", line 488, in _call_with_frames_removed
  File "/opt/airflow/dags/etl_pipeline_dag.py", line 8, in <module>
    from main_etl import run_etl
ModuleNotFoundError: No module named 'main_etl'
[2025-06-11T10:38:35.734+0000] {processor.py:842} WARNING - No viable dags retrieved from /opt/airflow/dags/etl_pipeline_dag.py
[2025-06-11T10:38:35.808+0000] {processor.py:183} INFO - Processing /opt/airflow/dags/etl_pipeline_dag.py took 0.188 seconds
[2025-06-11T10:39:06.448+0000] {processor.py:161} INFO - Started process (PID=380) to work on /opt/airflow/dags/etl_pipeline_dag.py
[2025-06-11T10:39:06.451+0000] {processor.py:830} INFO - Processing file /opt/airflow/dags/etl_pipeline_dag.py for tasks to queue
[2025-06-11T10:39:06.456+0000] {logging_mixin.py:188} INFO - [2025-06-11T10:39:06.456+0000] {dagbag.py:545} INFO - Filling up the DagBag from /opt/airflow/dags/etl_pipeline_dag.py
[2025-06-11T10:39:06.517+0000] {logging_mixin.py:188} INFO - [2025-06-11T10:39:06.508+0000] {dagbag.py:355} ERROR - Failed to import: /opt/airflow/dags/etl_pipeline_dag.py
Traceback (most recent call last):
  File "/home/airflow/.local/lib/python3.12/site-packages/airflow/models/dagbag.py", line 351, in parse
    loader.exec_module(new_module)
  File "<frozen importlib._bootstrap_external>", line 995, in exec_module
  File "<frozen importlib._bootstrap>", line 488, in _call_with_frames_removed
  File "/opt/airflow/dags/etl_pipeline_dag.py", line 8, in <module>
    from main_etl import run_etl
ModuleNotFoundError: No module named 'main_etl'
[2025-06-11T10:39:06.521+0000] {processor.py:842} WARNING - No viable dags retrieved from /opt/airflow/dags/etl_pipeline_dag.py
[2025-06-11T10:39:06.554+0000] {processor.py:183} INFO - Processing /opt/airflow/dags/etl_pipeline_dag.py took 0.112 seconds
[2025-06-11T10:39:37.357+0000] {processor.py:161} INFO - Started process (PID=385) to work on /opt/airflow/dags/etl_pipeline_dag.py
[2025-06-11T10:39:37.359+0000] {processor.py:830} INFO - Processing file /opt/airflow/dags/etl_pipeline_dag.py for tasks to queue
[2025-06-11T10:39:37.361+0000] {logging_mixin.py:188} INFO - [2025-06-11T10:39:37.361+0000] {dagbag.py:545} INFO - Filling up the DagBag from /opt/airflow/dags/etl_pipeline_dag.py
[2025-06-11T10:39:37.424+0000] {logging_mixin.py:188} INFO - [2025-06-11T10:39:37.415+0000] {dagbag.py:355} ERROR - Failed to import: /opt/airflow/dags/etl_pipeline_dag.py
Traceback (most recent call last):
  File "/home/airflow/.local/lib/python3.12/site-packages/airflow/models/dagbag.py", line 351, in parse
    loader.exec_module(new_module)
  File "<frozen importlib._bootstrap_external>", line 995, in exec_module
  File "<frozen importlib._bootstrap>", line 488, in _call_with_frames_removed
  File "/opt/airflow/dags/etl_pipeline_dag.py", line 8, in <module>
    from main_etl import run_etl
ModuleNotFoundError: No module named 'main_etl'
[2025-06-11T10:39:37.427+0000] {processor.py:842} WARNING - No viable dags retrieved from /opt/airflow/dags/etl_pipeline_dag.py
[2025-06-11T10:39:37.452+0000] {processor.py:183} INFO - Processing /opt/airflow/dags/etl_pipeline_dag.py took 0.100 seconds
[2025-06-11T10:40:08.050+0000] {processor.py:161} INFO - Started process (PID=390) to work on /opt/airflow/dags/etl_pipeline_dag.py
[2025-06-11T10:40:08.052+0000] {processor.py:830} INFO - Processing file /opt/airflow/dags/etl_pipeline_dag.py for tasks to queue
[2025-06-11T10:40:08.054+0000] {logging_mixin.py:188} INFO - [2025-06-11T10:40:08.054+0000] {dagbag.py:545} INFO - Filling up the DagBag from /opt/airflow/dags/etl_pipeline_dag.py
[2025-06-11T10:40:08.108+0000] {logging_mixin.py:188} INFO - [2025-06-11T10:40:08.100+0000] {dagbag.py:355} ERROR - Failed to import: /opt/airflow/dags/etl_pipeline_dag.py
Traceback (most recent call last):
  File "/home/airflow/.local/lib/python3.12/site-packages/airflow/models/dagbag.py", line 351, in parse
    loader.exec_module(new_module)
  File "<frozen importlib._bootstrap_external>", line 995, in exec_module
  File "<frozen importlib._bootstrap>", line 488, in _call_with_frames_removed
  File "/opt/airflow/dags/etl_pipeline_dag.py", line 8, in <module>
    from main_etl import run_etl
ModuleNotFoundError: No module named 'main_etl'
[2025-06-11T10:40:08.111+0000] {processor.py:842} WARNING - No viable dags retrieved from /opt/airflow/dags/etl_pipeline_dag.py
[2025-06-11T10:40:08.139+0000] {processor.py:183} INFO - Processing /opt/airflow/dags/etl_pipeline_dag.py took 0.094 seconds
[2025-06-11T10:40:38.877+0000] {processor.py:161} INFO - Started process (PID=395) to work on /opt/airflow/dags/etl_pipeline_dag.py
[2025-06-11T10:40:38.879+0000] {processor.py:830} INFO - Processing file /opt/airflow/dags/etl_pipeline_dag.py for tasks to queue
[2025-06-11T10:40:38.881+0000] {logging_mixin.py:188} INFO - [2025-06-11T10:40:38.881+0000] {dagbag.py:545} INFO - Filling up the DagBag from /opt/airflow/dags/etl_pipeline_dag.py
[2025-06-11T10:40:38.934+0000] {logging_mixin.py:188} INFO - [2025-06-11T10:40:38.925+0000] {dagbag.py:355} ERROR - Failed to import: /opt/airflow/dags/etl_pipeline_dag.py
Traceback (most recent call last):
  File "/home/airflow/.local/lib/python3.12/site-packages/airflow/models/dagbag.py", line 351, in parse
    loader.exec_module(new_module)
  File "<frozen importlib._bootstrap_external>", line 995, in exec_module
  File "<frozen importlib._bootstrap>", line 488, in _call_with_frames_removed
  File "/opt/airflow/dags/etl_pipeline_dag.py", line 8, in <module>
    from main_etl import run_etl
ModuleNotFoundError: No module named 'main_etl'
[2025-06-11T10:40:38.939+0000] {processor.py:842} WARNING - No viable dags retrieved from /opt/airflow/dags/etl_pipeline_dag.py
[2025-06-11T10:40:38.962+0000] {processor.py:183} INFO - Processing /opt/airflow/dags/etl_pipeline_dag.py took 0.090 seconds
[2025-06-11T10:41:09.619+0000] {processor.py:161} INFO - Started process (PID=400) to work on /opt/airflow/dags/etl_pipeline_dag.py
[2025-06-11T10:41:09.621+0000] {processor.py:830} INFO - Processing file /opt/airflow/dags/etl_pipeline_dag.py for tasks to queue
[2025-06-11T10:41:09.624+0000] {logging_mixin.py:188} INFO - [2025-06-11T10:41:09.623+0000] {dagbag.py:545} INFO - Filling up the DagBag from /opt/airflow/dags/etl_pipeline_dag.py
[2025-06-11T10:41:09.682+0000] {logging_mixin.py:188} INFO - [2025-06-11T10:41:09.674+0000] {dagbag.py:355} ERROR - Failed to import: /opt/airflow/dags/etl_pipeline_dag.py
Traceback (most recent call last):
  File "/home/airflow/.local/lib/python3.12/site-packages/airflow/models/dagbag.py", line 351, in parse
    loader.exec_module(new_module)
  File "<frozen importlib._bootstrap_external>", line 995, in exec_module
  File "<frozen importlib._bootstrap>", line 488, in _call_with_frames_removed
  File "/opt/airflow/dags/etl_pipeline_dag.py", line 8, in <module>
    from main_etl import run_etl
ModuleNotFoundError: No module named 'main_etl'
[2025-06-11T10:41:09.685+0000] {processor.py:842} WARNING - No viable dags retrieved from /opt/airflow/dags/etl_pipeline_dag.py
[2025-06-11T10:41:09.714+0000] {processor.py:183} INFO - Processing /opt/airflow/dags/etl_pipeline_dag.py took 0.102 seconds
[2025-06-11T10:41:40.491+0000] {processor.py:161} INFO - Started process (PID=405) to work on /opt/airflow/dags/etl_pipeline_dag.py
[2025-06-11T10:41:40.492+0000] {processor.py:830} INFO - Processing file /opt/airflow/dags/etl_pipeline_dag.py for tasks to queue
[2025-06-11T10:41:40.495+0000] {logging_mixin.py:188} INFO - [2025-06-11T10:41:40.495+0000] {dagbag.py:545} INFO - Filling up the DagBag from /opt/airflow/dags/etl_pipeline_dag.py
[2025-06-11T10:41:40.560+0000] {logging_mixin.py:188} INFO - [2025-06-11T10:41:40.550+0000] {dagbag.py:355} ERROR - Failed to import: /opt/airflow/dags/etl_pipeline_dag.py
Traceback (most recent call last):
  File "/home/airflow/.local/lib/python3.12/site-packages/airflow/models/dagbag.py", line 351, in parse
    loader.exec_module(new_module)
  File "<frozen importlib._bootstrap_external>", line 995, in exec_module
  File "<frozen importlib._bootstrap>", line 488, in _call_with_frames_removed
  File "/opt/airflow/dags/etl_pipeline_dag.py", line 8, in <module>
    from main_etl import run_etl
ModuleNotFoundError: No module named 'main_etl'
[2025-06-11T10:41:40.564+0000] {processor.py:842} WARNING - No viable dags retrieved from /opt/airflow/dags/etl_pipeline_dag.py
[2025-06-11T10:41:40.586+0000] {processor.py:183} INFO - Processing /opt/airflow/dags/etl_pipeline_dag.py took 0.100 seconds
[2025-06-11T10:42:11.218+0000] {processor.py:161} INFO - Started process (PID=410) to work on /opt/airflow/dags/etl_pipeline_dag.py
[2025-06-11T10:42:11.220+0000] {processor.py:830} INFO - Processing file /opt/airflow/dags/etl_pipeline_dag.py for tasks to queue
[2025-06-11T10:42:11.223+0000] {logging_mixin.py:188} INFO - [2025-06-11T10:42:11.222+0000] {dagbag.py:545} INFO - Filling up the DagBag from /opt/airflow/dags/etl_pipeline_dag.py
[2025-06-11T10:42:11.276+0000] {logging_mixin.py:188} INFO - [2025-06-11T10:42:11.269+0000] {dagbag.py:355} ERROR - Failed to import: /opt/airflow/dags/etl_pipeline_dag.py
Traceback (most recent call last):
  File "/home/airflow/.local/lib/python3.12/site-packages/airflow/models/dagbag.py", line 351, in parse
    loader.exec_module(new_module)
  File "<frozen importlib._bootstrap_external>", line 995, in exec_module
  File "<frozen importlib._bootstrap>", line 488, in _call_with_frames_removed
  File "/opt/airflow/dags/etl_pipeline_dag.py", line 8, in <module>
    from main_etl import run_etl
ModuleNotFoundError: No module named 'main_etl'
[2025-06-11T10:42:11.279+0000] {processor.py:842} WARNING - No viable dags retrieved from /opt/airflow/dags/etl_pipeline_dag.py
[2025-06-11T10:42:11.319+0000] {processor.py:183} INFO - Processing /opt/airflow/dags/etl_pipeline_dag.py took 0.111 seconds
[2025-06-11T10:42:42.185+0000] {processor.py:161} INFO - Started process (PID=415) to work on /opt/airflow/dags/etl_pipeline_dag.py
[2025-06-11T10:42:42.187+0000] {processor.py:830} INFO - Processing file /opt/airflow/dags/etl_pipeline_dag.py for tasks to queue
[2025-06-11T10:42:42.190+0000] {logging_mixin.py:188} INFO - [2025-06-11T10:42:42.189+0000] {dagbag.py:545} INFO - Filling up the DagBag from /opt/airflow/dags/etl_pipeline_dag.py
[2025-06-11T10:42:42.245+0000] {logging_mixin.py:188} INFO - [2025-06-11T10:42:42.235+0000] {dagbag.py:355} ERROR - Failed to import: /opt/airflow/dags/etl_pipeline_dag.py
Traceback (most recent call last):
  File "/home/airflow/.local/lib/python3.12/site-packages/airflow/models/dagbag.py", line 351, in parse
    loader.exec_module(new_module)
  File "<frozen importlib._bootstrap_external>", line 995, in exec_module
  File "<frozen importlib._bootstrap>", line 488, in _call_with_frames_removed
  File "/opt/airflow/dags/etl_pipeline_dag.py", line 8, in <module>
    from main_etl import run_etl
ModuleNotFoundError: No module named 'main_etl'
[2025-06-11T10:42:42.249+0000] {processor.py:842} WARNING - No viable dags retrieved from /opt/airflow/dags/etl_pipeline_dag.py
[2025-06-11T10:42:42.286+0000] {processor.py:183} INFO - Processing /opt/airflow/dags/etl_pipeline_dag.py took 0.107 seconds
[2025-06-11T10:43:13.006+0000] {processor.py:161} INFO - Started process (PID=420) to work on /opt/airflow/dags/etl_pipeline_dag.py
[2025-06-11T10:43:13.008+0000] {processor.py:830} INFO - Processing file /opt/airflow/dags/etl_pipeline_dag.py for tasks to queue
[2025-06-11T10:43:13.011+0000] {logging_mixin.py:188} INFO - [2025-06-11T10:43:13.011+0000] {dagbag.py:545} INFO - Filling up the DagBag from /opt/airflow/dags/etl_pipeline_dag.py
[2025-06-11T10:43:13.075+0000] {logging_mixin.py:188} INFO - [2025-06-11T10:43:13.064+0000] {dagbag.py:355} ERROR - Failed to import: /opt/airflow/dags/etl_pipeline_dag.py
Traceback (most recent call last):
  File "/home/airflow/.local/lib/python3.12/site-packages/airflow/models/dagbag.py", line 351, in parse
    loader.exec_module(new_module)
  File "<frozen importlib._bootstrap_external>", line 995, in exec_module
  File "<frozen importlib._bootstrap>", line 488, in _call_with_frames_removed
  File "/opt/airflow/dags/etl_pipeline_dag.py", line 8, in <module>
    from main_etl import run_etl
ModuleNotFoundError: No module named 'main_etl'
[2025-06-11T10:43:13.079+0000] {processor.py:842} WARNING - No viable dags retrieved from /opt/airflow/dags/etl_pipeline_dag.py
[2025-06-11T10:43:13.128+0000] {processor.py:183} INFO - Processing /opt/airflow/dags/etl_pipeline_dag.py took 0.127 seconds
[2025-06-11T10:43:43.711+0000] {processor.py:161} INFO - Started process (PID=425) to work on /opt/airflow/dags/etl_pipeline_dag.py
[2025-06-11T10:43:43.713+0000] {processor.py:830} INFO - Processing file /opt/airflow/dags/etl_pipeline_dag.py for tasks to queue
[2025-06-11T10:43:43.715+0000] {logging_mixin.py:188} INFO - [2025-06-11T10:43:43.714+0000] {dagbag.py:545} INFO - Filling up the DagBag from /opt/airflow/dags/etl_pipeline_dag.py
[2025-06-11T10:43:43.772+0000] {logging_mixin.py:188} INFO - [2025-06-11T10:43:43.764+0000] {dagbag.py:355} ERROR - Failed to import: /opt/airflow/dags/etl_pipeline_dag.py
Traceback (most recent call last):
  File "/home/airflow/.local/lib/python3.12/site-packages/airflow/models/dagbag.py", line 351, in parse
    loader.exec_module(new_module)
  File "<frozen importlib._bootstrap_external>", line 995, in exec_module
  File "<frozen importlib._bootstrap>", line 488, in _call_with_frames_removed
  File "/opt/airflow/dags/etl_pipeline_dag.py", line 8, in <module>
    from main_etl import run_etl
ModuleNotFoundError: No module named 'main_etl'
[2025-06-11T10:43:43.776+0000] {processor.py:842} WARNING - No viable dags retrieved from /opt/airflow/dags/etl_pipeline_dag.py
[2025-06-11T10:43:43.814+0000] {processor.py:183} INFO - Processing /opt/airflow/dags/etl_pipeline_dag.py took 0.108 seconds
[2025-06-11T10:44:14.626+0000] {processor.py:161} INFO - Started process (PID=430) to work on /opt/airflow/dags/etl_pipeline_dag.py
[2025-06-11T10:44:14.628+0000] {processor.py:830} INFO - Processing file /opt/airflow/dags/etl_pipeline_dag.py for tasks to queue
[2025-06-11T10:44:14.633+0000] {logging_mixin.py:188} INFO - [2025-06-11T10:44:14.631+0000] {dagbag.py:545} INFO - Filling up the DagBag from /opt/airflow/dags/etl_pipeline_dag.py
[2025-06-11T10:44:14.696+0000] {logging_mixin.py:188} INFO - [2025-06-11T10:44:14.687+0000] {dagbag.py:355} ERROR - Failed to import: /opt/airflow/dags/etl_pipeline_dag.py
Traceback (most recent call last):
  File "/home/airflow/.local/lib/python3.12/site-packages/airflow/models/dagbag.py", line 351, in parse
    loader.exec_module(new_module)
  File "<frozen importlib._bootstrap_external>", line 995, in exec_module
  File "<frozen importlib._bootstrap>", line 488, in _call_with_frames_removed
  File "/opt/airflow/dags/etl_pipeline_dag.py", line 8, in <module>
    from main_etl import run_etl
ModuleNotFoundError: No module named 'main_etl'
[2025-06-11T10:44:14.701+0000] {processor.py:842} WARNING - No viable dags retrieved from /opt/airflow/dags/etl_pipeline_dag.py
[2025-06-11T10:44:14.726+0000] {processor.py:183} INFO - Processing /opt/airflow/dags/etl_pipeline_dag.py took 0.114 seconds
[2025-06-11T10:44:45.351+0000] {processor.py:161} INFO - Started process (PID=435) to work on /opt/airflow/dags/etl_pipeline_dag.py
[2025-06-11T10:44:45.354+0000] {processor.py:830} INFO - Processing file /opt/airflow/dags/etl_pipeline_dag.py for tasks to queue
[2025-06-11T10:44:45.364+0000] {logging_mixin.py:188} INFO - [2025-06-11T10:44:45.363+0000] {dagbag.py:545} INFO - Filling up the DagBag from /opt/airflow/dags/etl_pipeline_dag.py
[2025-06-11T10:44:45.440+0000] {logging_mixin.py:188} INFO - [2025-06-11T10:44:45.428+0000] {dagbag.py:355} ERROR - Failed to import: /opt/airflow/dags/etl_pipeline_dag.py
Traceback (most recent call last):
  File "/home/airflow/.local/lib/python3.12/site-packages/airflow/models/dagbag.py", line 351, in parse
    loader.exec_module(new_module)
  File "<frozen importlib._bootstrap_external>", line 995, in exec_module
  File "<frozen importlib._bootstrap>", line 488, in _call_with_frames_removed
  File "/opt/airflow/dags/etl_pipeline_dag.py", line 8, in <module>
    from main_etl import run_etl
ModuleNotFoundError: No module named 'main_etl'
[2025-06-11T10:44:45.444+0000] {processor.py:842} WARNING - No viable dags retrieved from /opt/airflow/dags/etl_pipeline_dag.py
[2025-06-11T10:44:45.476+0000] {processor.py:183} INFO - Processing /opt/airflow/dags/etl_pipeline_dag.py took 0.131 seconds
[2025-06-11T10:45:16.170+0000] {processor.py:161} INFO - Started process (PID=440) to work on /opt/airflow/dags/etl_pipeline_dag.py
[2025-06-11T10:45:16.172+0000] {processor.py:830} INFO - Processing file /opt/airflow/dags/etl_pipeline_dag.py for tasks to queue
[2025-06-11T10:45:16.174+0000] {logging_mixin.py:188} INFO - [2025-06-11T10:45:16.174+0000] {dagbag.py:545} INFO - Filling up the DagBag from /opt/airflow/dags/etl_pipeline_dag.py
[2025-06-11T10:45:16.230+0000] {logging_mixin.py:188} INFO - [2025-06-11T10:45:16.223+0000] {dagbag.py:355} ERROR - Failed to import: /opt/airflow/dags/etl_pipeline_dag.py
Traceback (most recent call last):
  File "/home/airflow/.local/lib/python3.12/site-packages/airflow/models/dagbag.py", line 351, in parse
    loader.exec_module(new_module)
  File "<frozen importlib._bootstrap_external>", line 995, in exec_module
  File "<frozen importlib._bootstrap>", line 488, in _call_with_frames_removed
  File "/opt/airflow/dags/etl_pipeline_dag.py", line 8, in <module>
    from main_etl import run_etl
ModuleNotFoundError: No module named 'main_etl'
[2025-06-11T10:45:16.234+0000] {processor.py:842} WARNING - No viable dags retrieved from /opt/airflow/dags/etl_pipeline_dag.py
[2025-06-11T10:45:16.256+0000] {processor.py:183} INFO - Processing /opt/airflow/dags/etl_pipeline_dag.py took 0.091 seconds
[2025-06-11T10:45:47.129+0000] {processor.py:161} INFO - Started process (PID=445) to work on /opt/airflow/dags/etl_pipeline_dag.py
[2025-06-11T10:45:47.131+0000] {processor.py:830} INFO - Processing file /opt/airflow/dags/etl_pipeline_dag.py for tasks to queue
[2025-06-11T10:45:47.134+0000] {logging_mixin.py:188} INFO - [2025-06-11T10:45:47.134+0000] {dagbag.py:545} INFO - Filling up the DagBag from /opt/airflow/dags/etl_pipeline_dag.py
[2025-06-11T10:45:47.209+0000] {logging_mixin.py:188} INFO - [2025-06-11T10:45:47.191+0000] {dagbag.py:355} ERROR - Failed to import: /opt/airflow/dags/etl_pipeline_dag.py
Traceback (most recent call last):
  File "/home/airflow/.local/lib/python3.12/site-packages/airflow/models/dagbag.py", line 351, in parse
    loader.exec_module(new_module)
  File "<frozen importlib._bootstrap_external>", line 995, in exec_module
  File "<frozen importlib._bootstrap>", line 488, in _call_with_frames_removed
  File "/opt/airflow/dags/etl_pipeline_dag.py", line 8, in <module>
    from main_etl import run_etl
ModuleNotFoundError: No module named 'main_etl'
[2025-06-11T10:45:47.216+0000] {processor.py:842} WARNING - No viable dags retrieved from /opt/airflow/dags/etl_pipeline_dag.py
[2025-06-11T10:45:47.294+0000] {processor.py:183} INFO - Processing /opt/airflow/dags/etl_pipeline_dag.py took 0.170 seconds
[2025-06-11T10:46:18.140+0000] {processor.py:161} INFO - Started process (PID=450) to work on /opt/airflow/dags/etl_pipeline_dag.py
[2025-06-11T10:46:18.142+0000] {processor.py:830} INFO - Processing file /opt/airflow/dags/etl_pipeline_dag.py for tasks to queue
[2025-06-11T10:46:18.145+0000] {logging_mixin.py:188} INFO - [2025-06-11T10:46:18.144+0000] {dagbag.py:545} INFO - Filling up the DagBag from /opt/airflow/dags/etl_pipeline_dag.py
[2025-06-11T10:46:18.207+0000] {logging_mixin.py:188} INFO - [2025-06-11T10:46:18.196+0000] {dagbag.py:355} ERROR - Failed to import: /opt/airflow/dags/etl_pipeline_dag.py
Traceback (most recent call last):
  File "/home/airflow/.local/lib/python3.12/site-packages/airflow/models/dagbag.py", line 351, in parse
    loader.exec_module(new_module)
  File "<frozen importlib._bootstrap_external>", line 995, in exec_module
  File "<frozen importlib._bootstrap>", line 488, in _call_with_frames_removed
  File "/opt/airflow/dags/etl_pipeline_dag.py", line 8, in <module>
    from main_etl import run_etl
ModuleNotFoundError: No module named 'main_etl'
[2025-06-11T10:46:18.213+0000] {processor.py:842} WARNING - No viable dags retrieved from /opt/airflow/dags/etl_pipeline_dag.py
[2025-06-11T10:46:18.257+0000] {processor.py:183} INFO - Processing /opt/airflow/dags/etl_pipeline_dag.py took 0.168 seconds
[2025-06-11T10:46:48.811+0000] {processor.py:161} INFO - Started process (PID=455) to work on /opt/airflow/dags/etl_pipeline_dag.py
[2025-06-11T10:46:48.812+0000] {processor.py:830} INFO - Processing file /opt/airflow/dags/etl_pipeline_dag.py for tasks to queue
[2025-06-11T10:46:48.815+0000] {logging_mixin.py:188} INFO - [2025-06-11T10:46:48.815+0000] {dagbag.py:545} INFO - Filling up the DagBag from /opt/airflow/dags/etl_pipeline_dag.py
[2025-06-11T10:46:48.869+0000] {logging_mixin.py:188} INFO - [2025-06-11T10:46:48.859+0000] {dagbag.py:355} ERROR - Failed to import: /opt/airflow/dags/etl_pipeline_dag.py
Traceback (most recent call last):
  File "/home/airflow/.local/lib/python3.12/site-packages/airflow/models/dagbag.py", line 351, in parse
    loader.exec_module(new_module)
  File "<frozen importlib._bootstrap_external>", line 995, in exec_module
  File "<frozen importlib._bootstrap>", line 488, in _call_with_frames_removed
  File "/opt/airflow/dags/etl_pipeline_dag.py", line 8, in <module>
    from main_etl import run_etl
ModuleNotFoundError: No module named 'main_etl'
[2025-06-11T10:46:48.872+0000] {processor.py:842} WARNING - No viable dags retrieved from /opt/airflow/dags/etl_pipeline_dag.py
[2025-06-11T10:46:48.902+0000] {processor.py:183} INFO - Processing /opt/airflow/dags/etl_pipeline_dag.py took 0.097 seconds
[2025-06-11T10:47:19.611+0000] {processor.py:161} INFO - Started process (PID=460) to work on /opt/airflow/dags/etl_pipeline_dag.py
[2025-06-11T10:47:19.613+0000] {processor.py:830} INFO - Processing file /opt/airflow/dags/etl_pipeline_dag.py for tasks to queue
[2025-06-11T10:47:19.616+0000] {logging_mixin.py:188} INFO - [2025-06-11T10:47:19.615+0000] {dagbag.py:545} INFO - Filling up the DagBag from /opt/airflow/dags/etl_pipeline_dag.py
[2025-06-11T10:47:19.681+0000] {logging_mixin.py:188} INFO - [2025-06-11T10:47:19.671+0000] {dagbag.py:355} ERROR - Failed to import: /opt/airflow/dags/etl_pipeline_dag.py
Traceback (most recent call last):
  File "/home/airflow/.local/lib/python3.12/site-packages/airflow/models/dagbag.py", line 351, in parse
    loader.exec_module(new_module)
  File "<frozen importlib._bootstrap_external>", line 995, in exec_module
  File "<frozen importlib._bootstrap>", line 488, in _call_with_frames_removed
  File "/opt/airflow/dags/etl_pipeline_dag.py", line 8, in <module>
    from main_etl import run_etl
ModuleNotFoundError: No module named 'main_etl'
[2025-06-11T10:47:19.685+0000] {processor.py:842} WARNING - No viable dags retrieved from /opt/airflow/dags/etl_pipeline_dag.py
[2025-06-11T10:47:19.767+0000] {processor.py:183} INFO - Processing /opt/airflow/dags/etl_pipeline_dag.py took 0.166 seconds
[2025-06-11T10:47:23.079+0000] {processor.py:161} INFO - Started process (PID=465) to work on /opt/airflow/dags/etl_pipeline_dag.py
[2025-06-11T10:47:23.081+0000] {processor.py:830} INFO - Processing file /opt/airflow/dags/etl_pipeline_dag.py for tasks to queue
[2025-06-11T10:47:23.084+0000] {logging_mixin.py:188} INFO - [2025-06-11T10:47:23.083+0000] {dagbag.py:545} INFO - Filling up the DagBag from /opt/airflow/dags/etl_pipeline_dag.py
[2025-06-11T10:47:23.458+0000] {processor.py:840} INFO - DAG(s) 'etl_brazil_pipeline' retrieved from /opt/airflow/dags/etl_pipeline_dag.py
[2025-06-11T10:47:25.003+0000] {logging_mixin.py:188} INFO - [2025-06-11T10:47:25.001+0000] {override.py:1829} INFO - Created Permission View: can edit on DAG:etl_brazil_pipeline
[2025-06-11T10:47:25.030+0000] {logging_mixin.py:188} INFO - [2025-06-11T10:47:25.029+0000] {override.py:1829} INFO - Created Permission View: can delete on DAG:etl_brazil_pipeline
[2025-06-11T10:47:25.037+0000] {logging_mixin.py:188} INFO - [2025-06-11T10:47:25.037+0000] {override.py:1829} INFO - Created Permission View: can read on DAG:etl_brazil_pipeline
[2025-06-11T10:47:25.039+0000] {logging_mixin.py:188} INFO - [2025-06-11T10:47:25.039+0000] {dag.py:3096} INFO - Sync 1 DAGs
[2025-06-11T10:47:25.099+0000] {logging_mixin.py:188} INFO - [2025-06-11T10:47:25.099+0000] {dag.py:3118} INFO - Creating ORM DAG for etl_brazil_pipeline
[2025-06-11T10:47:25.104+0000] {logging_mixin.py:188} INFO - [2025-06-11T10:47:25.104+0000] {dag.py:3954} INFO - Setting next_dagrun for etl_brazil_pipeline to None, run_after=None
[2025-06-11T10:47:25.187+0000] {processor.py:183} INFO - Processing /opt/airflow/dags/etl_pipeline_dag.py took 2.148 seconds
