[2025-06-06T09:33:31.396+0000] {local_task_job_runner.py:120} INFO - ::group::Pre task execution logs
[2025-06-06T09:33:31.424+0000] {taskinstance.py:2076} INFO - Dependencies all met for dep_context=non-requeueable deps ti=<TaskInstance: cost_efficient_etl_pipeline.run_ge_validation scheduled__2025-06-05T00:00:00+00:00 [queued]>
[2025-06-06T09:33:31.436+0000] {taskinstance.py:2076} INFO - Dependencies all met for dep_context=requeueable deps ti=<TaskInstance: cost_efficient_etl_pipeline.run_ge_validation scheduled__2025-06-05T00:00:00+00:00 [queued]>
[2025-06-06T09:33:31.437+0000] {taskinstance.py:2306} INFO - Starting attempt 2 of 2
[2025-06-06T09:33:31.452+0000] {taskinstance.py:2330} INFO - Executing <Task(PythonOperator): run_ge_validation> on 2025-06-05 00:00:00+00:00
[2025-06-06T09:33:31.486+0000] {logging_mixin.py:188} WARNING - /home/***/.local/lib/python3.12/site-packages/***/task/task_runner/standard_task_runner.py:61 DeprecationWarning: This process (pid=338) is multi-threaded, use of fork() may lead to deadlocks in the child.
[2025-06-06T09:33:31.499+0000] {standard_task_runner.py:63} INFO - Started process 381 to run task
[2025-06-06T09:33:31.524+0000] {standard_task_runner.py:90} INFO - Running: ['***', 'tasks', 'run', 'cost_efficient_etl_pipeline', 'run_ge_validation', 'scheduled__2025-06-05T00:00:00+00:00', '--job-id', '7', '--raw', '--subdir', 'DAGS_FOLDER/etl_pipeline_dag.py', '--cfg-path', '/tmp/tmp6ym2j_fk']
[2025-06-06T09:33:31.558+0000] {standard_task_runner.py:91} INFO - Job 7: Subtask run_ge_validation
[2025-06-06T09:33:31.588+0000] {logging_mixin.py:188} WARNING - /home/***/.local/lib/python3.12/site-packages/***/settings.py:195 DeprecationWarning: The sql_alchemy_conn option in [core] has been moved to the sql_alchemy_conn option in [database] - the old setting has been used, but please update your config.
[2025-06-06T09:33:31.650+0000] {task_command.py:426} INFO - Running <TaskInstance: cost_efficient_etl_pipeline.run_ge_validation scheduled__2025-06-05T00:00:00+00:00 [running]> on host 6eea582f3f26
[2025-06-06T09:33:31.738+0000] {taskinstance.py:2648} INFO - Exporting env vars: AIRFLOW_CTX_DAG_OWNER='vaishnavi' AIRFLOW_CTX_DAG_ID='cost_efficient_etl_pipeline' AIRFLOW_CTX_TASK_ID='run_ge_validation' AIRFLOW_CTX_EXECUTION_DATE='2025-06-05T00:00:00+00:00' AIRFLOW_CTX_TRY_NUMBER='2' AIRFLOW_CTX_DAG_RUN_ID='scheduled__2025-06-05T00:00:00+00:00'
[2025-06-06T09:33:31.740+0000] {taskinstance.py:430} INFO - ::endgroup::
[2025-06-06T09:33:31.752+0000] {taskinstance.py:441} INFO - ::group::Post task execution logs
[2025-06-06T09:33:31.753+0000] {taskinstance.py:2905} ERROR - Task failed with exception
Traceback (most recent call last):
  File "/home/airflow/.local/lib/python3.12/site-packages/airflow/models/taskinstance.py", line 465, in _execute_task
    result = _execute_callable(context=context, **execute_callable_kwargs)
             ^^^^^^^^^^^^^^^^^^^^^^^^^^^^^^^^^^^^^^^^^^^^^^^^^^^^^^^^^^^^^
  File "/home/airflow/.local/lib/python3.12/site-packages/airflow/models/taskinstance.py", line 432, in _execute_callable
    return execute_callable(context=context, **execute_callable_kwargs)
           ^^^^^^^^^^^^^^^^^^^^^^^^^^^^^^^^^^^^^^^^^^^^^^^^^^^^^^^^^^^^
  File "/home/airflow/.local/lib/python3.12/site-packages/airflow/models/baseoperator.py", line 400, in wrapper
    return func(self, *args, **kwargs)
           ^^^^^^^^^^^^^^^^^^^^^^^^^^^
  File "/home/airflow/.local/lib/python3.12/site-packages/airflow/operators/python.py", line 235, in execute
    return_value = self.execute_callable()
                   ^^^^^^^^^^^^^^^^^^^^^^^
  File "/home/airflow/.local/lib/python3.12/site-packages/airflow/operators/python.py", line 252, in execute_callable
    return self.python_callable(*self.op_args, **self.op_kwargs)
           ^^^^^^^^^^^^^^^^^^^^^^^^^^^^^^^^^^^^^^^^^^^^^^^^^^^^^
  File "/opt/airflow/dags/etl_pipeline_dag.py", line 19, in run_validation
    validate_data("processed_data.csv")
  File "/opt/airflow/src/etl/validate_data.py", line 5, in validate_data
    context = ge.data_context.DataContext()
              ^^^^^^^^^^^^^^^^^^^^^^^^^^^
AttributeError: module 'great_expectations.data_context' has no attribute 'DataContext'. Did you mean: 'data_context'?
[2025-06-06T09:33:31.783+0000] {taskinstance.py:1206} INFO - Marking task as FAILED. dag_id=cost_efficient_etl_pipeline, task_id=run_ge_validation, run_id=scheduled__2025-06-05T00:00:00+00:00, execution_date=20250605T000000, start_date=20250606T093331, end_date=20250606T093331
[2025-06-06T09:33:31.796+0000] {standard_task_runner.py:110} ERROR - Failed to execute job 7 for task run_ge_validation (module 'great_expectations.data_context' has no attribute 'DataContext'; 381)
[2025-06-06T09:33:31.835+0000] {local_task_job_runner.py:240} INFO - Task exited with return code 1
[2025-06-06T09:33:31.849+0000] {taskinstance.py:3498} INFO - 0 downstream tasks scheduled from follow-on schedule check
[2025-06-06T09:33:31.853+0000] {local_task_job_runner.py:222} INFO - ::endgroup::
