[2025-06-06T09:32:23.573+0000] {local_task_job_runner.py:120} INFO - ::group::Pre task execution logs
[2025-06-06T09:32:23.616+0000] {taskinstance.py:2076} INFO - Dependencies all met for dep_context=non-requeueable deps ti=<TaskInstance: cost_efficient_etl_pipeline.run_ge_validation manual__2025-06-06T09:31:58.224268+00:00 [queued]>
[2025-06-06T09:32:23.632+0000] {taskinstance.py:2076} INFO - Dependencies all met for dep_context=requeueable deps ti=<TaskInstance: cost_efficient_etl_pipeline.run_ge_validation manual__2025-06-06T09:31:58.224268+00:00 [queued]>
[2025-06-06T09:32:23.634+0000] {taskinstance.py:2306} INFO - Starting attempt 1 of 2
[2025-06-06T09:32:23.656+0000] {taskinstance.py:2330} INFO - Executing <Task(PythonOperator): run_ge_validation> on 2025-06-06 09:31:58.224268+00:00
[2025-06-06T09:32:23.679+0000] {logging_mixin.py:188} WARNING - /home/***/.local/lib/python3.12/site-packages/***/task/task_runner/standard_task_runner.py:61 DeprecationWarning: This process (pid=285) is multi-threaded, use of fork() may lead to deadlocks in the child.
[2025-06-06T09:32:23.682+0000] {standard_task_runner.py:63} INFO - Started process 315 to run task
[2025-06-06T09:32:23.680+0000] {standard_task_runner.py:90} INFO - Running: ['***', 'tasks', 'run', 'cost_efficient_etl_pipeline', 'run_ge_validation', 'manual__2025-06-06T09:31:58.224268+00:00', '--job-id', '5', '--raw', '--subdir', 'DAGS_FOLDER/etl_pipeline_dag.py', '--cfg-path', '/tmp/tmp_wlkmifc']
[2025-06-06T09:32:23.686+0000] {standard_task_runner.py:91} INFO - Job 5: Subtask run_ge_validation
[2025-06-06T09:32:23.716+0000] {logging_mixin.py:188} WARNING - /home/***/.local/lib/python3.12/site-packages/***/settings.py:195 DeprecationWarning: The sql_alchemy_conn option in [core] has been moved to the sql_alchemy_conn option in [database] - the old setting has been used, but please update your config.
[2025-06-06T09:32:23.777+0000] {task_command.py:426} INFO - Running <TaskInstance: cost_efficient_etl_pipeline.run_ge_validation manual__2025-06-06T09:31:58.224268+00:00 [running]> on host 6eea582f3f26
[2025-06-06T09:32:23.906+0000] {taskinstance.py:2648} INFO - Exporting env vars: AIRFLOW_CTX_DAG_OWNER='vaishnavi' AIRFLOW_CTX_DAG_ID='cost_efficient_etl_pipeline' AIRFLOW_CTX_TASK_ID='run_ge_validation' AIRFLOW_CTX_EXECUTION_DATE='2025-06-06T09:31:58.224268+00:00' AIRFLOW_CTX_TRY_NUMBER='1' AIRFLOW_CTX_DAG_RUN_ID='manual__2025-06-06T09:31:58.224268+00:00'
[2025-06-06T09:32:23.908+0000] {taskinstance.py:430} INFO - ::endgroup::
[2025-06-06T09:32:23.923+0000] {taskinstance.py:441} INFO - ::group::Post task execution logs
[2025-06-06T09:32:23.924+0000] {taskinstance.py:2905} ERROR - Task failed with exception
Traceback (most recent call last):
  File "/home/airflow/.local/lib/python3.12/site-packages/airflow/models/taskinstance.py", line 465, in _execute_task
    result = _execute_callable(context=context, **execute_callable_kwargs)
             ^^^^^^^^^^^^^^^^^^^^^^^^^^^^^^^^^^^^^^^^^^^^^^^^^^^^^^^^^^^^^
  File "/home/airflow/.local/lib/python3.12/site-packages/airflow/models/taskinstance.py", line 432, in _execute_callable
    return execute_callable(context=context, **execute_callable_kwargs)
           ^^^^^^^^^^^^^^^^^^^^^^^^^^^^^^^^^^^^^^^^^^^^^^^^^^^^^^^^^^^^
  File "/home/airflow/.local/lib/python3.12/site-packages/airflow/models/baseoperator.py", line 400, in wrapper
    return func(self, *args, **kwargs)
           ^^^^^^^^^^^^^^^^^^^^^^^^^^^
  File "/home/airflow/.local/lib/python3.12/site-packages/airflow/operators/python.py", line 235, in execute
    return_value = self.execute_callable()
                   ^^^^^^^^^^^^^^^^^^^^^^^
  File "/home/airflow/.local/lib/python3.12/site-packages/airflow/operators/python.py", line 252, in execute_callable
    return self.python_callable(*self.op_args, **self.op_kwargs)
           ^^^^^^^^^^^^^^^^^^^^^^^^^^^^^^^^^^^^^^^^^^^^^^^^^^^^^
  File "/opt/airflow/dags/etl_pipeline_dag.py", line 19, in run_validation
    validate_data("processed_data.csv")
  File "/opt/airflow/src/etl/validate_data.py", line 5, in validate_data
    context = ge.data_context.DataContext()
              ^^^^^^^^^^^^^^^^^^^^^^^^^^^
AttributeError: module 'great_expectations.data_context' has no attribute 'DataContext'. Did you mean: 'data_context'?
[2025-06-06T09:32:23.957+0000] {taskinstance.py:1206} INFO - Marking task as UP_FOR_RETRY. dag_id=cost_efficient_etl_pipeline, task_id=run_ge_validation, run_id=manual__2025-06-06T09:31:58.224268+00:00, execution_date=20250606T093158, start_date=20250606T093223, end_date=20250606T093223
[2025-06-06T09:32:23.972+0000] {standard_task_runner.py:110} ERROR - Failed to execute job 5 for task run_ge_validation (module 'great_expectations.data_context' has no attribute 'DataContext'; 315)
[2025-06-06T09:32:24.019+0000] {local_task_job_runner.py:240} INFO - Task exited with return code 1
[2025-06-06T09:32:24.045+0000] {taskinstance.py:3498} INFO - 0 downstream tasks scheduled from follow-on schedule check
[2025-06-06T09:32:24.048+0000] {local_task_job_runner.py:222} INFO - ::endgroup::
