[2025-06-06T13:54:15.621+0000] {local_task_job_runner.py:120} INFO - ::group::Pre task execution logs
[2025-06-06T13:54:15.689+0000] {taskinstance.py:2076} INFO - Dependencies all met for dep_context=non-requeueable deps ti=<TaskInstance: cost_efficient_etl_pipeline.run_ge_validation manual__2025-06-06T13:52:33.996231+00:00 [queued]>
[2025-06-06T13:54:15.702+0000] {taskinstance.py:2076} INFO - Dependencies all met for dep_context=requeueable deps ti=<TaskInstance: cost_efficient_etl_pipeline.run_ge_validation manual__2025-06-06T13:52:33.996231+00:00 [queued]>
[2025-06-06T13:54:15.703+0000] {taskinstance.py:2306} INFO - Starting attempt 2 of 2
[2025-06-06T13:54:15.721+0000] {taskinstance.py:2330} INFO - Executing <Task(PythonOperator): run_ge_validation> on 2025-06-06 13:52:33.996231+00:00
[2025-06-06T13:54:15.738+0000] {warnings.py:110} WARNING - /home/***/.local/lib/python3.12/site-packages/***/task/task_runner/standard_task_runner.py:61: DeprecationWarning: This process (pid=446) is multi-threaded, use of fork() may lead to deadlocks in the child.
  pid = os.fork()

[2025-06-06T13:54:15.745+0000] {standard_task_runner.py:63} INFO - Started process 460 to run task
[2025-06-06T13:54:15.747+0000] {standard_task_runner.py:90} INFO - Running: ['***', 'tasks', 'run', 'cost_efficient_etl_pipeline', 'run_ge_validation', 'manual__2025-06-06T13:52:33.996231+00:00', '--job-id', '13', '--raw', '--subdir', 'DAGS_FOLDER/etl_pipeline_dag.py', '--cfg-path', '/tmp/tmpunwfi0fd']
[2025-06-06T13:54:15.748+0000] {standard_task_runner.py:91} INFO - Job 13: Subtask run_ge_validation
[2025-06-06T13:54:15.780+0000] {warnings.py:110} WARNING - /home/***/.local/lib/python3.12/site-packages/***/settings.py:195: DeprecationWarning: The sql_alchemy_conn option in [core] has been moved to the sql_alchemy_conn option in [database] - the old setting has been used, but please update your config.
  SQL_ALCHEMY_CONN = conf.get("database", "SQL_ALCHEMY_CONN")

[2025-06-06T13:54:15.876+0000] {task_command.py:426} INFO - Running <TaskInstance: cost_efficient_etl_pipeline.run_ge_validation manual__2025-06-06T13:52:33.996231+00:00 [running]> on host 5203c265b0c6
[2025-06-06T13:54:16.037+0000] {taskinstance.py:2648} INFO - Exporting env vars: AIRFLOW_CTX_DAG_OWNER='vaishnavi' AIRFLOW_CTX_DAG_ID='cost_efficient_etl_pipeline' AIRFLOW_CTX_TASK_ID='run_ge_validation' AIRFLOW_CTX_EXECUTION_DATE='2025-06-06T13:52:33.996231+00:00' AIRFLOW_CTX_TRY_NUMBER='2' AIRFLOW_CTX_DAG_RUN_ID='manual__2025-06-06T13:52:33.996231+00:00'
[2025-06-06T13:54:16.040+0000] {taskinstance.py:430} INFO - ::endgroup::
[2025-06-06T13:54:16.207+0000] {file_data_context.py:224} INFO - FileDataContext loading fluent config
[2025-06-06T13:54:16.233+0000] {config.py:185} INFO - Loading 'datasources' ->
[]
[2025-06-06T13:54:16.666+0000] {taskinstance.py:441} INFO - ::group::Post task execution logs
[2025-06-06T13:54:16.669+0000] {taskinstance.py:2905} ERROR - Task failed with exception
Traceback (most recent call last):
  File "/home/airflow/.local/lib/python3.12/site-packages/great_expectations/data_context/store/tuple_store_backend.py", line 320, in _get
    with open(filepath) as infile:
         ^^^^^^^^^^^^^^
FileNotFoundError: [Errno 2] No such file or directory: '/opt/airflow/gx/checkpoints/validation_checkpoint.yml'

During handling of the above exception, another exception occurred:

Traceback (most recent call last):
  File "/home/airflow/.local/lib/python3.12/site-packages/great_expectations/data_context/store/checkpoint_store.py", line 154, in get_checkpoint
    checkpoint_config: Optional[Any] = self.get(key=key)
                                       ^^^^^^^^^^^^^^^^^
  File "/home/airflow/.local/lib/python3.12/site-packages/great_expectations/data_context/store/store.py", line 212, in get
    value = self._store_backend.get(self.key_to_tuple(key))
            ^^^^^^^^^^^^^^^^^^^^^^^^^^^^^^^^^^^^^^^^^^^^^^^
  File "/home/airflow/.local/lib/python3.12/site-packages/great_expectations/data_context/store/_store_backend.py", line 123, in get
    value = self._get(key, **kwargs)
            ^^^^^^^^^^^^^^^^^^^^^^^^
  File "/home/airflow/.local/lib/python3.12/site-packages/great_expectations/data_context/store/tuple_store_backend.py", line 323, in _get
    raise InvalidKeyError(
great_expectations.exceptions.exceptions.InvalidKeyError: Unable to retrieve object from TupleFilesystemStoreBackend with the following Key: /opt/***/gx/checkpoints/validation_checkpoint.yml

During handling of the above exception, another exception occurred:

Traceback (most recent call last):
  File "/home/airflow/.local/lib/python3.12/site-packages/airflow/models/taskinstance.py", line 465, in _execute_task
    result = _execute_callable(context=context, **execute_callable_kwargs)
             ^^^^^^^^^^^^^^^^^^^^^^^^^^^^^^^^^^^^^^^^^^^^^^^^^^^^^^^^^^^^^
  File "/home/airflow/.local/lib/python3.12/site-packages/airflow/models/taskinstance.py", line 432, in _execute_callable
    return execute_callable(context=context, **execute_callable_kwargs)
           ^^^^^^^^^^^^^^^^^^^^^^^^^^^^^^^^^^^^^^^^^^^^^^^^^^^^^^^^^^^^
  File "/home/airflow/.local/lib/python3.12/site-packages/airflow/models/baseoperator.py", line 400, in wrapper
    return func(self, *args, **kwargs)
           ^^^^^^^^^^^^^^^^^^^^^^^^^^^
  File "/home/airflow/.local/lib/python3.12/site-packages/airflow/operators/python.py", line 235, in execute
    return_value = self.execute_callable()
                   ^^^^^^^^^^^^^^^^^^^^^^^
  File "/home/airflow/.local/lib/python3.12/site-packages/airflow/operators/python.py", line 252, in execute_callable
    return self.python_callable(*self.op_args, **self.op_kwargs)
           ^^^^^^^^^^^^^^^^^^^^^^^^^^^^^^^^^^^^^^^^^^^^^^^^^^^^^
  File "/opt/airflow/dags/etl_pipeline_dag.py", line 19, in run_validation
    validate_data("processed_data.csv")
  File "/opt/airflow/src/etl/validate_data.py", line 17, in validate_data
    results = context.run_checkpoint(
              ^^^^^^^^^^^^^^^^^^^^^^^
  File "/home/airflow/.local/lib/python3.12/site-packages/great_expectations/core/usage_statistics/usage_statistics.py", line 260, in usage_statistics_wrapped_method
    result = func(*args, **kwargs)
             ^^^^^^^^^^^^^^^^^^^^^
  File "/home/airflow/.local/lib/python3.12/site-packages/great_expectations/data_context/data_context/abstract_data_context.py", line 2215, in run_checkpoint
    return self._run_checkpoint(
           ^^^^^^^^^^^^^^^^^^^^^
  File "/home/airflow/.local/lib/python3.12/site-packages/great_expectations/data_context/data_context/abstract_data_context.py", line 2255, in _run_checkpoint
    checkpoint: Checkpoint = self.get_checkpoint(
                             ^^^^^^^^^^^^^^^^^^^^
  File "/home/airflow/.local/lib/python3.12/site-packages/great_expectations/data_context/data_context/abstract_data_context.py", line 2106, in get_checkpoint
    checkpoint_config: CheckpointConfig = self.checkpoint_store.get_checkpoint(
                                          ^^^^^^^^^^^^^^^^^^^^^^^^^^^^^^^^^^^^^
  File "/home/airflow/.local/lib/python3.12/site-packages/great_expectations/data_context/store/checkpoint_store.py", line 159, in get_checkpoint
    raise gx_exceptions.CheckpointNotFoundError(
great_expectations.exceptions.exceptions.CheckpointNotFoundError: Non-existent Checkpoint configuration named "validation_checkpoint".

Details: Unable to retrieve object from TupleFilesystemStoreBackend with the following Key: /opt/***/gx/checkpoints/validation_checkpoint.yml
[2025-06-06T13:54:16.703+0000] {taskinstance.py:1206} INFO - Marking task as FAILED. dag_id=cost_efficient_etl_pipeline, task_id=run_ge_validation, run_id=manual__2025-06-06T13:52:33.996231+00:00, execution_date=20250606T135233, start_date=20250606T135415, end_date=20250606T135416
[2025-06-06T13:54:16.719+0000] {standard_task_runner.py:110} ERROR - Failed to execute job 13 for task run_ge_validation (Non-existent Checkpoint configuration named "validation_checkpoint".

Details: Unable to retrieve object from TupleFilesystemStoreBackend with the following Key: /opt/***/gx/checkpoints/validation_checkpoint.yml; 460)
[2025-06-06T13:54:16.767+0000] {local_task_job_runner.py:240} INFO - Task exited with return code 1
[2025-06-06T13:54:16.795+0000] {taskinstance.py:3498} INFO - 0 downstream tasks scheduled from follow-on schedule check
[2025-06-06T13:54:16.799+0000] {local_task_job_runner.py:222} INFO - ::endgroup::
